Workbook

Sheet Cover Page
B4: Media & Entertainment Private Credit Model — Crescent Harbor Media Holdings, LLC
B7: Senior Secured Unitranche Borrowing Base Facility | Illustrative Transaction — Not a Real Client Engagement
B12: This illustrative model presents a $75.0 million private credit underwriting for a media-library-backed facility.
B13: It covers borrowing-base mechanics, covenant structuring, sensitivity and scenario analysis, and recovery modeling.
B14: The credit recommendation is “Approve with Conditions,” supported by a 3.22 overall score.
B15: Downside borrowing-base performance and maturity refinancing risk are the binding credit issues.
A20: KEY FACTS
A21: Facility Size | B21: 75000000
A22: Facility Type | B22: Senior Secured Unitranche Borrowing Base Facility
A23: Credit Rating | B23: 3 - Watch
A24: Recommendation | B24: Approve with Conditions
A25: Prepared By | B25: Tanmay Srivastava
B29: All figures and entities are illustrative and constructed for modeling demonstration purposes only.

Sheet Transaction Overview
A1: Transaction Overview
A2: Investment question: What is being financed, on what terms, and with what collateral?
A4: Item | B4: Description / Value
A5: Borrower | B5: Crescent Harbor Media Holdings, LLC
A6: Facility Type | B6: Senior Secured Unitranche Borrowing Base Facility
A7: Purpose | B7: Refinancing, working capital, and selective content investment
A8: Collateral Package | B8: Media library, tax credits, international pre-sales, receivables, cash, and other eligible assets
A9: Security Position | B9: First-priority perfected security interest; subject to customary permitted liens
A10: Jurisdiction | B10: Delaware, United States
A11: Facility Amount | B11: ='Inputs & Assumptions'!C36 -> 75000000
A12: Tenor | B12: ='Inputs & Assumptions'!C37 -> 5
A13: Interest Structure | B13: ="SOFR + "&TEXT('Inputs & Assumptions'!C32,"0.00%") -> SOFR + 6.50%
A14: Sources & Uses | B14: Illustrative: refinance existing obligations and fund permitted business purposes
A15: Closing Date | B15: =DATE(2026,11,19) -> 46345
A17: Investment Summary | B17: ="Proposed "&TEXT('Inputs & Assumptions'!C36/1000000,"$0.0")&" million facility supported by a diversified borrowing base with "&TEXT('Borrowing Base'!B16,"0.00x")&" eligible collateral coverage and base-case DSCR of "&TEXT('Debt Service'!B12,"0.00x")&"." -> Proposed $75.0 million facility supported by a diversified borrowing base with 2.15x eligible collateral coverage and base-case DSCR of 1.90x.
A19: Lender Takeaway
A20: ="The proposed "&TEXT(B11/1000000,"$0.0")&" million first-lien facility relies on borrowing-base discipline and controlled cash collections rather than enterprise value alone." -> The proposed $75.0 million first-lien facility relies on borrowing-base discipline and controlled cash collections rather than enterprise value alone.

Sheet Investment Committee Decision
A1: Investment Committee Decision — Media & Entertainment Credit Facility
A2: Institutional underwriting summary | Illustrative transaction | USD unless noted
A4: Recommendation | B4: =IF('Credit Scorecard'!B15="DECLINE","REJECT",IF('Credit Scorecard'!B15="CONDITIONAL APPROVAL","APPROVE WITH CONDITIONS",IF('Credit Scorecard'!B15="WATCH / RESTRUCTURE TERMS","APPROVE WITH CONDITIONS","REVIEW"))) -> APPROVE WITH CONDITIONS | D4: Facility Metrics | G4: Traffic-Light Status
A5: Credit Rating | B5: ='Executive Dashboard'!E9 -> 3 - Watch | D5: Facility Size | E5: ='Inputs & Assumptions'!C36 -> 75000000 | G5: DSCR | H5: 1.25x minimum | I5: =IF(E10>=1.25,"🟢 STRONG",IF(E10>=1.15,"🟡 MODERATE RISK","🔴 HIGH RISK")) -> 🟡 MODERATE RISK
A6: Overall Credit Score | B6: ='Credit Scorecard'!B14 -> 3.22 | D6: Borrowing Base | E6: ='Borrowing Base'!F11 -> 92582285 | G6: LTV | H6: 50.0% maximum | I6: =IF(E9<=0.5,"🟢 STRONG",IF(E9<=0.55,"🟡 MODERATE RISK","🔴 HIGH RISK")) -> 🟢 STRONG
A7: Decision Rationale | B7: =IF(B4="APPROVE WITH CONDITIONS","Adequate base cash flow and collateral; downside borrowing-base gap, maturity refinancing risk — structural protections required.",IF(B4="APPROVE","Metrics support approval on proposed terms.","Risk-adjusted protection insufficient under modeled structure.")) -> Adequate base cash flow and collateral; downside borrowing-base gap, maturity refinancing risk — structural protections required. | D7: Borrowing Base Coverage | E7: ='Borrowing Base'!F11/'Inputs & Assumptions'!C36 -> 1.2344305 | G7: Borrowing Base Coverage | H7: 1.10x minimum | I7: =IF(E7>=1.1,"🟢 STRONG",IF(E7>=1,"🟡 MODERATE RISK","🔴 HIGH RISK")) -> 🟢 STRONG
D8: Gross Collateral Coverage | E8: ='Borrowing Base'!E11/'Inputs & Assumptions'!C36 -> 2.1502276 | G8: Downside BB Coverage | H8: 1.00x minimum | I8: =IF('Scenario Analysis'!C14>=1.1,"🟢 STRONG",IF('Scenario Analysis'!C14>=1,"🟡 MODERATE RISK","🔴 HIGH RISK")) -> 🔴 HIGH RISK
D9: Loan-to-Value | E9: ='Borrowing Base'!B17 -> 0.42005807 | G9: Recovery | H9: 90.0% minimum | I9: =IF(E14>=0.9,"🟢 STRONG",IF(E14>=0.8,"🟡 MODERATE RISK","🔴 HIGH RISK")) -> 🟢 STRONG
A10: Investment Thesis | D10: Minimum Pre-Maturity DSCR | E10: =MIN('Debt Service'!B12:E12) -> 1.2009636 | G10: Interest Coverage | H10: 1.50x minimum | I10: =IF(E12>=1.5,"🟢 STRONG",IF(E12>=1.25,"🟡 MODERATE RISK","🔴 HIGH RISK")) -> 🟡 MODERATE RISK
A11: ="Asset-backed first-lien facility with "&TEXT(E7,"0.00x")&" borrowing-base coverage, "&TEXT(E9,"0.0%")&" LTV and "&TEXT(E13,"0.0%")&" expected net yield. Approval is conditioned on curing downside borrowing-base pressure and maturity liquidity risk." -> Asset-backed first-lien facility with 1.23x borrowing-base coverage, 42.0% LTV and 8.2% expected net yield. Approval is conditioned on curing downside borrowing-base pressure and maturity liquidity risk. | D11: Downside DSCR | E11: ='Scenario Analysis'!C15 -> 1.3234253
D12: Minimum Interest Coverage | E12: =MIN('Debt Service'!B11:F11) -> 1.4657097
A13: Key Credit Strengths | D13: Expected Net Yield | E13: ='Debt Structure'!B22 -> 0.0823 | F13: Principal Risks
A14: • Diversified collateral — library, tax credits, pre-sales, receivables, cash. | D14: Expected Recovery | E14: ='Recovery Analysis'!B14 -> 1 | F14: ="• Downside BB coverage — "&TEXT('Scenario Analysis'!C14,"0.00x")&"; below full principal coverage." -> • Downside BB coverage — 0.97x; below full principal coverage.
A15: ="• Current borrowing-base headroom — "&TEXT('Borrowing Base'!G11/1000000,"$0.0")&" million." -> • Current borrowing-base headroom — $17.6 million. | D15: Maturity Cash Shortfall | E15: =MIN(0,'Debt Service'!F13) -> -57209309 | F15: ="• Minimum pre-maturity DSCR declines to "&TEXT(E10,"0.00x")&" as library cash flow decays." -> • Minimum pre-maturity DSCR declines to 1.20x as library cash flow decays.
A16: ="• Modeled PV recovery is "&TEXT('Recovery Analysis'!B14,"0.0%")&" of principal with first-lien structural protection." -> • Modeled PV recovery is 100.0% of principal with first-lien structural protection. | F16: ="• Maturity cash shortfall — "&TEXT(ABS(E15)/1000000,"$0.0")&" million; refinancing risk." -> • Maturity cash shortfall — $57.2 million; refinancing risk.
A18: Required Covenants | F18: Conditions Precedent
A19: • Minimum DSCR: 1.25x; cash trap below 1.35x. | F19: • Independent third-party library appraisal and verified chain of title.
A20: • Maximum LTV: 50%; mandatory paydown above 50%. | F20: • Perfection of first-priority liens and lender-controlled collection accounts.
A21: • Minimum borrowing-base coverage: 1.10x; immediate cure below 1.00x. | F21: • Validation of tax-credit eligibility, timing and assignability.
A22: • Quarterly borrowing-base certificates and semiannual independent library appraisals. | F22: • Counterparty diligence and executed notices for material pre-sales and receivables.
A23: • Controlled collection accounts, approved counterparties, concentration limits and full cash sweep. | F23: • Maturity takeout plan, liquidity reserve and interest-rate hedging acceptable to lenders.
A25: Monitoring Requirements | F25: Model Validation
A26: • Monthly cash collections, waterfall performance and covenant reporting. | F26: Required Inputs Complete | G26: =IF(SUM(COUNTBLANK('Inputs & Assumptions'!C5:C12),COUNTBLANK('Inputs & Assumptions'!C14:C23),COUNTBLANK('Inputs & Assumptions'!C25:C29),COUNTBLANK('Inputs & Assumptions'!C31:C39),COUNTBLANK('Inputs & Assumptions'!C42:C46),COUNTBLANK('Inputs & Assumptions'!C48:C53),COUNTBLANK('Inputs & Assumptions'!C55:C60),COUNTBLANK('Inputs & Assumptions'!C62:C65),COUNTBLANK('Inputs & Assumptions'!C67:C68),COUNTBLANK('Inputs & Assumptions'!C72:C76),COUNTBLANK('Inputs & Assumptions'!C78:C85))=0,"PASS","FAIL") -> PASS
A27: • Quarterly DSCR, interest coverage, borrowing-base utilization and counterparty concentration. | F27: Channel Mix | G27: ='Inputs & Assumptions'!G70 -> PASS
A28: • Semiannual collateral reappraisal and advance-rate redetermination. | F28: Debt Roll-Forward | G28: =IF(ABS('Debt Service'!F10)<1,"PASS","FAIL") -> PASS
A29: • Immediate reporting of title disputes, tax-credit delays or distributor defaults. | F29: Key Formula Outputs | G29: =IF(OR(ISERROR('Library Valuation'!B32),ISERROR('Borrowing Base'!F11),ISERROR('Debt Service'!B12),ISERROR('Recovery Analysis'!B14),ISERROR('Credit Scorecard'!B15)),"FAIL","PASS") -> PASS
A30: • Annual recovery review and refinancing progress beginning 24 months before maturity. | F30: Maturity Cash Coverage | G30: =IF('Debt Service'!F13>=0,"PASS","FAIL") -> FAIL
F31: Calculation Chain Integrity | G31: =IF(AND(ISNUMBER('Library Valuation'!B32),ISNUMBER('Borrowing Base'!F11),ISNUMBER('Debt Service'!B12),ISNUMBER('Recovery Analysis'!B14)),"PASS","FAIL") -> PASS
A32: Lender Commentary | F32: Circular Reference Review | G32: PASS — no circular linkages identified
A33: ="Base metrics support a conditional approval, but the structure must convert modeled collateral value into enforceable liquidity. The binding issues are downside borrowing-base coverage, declining debt-service capacity and the maturity bullet." -> Base metrics support a conditional approval, but the structure must convert modeled collateral value into enforceable liquidity. The binding issues are downside borrowing-base coverage, declining debt-service capacity and the maturity bullet.
A35: Prepared for Investment Committee review; illustrative assumptions remain subject to confirmatory diligence and final documentation.

Sheet Executive Dashboard
A1: Executive Dashboard — Media & Entertainment Private Credit
A2: Investment question: What are the decisive credit metrics, downside outcomes, and warning flags?
A4: Key Credit Metrics | F4: Early Warning Indicators
A5: Facility Size | B5: ='Inputs & Assumptions'!C36 -> 75000000 | D5: DSCR | E5: ='Debt Service'!B12 -> 1.8961253 | F5: DSCR | G5: =MIN('Debt Service'!B12:E12) -> 1.2009636 | H5: =IF(G5>=1.25,"🟢 STRONG",IF(G5>=1.15,"🟡 MODERATE RISK","🔴 HIGH RISK")) -> 🟡 MODERATE RISK
A6: Borrowing Base | B6: ='Borrowing Base'!F11 -> 92582285 | D6: Interest Coverage | E6: ='Debt Service'!B11 -> 2.2704837 | F6: LTV | G6: ='Borrowing Base'!B17 -> 0.42005807 | H6: =IF(G6<=0.5,"🟢 STRONG",IF(G6<=0.55,"🟡 MODERATE RISK","🔴 HIGH RISK")) -> 🟢 STRONG
A7: Gross Collateral Coverage | B7: ='Borrowing Base'!B16 -> 2.1502276 | D7: Expected Gross Yield | E7: ='Debt Structure'!B20 -> 0.1103 | F7: Borrowing Base Coverage | G7: ='Borrowing Base'!F11/'Inputs & Assumptions'!C36 -> 1.2344305 | H7: =IF(G7>=1.1,"🟢 STRONG",IF(G7>=1,"🟡 MODERATE RISK","🔴 HIGH RISK")) -> 🟢 STRONG
A8: Loan-to-Value | B8: ='Borrowing Base'!B17 -> 0.42005807 | D8: Expected Net Yield | E8: ='Debt Structure'!B22 -> 0.0823 | F8: Downside BB Coverage | G8: ='Scenario Analysis'!C14 -> 0.97249505 | H8: =IF(G8>=1.1,"🟢 STRONG",IF(G8>=1,"🟡 MODERATE RISK","🔴 HIGH RISK")) -> 🔴 HIGH RISK
A9: Borrowing Base Utilization | B9: ='Borrowing Base'!B15 -> 0.81009018 | D9: Risk Rating | E9: =IF('Credit Scorecard'!B14>=4,"1 - Strong",IF('Credit Scorecard'!B14>=3.25,"2 - Acceptable",IF('Credit Scorecard'!B14>=2.75,"3 - Watch","4 - Weak"))) -> 3 - Watch | F9: Recovery | G9: ='Recovery Analysis'!B14 -> 1 | H9: =IF(G9>=0.9,"🟢 STRONG",IF(G9>=0.8,"🟡 MODERATE RISK","🔴 HIGH RISK")) -> 🟢 STRONG
A10: Library Value | B10: ='Library Valuation'!B32 -> 1.3204674e+08 | D10: Credit Recommendation | E10: ='Credit Scorecard'!B15 -> WATCH / RESTRUCTURE TERMS | F10: Interest Coverage | G10: =MIN('Debt Service'!B11:F11) -> 1.4657097 | H10: =IF(G10>=1.5,"🟢 STRONG",IF(G10>=1.25,"🟡 MODERATE RISK","🔴 HIGH RISK")) -> 🟡 MODERATE RISK
A11: Borrowing Base Coverage | B11: ='Borrowing Base'!F11/'Inputs & Assumptions'!C36 -> 1.2344305 | D11: Minimum Pre-Maturity DSCR | E11: =MIN('Debt Service'!B12:E12) -> 1.2009636
A13: Scenario Summary
A14: Metric | B14: Base | C14: Downside | D14: Severe
A15: Borrowing Base | B15: ='Scenario Analysis'!B13 -> 92582285 | C15: ='Scenario Analysis'!C13 -> 72937129 | D15: ='Scenario Analysis'!D13 -> 54700229
A16: Coverage | B16: ='Scenario Analysis'!B14 -> 1.2344305 | C16: ='Scenario Analysis'!C14 -> 0.97249505 | D16: ='Scenario Analysis'!D14 -> 0.72933639
A17: DSCR | B17: ='Scenario Analysis'!B15 -> 1.8961253 | C17: ='Scenario Analysis'!C15 -> 1.3234253 | D17: ='Scenario Analysis'!D15 -> 0.89687952
A20: Borrowing Base Composition — Chart Source | D20: Debt Outstanding — Chart Source | G20: Revenue Decay — Chart Source
A21: Media Library | B21: ='Borrowing Base'!F5 -> 59421035 | D21: Year 1 | E21: ='Debt Service'!B10 -> 69423750 | G21: Year 1 | H21: ='Library Valuation'!B15 -> 25000000
A22: Tax Credits | B22: ='Borrowing Base'!F6 -> 14938750 | D22: Year 2 | E22: ='Debt Service'!C10 -> 65290063 | G22: Year 2 | H22: ='Library Valuation'!C15 -> 20000000
A23: International Pre-sales | B23: ='Borrowing Base'!F7 -> 7560000 | D23: Year 3 | E23: ='Debt Service'!D10 -> 62327005 | G23: Year 3 | H23: ='Library Valuation'!D15 -> 16000000
A24: Receivables | B24: ='Borrowing Base'!F8 -> 5100000 | D24: Year 4 | E24: ='Debt Service'!E10 -> 60041867 | G24: Year 4 | H24: ='Library Valuation'!E15 -> 13600000
A25: Cash | B25: ='Borrowing Base'!F9 -> 5000000 | D25: Year 5 | E25: ='Debt Service'!F10 -> 0 | G25: Year 5 | H25: ='Library Valuation'!F15 -> 12920000
A26: Other Assets | B26: ='Borrowing Base'!F10 -> 562500
A29: Recovery & Coverage | D29: Model Status
A30: Recovery % | B30: ='Recovery Analysis'!B14 -> 1 | D30: Channel Mix Check | E30: ='Inputs & Assumptions'!G70 -> PASS
A31: Loss Severity | B31: ='Recovery Analysis'!B16 -> 0 | D31: Debt Roll-forward | E31: =IF(ABS('Debt Service'!F10)<1,"PASS","FAIL") -> PASS
A32: Downside Coverage | B32: ='Scenario Analysis'!C14 -> 0.97249505 | D32: Borrowing Base Coverage Threshold | E32: =IF(B11>=1.1,"PASS","FAIL") -> PASS
A33: Downside DSCR | B33: ='Scenario Analysis'!C15 -> 1.3234253 | D33: Downside DSCR Threshold | E33: =IF(B33>=1.15,"PASS","FAIL") -> PASS
A34: Maturity Cash Shortfall | B34: =MIN(0,'Debt Service'!F13) -> -57209309 | D34: Maturity Cash Coverage | E34: =IF('Debt Service'!F13>=0,"PASS","FAIL") -> FAIL
A36: Lender Takeaway
A37: ="Base collateral and cash-flow metrics support continued underwriting, but downside borrowing-base coverage of "&TEXT('Scenario Analysis'!C14,"0.00x")&" and a modeled maturity cash shortfall of "&TEXT(ABS('Debt Service'!F13)/1000000,"$0.0")&" million require tighter covenants, cash control and a credible takeout plan." -> Base collateral and cash-flow metrics support continued underwriting, but downside borrowing-base coverage of 0.97x and a modeled maturity cash shortfall of $57.2 million require tighter covenants, cash control and a credible takeout plan.

Sheet Inputs & Assumptions
A1: Inputs & Assumptions — Hypothetical Media & Entertainment Private Credit
A2: Investment question: Which assumptions drive valuation, liquidity, recovery, and credit risk?
A4: Category | B4: Assumption | C4: Value | D4: Units | E4: Source | F4: Publication Date | G4: Comments
A5: Valuation | B5: Discount Rate | C5: 0.08 | D5: % | E5: Illustrative Assumption | F5: 46215 | G5: Editable underwriting input
A6: Valuation | B6: Terminal Growth Rate | C6: 0.02 | D6: % | E6: Illustrative Assumption | F6: 46215 | G6: Used in library terminal value
A7: Revenue | B7: Year 1 Gross Revenue | C7: 25000000 | D7: USD | E7: Illustrative Assumption | F7: 46215 | G7: Hypothetical portfolio revenue
A8: Revenue | B8: Revenue Growth / Decay Year 2 | C8: -0.2 | D8: % | E8: Illustrative Assumption | F8: 46215 | G8: Editable
A9: Revenue | B9: Revenue Growth / Decay Year 3 | C9: -0.2 | D9: % | E9: Illustrative Assumption | F9: 46215 | G9: Editable
A10: Revenue | B10: Revenue Growth / Decay Year 4 | C10: -0.15 | D10: % | E10: Illustrative Assumption | F10: 46215 | G10: Editable
A11: Revenue | B11: Revenue Growth / Decay Year 5 | C11: -0.05 | D11: % | E11: Illustrative Assumption | F11: 46215 | G11: Editable
A12: Revenue | B12: Revenue Growth / Decay Years 6-10 | C12: -0.03 | D12: % | E12: Illustrative Assumption | F12: 46215 | G12: Applied annually
A14: Channel Mix | B14: SVOD | C14: 0.28 | D14: % | E14: Illustrative Assumption | F14: 46215 | G14: Mix totals 100%
A15: Channel Mix | B15: AVOD | C15: 0.1 | D15: % | E15: Illustrative Assumption | F15: 46215 | G15: Mix totals 100%
A16: Channel Mix | B16: FAST | C16: 0.08 | D16: % | E16: Illustrative Assumption | F16: 46215 | G16: Mix totals 100%
A17: Channel Mix | B17: Broadcast | C17: 0.12 | D17: % | E17: Illustrative Assumption | F17: 46215
A18: Channel Mix | B18: International TV | C18: 0.14 | D18: % | E18: Illustrative Assumption | F18: 46215 | G18: Mix totals 100%
A19: Channel Mix | B19: Transactional VOD | C19: 0.1 | D19: % | E19: Illustrative Assumption | F19: 46215 | G19: Mix totals 100%
A20: Channel Mix | B20: Airline | C20: 0.03 | D20: % | E20: Illustrative Assumption | F20: 46215
A21: Channel Mix | B21: Educational | C21: 0.03 | D21: % | E21: Illustrative Assumption | F21: 46215 | G21: Mix totals 100%
A22: Channel Mix | B22: Physical Media | C22: 0.05 | D22: % | E22: Illustrative Assumption | F22: 46215
A23: Channel Mix | B23: Other Licensing | C23: 0.07 | D23: % | E23: Illustrative Assumption | F23: 46215 | G23: Mix totals 100%
A25: Waterfall | B25: Distribution Fee | C25: 0.2 | D25: % | E25: Illustrative Assumption | F25: 46215 | G25: Applied to gross revenue
A26: Waterfall | B26: Residual Rate | C26: 0.05 | D26: % | E26: Illustrative Assumption | F26: 46215 | G26: Applied to gross revenue
A27: Waterfall | B27: Guild Payments | C27: 0.025 | D27: % | E27: Illustrative Assumption | F27: 46215 | G27: Applied to gross revenue
A28: Waterfall | B28: Participations | C28: 0.025 | D28: % | E28: Illustrative Assumption | F28: 46215 | G28: Applied to gross revenue
A29: Waterfall | B29: Collection Account Fee | C29: 0.01 | D29: % | E29: Illustrative Assumption | F29: 46215 | G29: Applied to gross revenue
A31: Debt | B31: SOFR | C31: ='Market Data'!B9 -> 0.0363 | D31: % | E31: Federal Reserve Bank of New York | F31: ='Market Data'!D9 -> 46209 | G31: External market input
A32: Debt | B32: Credit Spread | C32: 0.065 | D32: % | E32: Illustrative Assumption | F32: 46215 | G32: Hypothetical underwriting term
A33: Debt | B33: OID | C33: 0.02 | D33: % | E33: Illustrative Assumption | F33: 46215 | G33: Discount to par
A34: Debt | B34: Upfront Fee | C34: 0.015 | D34: % | E34: Illustrative Assumption | F34: 46215 | G34: On facility size
A35: Debt | B35: Exit Fee | C35: 0.01 | D35: % | E35: Illustrative Assumption | F35: 46215 | G35: On original principal
A36: Debt | B36: Facility Size | C36: 75000000 | D36: USD | E36: Illustrative Assumption | F36: 46215 | G36: Unitranche facility
A37: Debt | B37: Tenor | C37: 5 | D37: Years | E37: Illustrative Assumption | F37: 46215 | G37: Annual model
A38: Debt | B38: Mandatory Amortization | C38: 0.02 | D38: % | E38: Illustrative Assumption | F38: 46215 | G38: Of original principal
A39: Debt | B39: Cash Sweep | C39: 0.5 | D39: % | E39: Illustrative Assumption | F39: 46215 | G39: After mandatory debt service
A41: Collateral | B41: Media Library Gross Value | C41: ='Library Valuation'!B32 -> 1.3204674e+08 | D41: USD | E41: Calculated | F41: 46215 | G41: Linked to library NPV
A42: Collateral | B42: Tax Credits Gross Value | C42: 18500000 | D42: USD | E42: Illustrative Assumption | F42: 46215 | G42: Not public transaction data
A43: Collateral | B43: International Pre-sales Gross Value | C43: 12000000 | D43: USD | E43: Illustrative Assumption | F43: 46215 | G43: Not public transaction data
A44: Collateral | B44: Receivables Gross Value | C44: 8000000 | D44: USD | E44: Illustrative Assumption | F44: 46215 | G44: Hypothetical
A45: Collateral | B45: Cash | C45: 5000000 | D45: USD | E45: Illustrative Assumption | F45: 46215 | G45: Hypothetical
...

Sheet Library Valuation
A1: Entertainment Library Valuation
A2: Investment question: What is the present value of recurring library cash flow after decay and waterfall deductions?
A4: Revenue Channel | B4: Year 1 | C4: Year 2 | D4: Year 3 | E4: Year 4 | F4: Year 5 | G4: Year 6 | H4: Year 7 | I4: Year 8 | J4: Year 9 | K4: Year 10
A5: SVOD | B5: ='Inputs & Assumptions'!$C$7*'Inputs & Assumptions'!$C$14 -> 7000000 | C5: =B5*(1+C$16) -> 5600000 | D5: =C5*(1+D$16) -> 4480000 | E5: =D5*(1+E$16) -> 3808000 | F5: =E5*(1+F$16) -> 3617600 | G5: =F5*(1+G$16) -> 3509072 | H5: =G5*(1+H$16) -> 3403799.8 | I5: =H5*(1+I$16) -> 3301685.8 | J5: =I5*(1+J$16) -> 3202635.3 | K5: =J5*(1+K$16) -> 3106556.2
A6: AVOD | B6: ='Inputs & Assumptions'!$C$7*'Inputs & Assumptions'!$C$15 -> 2500000 | C6: =B6*(1+C$16) -> 2000000 | D6: =C6*(1+D$16) -> 1600000 | E6: =D6*(1+E$16) -> 1360000 | F6: =E6*(1+F$16) -> 1292000 | G6: =F6*(1+G$16) -> 1253240 | H6: =G6*(1+H$16) -> 1215642.8 | I6: =H6*(1+I$16) -> 1179173.5 | J6: =I6*(1+J$16) -> 1143798.3 | K6: =J6*(1+K$16) -> 1109484.4
A7: FAST | B7: ='Inputs & Assumptions'!$C$7*'Inputs & Assumptions'!$C$16 -> 2000000 | C7: =B7*(1+C$16) -> 1600000 | D7: =C7*(1+D$16) -> 1280000 | E7: =D7*(1+E$16) -> 1088000 | F7: =E7*(1+F$16) -> 1033600 | G7: =F7*(1+G$16) -> 1002592 | H7: =G7*(1+H$16) -> 972514.24 | I7: =H7*(1+I$16) -> 943338.81 | J7: =I7*(1+J$16) -> 915038.65 | K7: =J7*(1+K$16) -> 887587.49
A8: Broadcast | B8: ='Inputs & Assumptions'!$C$7*'Inputs & Assumptions'!$C$17 -> 3000000 | C8: =B8*(1+C$16) -> 2400000 | D8: =C8*(1+D$16) -> 1920000 | E8: =D8*(1+E$16) -> 1632000 | F8: =E8*(1+F$16) -> 1550400 | G8: =F8*(1+G$16) -> 1503888 | H8: =G8*(1+H$16) -> 1458771.4 | I8: =H8*(1+I$16) -> 1415008.2 | J8: =I8*(1+J$16) -> 1372558 | K8: =J8*(1+K$16) -> 1331381.2
A9: International TV | B9: ='Inputs & Assumptions'!$C$7*'Inputs & Assumptions'!$C$18 -> 3500000 | C9: =B9*(1+C$16) -> 2800000 | D9: =C9*(1+D$16) -> 2240000 | E9: =D9*(1+E$16) -> 1904000 | F9: =E9*(1+F$16) -> 1808800 | G9: =F9*(1+G$16) -> 1754536 | H9: =G9*(1+H$16) -> 1701899.9 | I9: =H9*(1+I$16) -> 1650842.9 | J9: =I9*(1+J$16) -> 1601317.6 | K9: =J9*(1+K$16) -> 1553278.1
A10: Transactional VOD | B10: ='Inputs & Assumptions'!$C$7*'Inputs & Assumptions'!$C$19 -> 2500000 | C10: =B10*(1+C$16) -> 2000000 | D10: =C10*(1+D$16) -> 1600000 | E10: =D10*(1+E$16) -> 1360000 | F10: =E10*(1+F$16) -> 1292000 | G10: =F10*(1+G$16) -> 1253240 | H10: =G10*(1+H$16) -> 1215642.8 | I10: =H10*(1+I$16) -> 1179173.5 | J10: =I10*(1+J$16) -> 1143798.3 | K10: =J10*(1+K$16) -> 1109484.4
A11: Airline | B11: ='Inputs & Assumptions'!$C$7*'Inputs & Assumptions'!$C$20 -> 750000 | C11: =B11*(1+C$16) -> 600000 | D11: =C11*(1+D$16) -> 480000 | E11: =D11*(1+E$16) -> 408000 | F11: =E11*(1+F$16) -> 387600 | G11: =F11*(1+G$16) -> 375972 | H11: =G11*(1+H$16) -> 364692.84 | I11: =H11*(1+I$16) -> 353752.05 | J11: =I11*(1+J$16) -> 343139.49 | K11: =J11*(1+K$16) -> 332845.31
A12: Educational | B12: ='Inputs & Assumptions'!$C$7*'Inputs & Assumptions'!$C$21 -> 750000 | C12: =B12*(1+C$16) -> 600000 | D12: =C12*(1+D$16) -> 480000 | E12: =D12*(1+E$16) -> 408000 | F12: =E12*(1+F$16) -> 387600 | G12: =F12*(1+G$16) -> 375972 | H12: =G12*(1+H$16) -> 364692.84 | I12: =H12*(1+I$16) -> 353752.05 | J12: =I12*(1+J$16) -> 343139.49 | K12: =J12*(1+K$16) -> 332845.31
A13: Physical Media | B13: ='Inputs & Assumptions'!$C$7*'Inputs & Assumptions'!$C$22 -> 1250000 | C13: =B13*(1+C$16) -> 1000000 | D13: =C13*(1+D$16) -> 800000 | E13: =D13*(1+E$16) -> 680000 | F13: =E13*(1+F$16) -> 646000 | G13: =F13*(1+G$16) -> 626620 | H13: =G13*(1+H$16) -> 607821.4 | I13: =H13*(1+I$16) -> 589586.76 | J13: =I13*(1+J$16) -> 571899.16 | K13: =J13*(1+K$16) -> 554742.18
A14: Other Licensing | B14: ='Inputs & Assumptions'!$C$7*'Inputs & Assumptions'!$C$23 -> 1750000 | C14: =B14*(1+C$16) -> 1400000 | D14: =C14*(1+D$16) -> 1120000 | E14: =D14*(1+E$16) -> 952000 | F14: =E14*(1+F$16) -> 904400 | G14: =F14*(1+G$16) -> 877268 | H14: =G14*(1+H$16) -> 850949.96 | I14: =H14*(1+I$16) -> 825421.46 | J14: =I14*(1+J$16) -> 800658.82 | K14: =J14*(1+K$16) -> 776639.05
A15: Gross Revenue | B15: =SUM(B5:B14) -> 25000000 | C15: =SUM(C5:C14) -> 20000000 | D15: =SUM(D5:D14) -> 16000000 | E15: =SUM(E5:E14) -> 13600000 | F15: =SUM(F5:F14) -> 12920000 | G15: =SUM(G5:G14) -> 12532400 | H15: =SUM(H5:H14) -> 12156428 | I15: =SUM(I5:I14) -> 11791735 | ... K15: =SUM(K5:K14) -> 11094844
A16: Revenue Growth / Decay | B16: 0 | C16: ='Inputs & Assumptions'!$C$8 -> -0.2 | D16: ='Inputs & Assumptions'!$C$9 -> -0.2 | E16: ='Inputs & Assumptions'!$C$10 -> -0.15 | F16: ='Inputs & Assumptions'!$C$11 -> -0.05 | G16: ='Inputs & Assumptions'!$C$12 -> -0.03 | H16: ='Inputs & Assumptions'!$C$12 -> -0.03 | I16: ='Inputs & Assumptions'!$C$12 -> -0.03 | J16: ='Inputs & Assumptions'!$C$12 -> -0.03 | K16: ='Inputs & Assumptions'!$C$12 -> -0.03
A18: Less: Distribution Fee | B18: =B15*'Inputs & Assumptions'!$C$25 -> 5000000 | C18: =C15*'Inputs & Assumptions'!$C$25 -> 4000000 | D18: =D15*'Inputs & Assumptions'!$C$25 -> 3200000 | E18: =E15*'Inputs & Assumptions'!$C$25 -> 2720000 | F18: =F15*'Inputs & Assumptions'!$C$25 -> 2584000 | G18: =G15*'Inputs & Assumptions'!$C$25 -> 2506480 | H18: =H15*'Inputs & Assumptions'!$C$25 -> 2431285.6 | I18: =I15*'Inputs & Assumptions'!$C$25 -> 2358347 | ... K18: =K15*'Inputs & Assumptions'!$C$25 -> 2218968.7
A19: Less: Residuals | B19: =B15*'Inputs & Assumptions'!$C$26 -> 1250000 | C19: =C15*'Inputs & Assumptions'!$C$26 -> 1000000 | D19: =D15*'Inputs & Assumptions'!$C$26 -> 800000 | E19: =E15*'Inputs & Assumptions'!$C$26 -> 680000 | F19: =F15*'Inputs & Assumptions'!$C$26 -> 646000 | G19: =G15*'Inputs & Assumptions'!$C$26 -> 626620 | H19: =H15*'Inputs & Assumptions'!$C$26 -> 607821.4 | I19: =I15*'Inputs & Assumptions'!$C$26 -> 589586.76 | ... K19: =K15*'Inputs & Assumptions'!$C$26 -> 554742.18
A20: Less: Guild Payments | B20: =B15*'Inputs & Assumptions'!$C$27 -> 625000 | C20: =C15*'Inputs & Assumptions'!$C$27 -> 500000 | D20: =D15*'Inputs & Assumptions'!$C$27 -> 400000 | E20: =E15*'Inputs & Assumptions'!$C$27 -> 340000 | F20: =F15*'Inputs & Assumptions'!$C$27 -> 323000 | G20: =G15*'Inputs & Assumptions'!$C$27 -> 313310 | H20: =H15*'Inputs & Assumptions'!$C$27 -> 303910.7 | I20: =I15*'Inputs & Assumptions'!$C$27 -> 294793.38 | ... K20: =K15*'Inputs & Assumptions'!$C$27 -> 277371.09
A21: Less: Participations | B21: =B15*'Inputs & Assumptions'!$C$28 -> 625000 | C21: =C15*'Inputs & Assumptions'!$C$28 -> 500000 | D21: =D15*'Inputs & Assumptions'!$C$28 -> 400000 | E21: =E15*'Inputs & Assumptions'!$C$28 -> 340000 | F21: =F15*'Inputs & Assumptions'!$C$28 -> 323000 | G21: =G15*'Inputs & Assumptions'!$C$28 -> 313310 | H21: =H15*'Inputs & Assumptions'!$C$28 -> 303910.7 | I21: =I15*'Inputs & Assumptions'!$C$28 -> 294793.38 | ... K21: =K15*'Inputs & Assumptions'!$C$28 -> 277371.09
A22: Less: Collection Account | B22: =B15*'Inputs & Assumptions'!$C$29 -> 250000 | C22: =C15*'Inputs & Assumptions'!$C$29 -> 200000 | D22: =D15*'Inputs & Assumptions'!$C$29 -> 160000 | E22: =E15*'Inputs & Assumptions'!$C$29 -> 136000 | F22: =F15*'Inputs & Assumptions'!$C$29 -> 129200 | G22: =G15*'Inputs & Assumptions'!$C$29 -> 125324 | H22: =H15*'Inputs & Assumptions'!$C$29 -> 121564.28 | I22: =I15*'Inputs & Assumptions'!$C$29 -> 117917.35 | ... K22: =K15*'Inputs & Assumptions'!$C$29 -> 110948.44
A23: Annual Free Cash Flow | B23: =B15-SUM(B18:B22) -> 17250000 | C23: =C15-SUM(C18:C22) -> 13800000 | D23: =D15-SUM(D18:D22) -> 11040000 | E23: =E15-SUM(E18:E22) -> 9384000 | F23: =F15-SUM(F18:F22) -> 8914800 | G23: =G15-SUM(G18:G22) -> 8647356 | H23: =H15-SUM(H18:H22) -> 8387935.3 | I23: =I15-SUM(I18:I22) -> 8136297.3 | ... K23: =K15-SUM(K18:K22) -> 7655442.1
A24: Discount Factor | B24: =1/(1+'Inputs & Assumptions'!$C$5)^1 -> 0.92592593 | C24: =1/(1+'Inputs & Assumptions'!$C$5)^2 -> 0.85733882 | D24: =1/(1+'Inputs & Assumptions'!$C$5)^3 -> 0.79383224 | E24: =1/(1+'Inputs & Assumptions'!$C$5)^4 -> 0.73502985 | F24: =1/(1+'Inputs & Assumptions'!$C$5)^5 -> 0.6805832 | G24: =1/(1+'Inputs & Assumptions'!$C$5)^6 -> 0.63016963 | H24: =1/(1+'Inputs & Assumptions'!$C$5)^7 -> 0.5834904 | I24: =1/(1+'Inputs & Assumptions'!$C$5)^8 -> 0.54026888 | J24: =1/(1+'Inputs & Assumptions'!$C$5)^9 -> 0.50024897 | K24: =1/(1+'Inputs & Assumptions'!$C$5)^10 -> 0.46319349
A25: Present Value of FCF | B25: =B23*B24 -> 15972222 | C25: =C23*C24 -> 11831276 | D25: =D23*D24 -> 8763907.9 | E25: =E23*E24 -> 6897520.1 | F25: =F23*F24 -> 6067263.1 | G25: =G23*G24 -> 5449301.1 | H25: =H23*H24 -> 4894279.7 | I25: =I23*I24 -> 4395788.2 | ... K25: =K23*K24 -> 3545950.9
A27: Terminal Value | K27: =K23*(1+'Inputs & Assumptions'!$C$6)/('Inputs & Assumptions'!$C$5-'Inputs & Assumptions'!$C$6) -> 1.3014252e+08
A28: PV of Terminal Value | K28: =K27/(1+'Inputs & Assumptions'!$C$5)^10 -> 60281166
A30: PV of Explicit FCF | B30: =SUM(B25:K25) -> 71765578
A31: PV of Terminal Value | B31: =K28 -> 60281166
A32: Total Library NPV | B32: =SUM(B30:B31) -> 1.3204674e+08
A34: Lender Takeaway
A35: ="Library value is "&TEXT(B32/1000000,"$0.0")&" million, but terminal value represents "&TEXT(B31/B32,"0%")&" of total NPV and remains sensitive to discount rate and long-tail decay." -> Library value is $132.0 million, but terminal value represents 46% of total NPV and remains sensitive to discount rate and long-tail decay.

Sheet Revenue Waterfall
A1: Revenue Waterfall
A2: Investment question: How much cash remains available for debt service after contractual deductions?
A4: Waterfall Step | B4: Year 1 | C4: Year 2 | D4: Year 3 | E4: Year 4 | F4: Year 5
A5: Gross Revenue | B5: ='Library Valuation'!B15 -> 25000000 | C5: ='Library Valuation'!C15 -> 20000000 | D5: ='Library Valuation'!D15 -> 16000000 | E5: ='Library Valuation'!E15 -> 13600000 | F5: ='Library Valuation'!F15 -> 12920000
A6: Less: Distribution Fee | B6: =B5*'Inputs & Assumptions'!$C$25 -> 5000000 | C6: =C5*'Inputs & Assumptions'!$C$25 -> 4000000 | D6: =D5*'Inputs & Assumptions'!$C$25 -> 3200000 | E6: =E5*'Inputs & Assumptions'!$C$25 -> 2720000 | F6: =F5*'Inputs & Assumptions'!$C$25 -> 2584000
A7: Less: Residuals | B7: =B5*'Inputs & Assumptions'!$C$26 -> 1250000 | C7: =C5*'Inputs & Assumptions'!$C$26 -> 1000000 | D7: =D5*'Inputs & Assumptions'!$C$26 -> 800000 | E7: =E5*'Inputs & Assumptions'!$C$26 -> 680000 | F7: =F5*'Inputs & Assumptions'!$C$26 -> 646000
A8: Less: Guild Payments | B8: =B5*'Inputs & Assumptions'!$C$27 -> 625000 | C8: =C5*'Inputs & Assumptions'!$C$27 -> 500000 | D8: =D5*'Inputs & Assumptions'!$C$27 -> 400000 | E8: =E5*'Inputs & Assumptions'!$C$27 -> 340000 | F8: =F5*'Inputs & Assumptions'!$C$27 -> 323000
A9: Less: Participations | B9: =B5*'Inputs & Assumptions'!$C$28 -> 625000 | C9: =C5*'Inputs & Assumptions'!$C$28 -> 500000 | D9: =D5*'Inputs & Assumptions'!$C$28 -> 400000 | E9: =E5*'Inputs & Assumptions'!$C$28 -> 340000 | F9: =F5*'Inputs & Assumptions'!$C$28 -> 323000
A10: Less: Collection Account | B10: =B5*'Inputs & Assumptions'!$C$29 -> 250000 | C10: =C5*'Inputs & Assumptions'!$C$29 -> 200000 | D10: =D5*'Inputs & Assumptions'!$C$29 -> 160000 | E10: =E5*'Inputs & Assumptions'!$C$29 -> 136000 | F10: =F5*'Inputs & Assumptions'!$C$29 -> 129200
A11: Available Cash Flow | B11: =B5-SUM(B6:B10) -> 17250000 | C11: =C5-SUM(C6:C10) -> 13800000 | D11: =D5-SUM(D6:D10) -> 11040000 | E11: =E5-SUM(E6:E10) -> 9384000 | F11: =F5-SUM(F6:F10) -> 8914800
A12: Debt Service | B12: ='Debt Service'!B9 -> 13173750 | C12: ='Debt Service'!C9 -> 11166313 | D12: ='Debt Service'!D9 -> 9576941.7 | E12: ='Debt Service'!E9 -> 8598862.8 | F12: ='Debt Service'!F9 -> 66124109
A13: Cash Remaining | B13: =B11-B12 -> 4076250 | C13: =C11-C12 -> 2633687.1 | D13: =D11-D12 -> 1463058.3 | E13: =E11-E12 -> 785137.22 | F13: =F11-F12 -> -57209309
A16: Chart Source — Waterfall (Year 1)
A17: Gross Revenue | B17: =B5 -> 25000000
A18: Distribution Fee | B18: =-B6 -> -5000000
A19: Residuals | B19: =-B7 -> -1250000
A20: Guild Payments | B20: =-B8 -> -625000
A21: Participations | B21: =-B9 -> -625000
A22: Collection Account | B22: =-B10 -> -250000
A23: Available Cash Flow | B23: =B11 -> 17250000
A25: Lender Takeaway
A26: ="Available cash flow declines from "&TEXT(B11/1000000,"$0.0")&" million to "&TEXT(F11/1000000,"$0.0")&" million, reducing debt-service flexibility as the library seasons." -> Available cash flow declines from $17.3 million to $8.9 million, reducing debt-service flexibility as the library seasons.

Sheet Borrowing Base
A1: Borrowing Base
A2: Investment question: How much lendable value remains after eligibility tests, haircuts, and advance rates?
A4: Collateral | B4: Gross Value | C4: Advance Rate | D4: Haircut | E4: Eligible Value | F4: Borrowing Base | G4: Unused Capacity | H4: Collateral Coverage
A5: Media Library | B5: ='Inputs & Assumptions'!C41 -> 1.3204674e+08 | C5: ='Inputs & Assumptions'!C48 -> 0.5 | D5: ='Inputs & Assumptions'!C55 -> 0.1 | E5: =B5*(1-D5) -> 1.1884207e+08 | F5: =E5*C5 -> 59421035 | G5: =MAX(0,F5-'Inputs & Assumptions'!$C$36) -> 0 | H5: =E5/'Inputs & Assumptions'!$C$36 -> 1.5845609
A6: Tax Credits | B6: ='Inputs & Assumptions'!C42 -> 18500000 | C6: ='Inputs & Assumptions'!C49 -> 0.85 | D6: ='Inputs & Assumptions'!C56 -> 0.05 | E6: =B6*(1-D6) -> 17575000 | F6: =E6*C6 -> 14938750 | G6: =MAX(0,F6-MAX(0,'Inputs & Assumptions'!$C$36-F5)) -> 0 | H6: =E6/'Inputs & Assumptions'!$C$36 -> 0.23433333
A7: International Pre-sales | B7: ='Inputs & Assumptions'!C43 -> 12000000 | C7: ='Inputs & Assumptions'!C50 -> 0.7 | D7: ='Inputs & Assumptions'!C57 -> 0.1 | E7: =B7*(1-D7) -> 10800000 | F7: =E7*C7 -> 7560000 | G7: =MAX(0,F7-MAX(0,'Inputs & Assumptions'!$C$36-SUM(F5:F6))) -> 6919784.7 | H7: =E7/'Inputs & Assumptions'!$C$36 -> 0.144
A8: Receivables | B8: ='Inputs & Assumptions'!C44 -> 8000000 | C8: ='Inputs & Assumptions'!C51 -> 0.75 | D8: ='Inputs & Assumptions'!C58 -> 0.15 | E8: =B8*(1-D8) -> 6800000 | F8: =E8*C8 -> 5100000 | G8: =MAX(0,F8-MAX(0,'Inputs & Assumptions'!$C$36-SUM(F5:F7))) -> 5100000 | H8: =E8/'Inputs & Assumptions'!$C$36 -> 0.090666667
A9: Cash | B9: ='Inputs & Assumptions'!C45 -> 5000000 | C9: ='Inputs & Assumptions'!C52 -> 1 | D9: ='Inputs & Assumptions'!C59 -> 0 | E9: =B9*(1-D9) -> 5000000 | F9: =E9*C9 -> 5000000 | G9: =MAX(0,F9-MAX(0,'Inputs & Assumptions'!$C$36-SUM(F5:F8))) -> 5000000 | H9: =E9/'Inputs & Assumptions'!$C$36 -> 0.066666667
A10: Other Assets | B10: ='Inputs & Assumptions'!C46 -> 3000000 | C10: ='Inputs & Assumptions'!C53 -> 0.25 | D10: ='Inputs & Assumptions'!C60 -> 0.25 | E10: =B10*(1-D10) -> 2250000 | F10: =E10*C10 -> 562500 | G10: =MAX(0,F10-MAX(0,'Inputs & Assumptions'!$C$36-SUM(F5:F9))) -> 562500 | H10: =E10/'Inputs & Assumptions'!$C$36 -> 0.03
A11: Total | B11: =SUM(B5:B10) -> 1.7854674e+08 | E11: =SUM(E5:E10) -> 1.6126707e+08 | F11: =SUM(F5:F10) -> 92582285 | G11: =MAX(0,F11-'Inputs & Assumptions'!$C$36) -> 17582285 | H11: =E11/'Inputs & Assumptions'!$C$36 -> 2.1502276
A14: Facility Size | B14: ='Inputs & Assumptions'!C36 -> 75000000
A15: Borrowing Base Utilization | B15: =B14/F11 -> 0.81009018
A16: Collateral Coverage | B16: =E11/B14 -> 2.1502276
A17: Loan-to-Value | B17: =B14/B11 -> 0.42005807
A19: Lender Takeaway
A20: ="The "&TEXT(F11/1000000,"$0.0")&" million borrowing base covers the facility by "&TEXT(F11/B14,"0.00x")&"; this is distinct from "&TEXT(E11/B14,"0.00x")&" gross eligible collateral coverage." -> The $92.6 million borrowing base covers the facility by 1.23x; this is distinct from 2.15x gross eligible collateral coverage.

Sheet Debt Structure
A1: Debt Structure
A2: Investment question: Do pricing, amortization, and lender economics compensate for the modeled risk?
A4: Term | B4: Value | C4: Units / Structure
A5: Facility Size | B5: ='Inputs & Assumptions'!C36 -> 75000000 | C5: USD
A6: SOFR | B6: ='Inputs & Assumptions'!C31 -> 0.0363 | C6: Floating benchmark
A7: Credit Spread | B7: ='Inputs & Assumptions'!C32 -> 0.065 | C7: Margin
A8: All-in Coupon | B8: =B6+B7 -> 0.1013 | C8: Floating
A9: OID | B9: ='Inputs & Assumptions'!C33 -> 0.02 | C9: Discount to par
A10: Upfront Fee | B10: ='Inputs & Assumptions'!C34 -> 0.015 | C10: On commitments
A11: Exit Fee | B11: ='Inputs & Assumptions'!C35 -> 0.01 | C11: On original principal
A12: Amortization | B12: ='Inputs & Assumptions'!C38 -> 0.02 | C12: Annual mandatory
A13: Bullet Payment | B13: =1-B12*'Inputs & Assumptions'!C37 -> 0.9 | C13: At maturity before sweep
A14: Cash Sweep | B14: ='Inputs & Assumptions'!C39 -> 0.5 | C14: Excess cash flow
A15: Interest Frequency | B15: Quarterly | C15: Illustrative Assumption
A16: Tenor | B16: ='Inputs & Assumptions'!C37 -> 5 | C16: Years
A17: Maturity | B17: =DATE(2026+'Inputs & Assumptions'!C37,12,31) -> 48213 | C17: Illustrative date
A20: Gross Yield | B20: =B8+B10/'Inputs & Assumptions'!C37+B11/'Inputs & Assumptions'!C37+B9/'Inputs & Assumptions'!C37 -> 0.1103
A21: Expected Credit Loss | B21: ='Inputs & Assumptions'!C63*'Inputs & Assumptions'!C64 -> 0.028
A22: Expected Net Yield | B22: =B20-B21 -> 0.0823
A24: Lender Takeaway
A25: ="Expected net yield is "&TEXT(B22,"0.0%")&" after modeled credit loss, with a material maturity bullet that requires active deleveraging and takeout planning." -> Expected net yield is 8.2% after modeled credit loss, with a material maturity bullet that requires active deleveraging and takeout planning.

Sheet Debt Service
A1: Debt Service Schedule
A2: Investment question: Can recurring cash flow service interest and scheduled principal through maturity?
A4: Metric | B4: Year 1 | C4: Year 2 | D4: Year 3 | E4: Year 4 | F4: Year 5
A5: Opening Balance | B5: ='Inputs & Assumptions'!C36 -> 75000000 | C5: =B10 -> 69423750 | D5: =C10 -> 65290063 | E5: =D10 -> 62327005 | F5: =E10 -> 60041867
A6: Cash Interest | B6: =B5*'Debt Structure'!B8 -> 7597500 | C6: =C5*'Debt Structure'!B8 -> 7032625.9 | D6: =D5*'Debt Structure'!$B$8 -> 6613883.4 | E6: =E5*'Debt Structure'!$B$8 -> 6313725.6 | F6: =F5*'Debt Structure'!$B$8 -> 6082241.2
A7: Mandatory Amortization | B7: =MIN(B5,'Inputs & Assumptions'!$C$36*'Inputs & Assumptions'!$C$38) -> 1500000 | C7: =MIN(C5,'Inputs & Assumptions'!$C$36*'Inputs & Assumptions'!$C$38) -> 1500000 | D7: =MIN(D5,'Inputs & Assumptions'!$C$36*'Inputs & Assumptions'!$C$38) -> 1500000 | E7: =MIN(E5,'Inputs & Assumptions'!$C$36*'Inputs & Assumptions'!$C$38) -> 1500000 | F7: =MIN(F5,'Inputs & Assumptions'!$C$36*'Inputs & Assumptions'!$C$38) -> 1500000
A8: Cash Sweep | B8: =MIN(MAX(0,'Revenue Waterfall'!B11-B6-B7)*'Inputs & Assumptions'!$C$39,B5-B7) -> 4076250 | C8: =MIN(MAX(0,'Revenue Waterfall'!C11-C6-C7)*'Inputs & Assumptions'!$C$39,C5-C7) -> 2633687.1 | D8: =MIN(MAX(0,'Revenue Waterfall'!D11-D6-D7)*'Inputs & Assumptions'!$C$39,D5-D7) -> 1463058.3 | E8: =MIN(MAX(0,'Revenue Waterfall'!E11-E6-E7)*'Inputs & Assumptions'!$C$39,E5-E7) -> 785137.22 | F8: =MAX(0,F5-F7) -> 58541867
A9: Total Debt Service | B9: =SUM(B6:B8) -> 13173750 | C9: =SUM(C6:C8) -> 11166313 | D9: =SUM(D6:D8) -> 9576941.7 | E9: =SUM(E6:E8) -> 8598862.8 | F9: =SUM(F6:F8) -> 66124109
A10: Ending Balance | B10: =B5-B7-B8 -> 69423750 | C10: =C5-C7-C8 -> 65290063 | D10: =D5-D7-D8 -> 62327005 | E10: =E5-E7-E8 -> 60041867 | F10: =0 -> 0
A11: Interest Coverage | B11: ='Revenue Waterfall'!B11/B6 -> 2.2704837 | C11: ='Revenue Waterfall'!C11/C6 -> 1.9622827 | D11: ='Revenue Waterfall'!D11/D6 -> 1.669216 | E11: ='Revenue Waterfall'!E11/E6 -> 1.4862857 | F11: ='Revenue Waterfall'!F11/F6 -> 1.4657097
A12: DSCR | B12: ='Revenue Waterfall'!B11/(B6+B7) -> 1.8961253 | C12: ='Revenue Waterfall'!C11/(C6+C7) -> 1.6173216 | D12: ='Revenue Waterfall'!D11/(D6+D7) -> 1.3606308 | E12: ='Revenue Waterfall'!E11/(E6+E7) -> 1.2009636 | F12: ='Revenue Waterfall'!F11/F9 -> 0.13481921
A13: Cash Remaining | B13: ='Revenue Waterfall'!B11-B9 -> 4076250 | C13: ='Revenue Waterfall'!C11-C9 -> 2633687.1 | D13: ='Revenue Waterfall'!D11-D9 -> 1463058.3 | E13: ='Revenue Waterfall'!E11-E9 -> 785137.22 | F13: ='Revenue Waterfall'!F11-F9 -> -57209309
A15: Lender Takeaway
A16: ="Minimum pre-maturity DSCR is "&TEXT(MIN(B12:E12),"0.00x")&" and maturity cash coverage fails by "&TEXT(ABS(F13)/1000000,"$0.0")&" million, making refinancing risk the binding credit issue." -> Minimum pre-maturity DSCR is 1.20x and maturity cash coverage fails by $57.2 million, making refinancing risk the binding credit issue.

Sheet Sensitivity Analysis
A1: Sensitivity Analysis
A2: Investment question: Which valuation and coverage assumptions most quickly erode lender protection?
A4: Discount Rate Sensitivity
A5: Discount Rate | B5: 0.06 | C5: 0.08 | D5: 0.1 | E5: 0.12
A6: Library Value | B6: {=NPV(B5,'Library Valuation'!B23:K23)+'Library Valuation'!K23*(1+'Inputs & Assumptions'!C6)/(B5-'Inputs & Assumptions'!C6)/(1+B5)^10} -> 1.8665141e+08 | C6: {=NPV(C5,'Library Valuation'!B23:K23)+'Library Valuation'!K23*(1+'Inputs & Assumptions'!C6)/(C5-'Inputs & Assumptions'!C6)/(1+C5)^10} -> 1.3204674e+08 | D6: {=NPV(D5,'Library Valuation'!B23:K23)+'Library Valuation'!K23*(1+'Inputs & Assumptions'!C6)/(D5-'Inputs & Assumptions'!C6)/(1+D5)^10} -> 104237518 | E6: {=NPV(E5,'Library Valuation'!B23:K23)+'Library Valuation'!K23*(1+'Inputs & Assumptions'!C6)/(E5-'Inputs & Assumptions'!C6)/(1+E5)^10} -> 87197024
A8: Revenue Decline Sensitivity
A9: Revenue Multiplier | B9: 1 | C9: 0.9 | D9: 0.8 | E9: 0.7
A10: Borrowing Base | B10: ='Borrowing Base'!F11 -> 92582285 | C10: ='Borrowing Base'!F11*C9 -> 83324056 | D10: ='Borrowing Base'!F11*D9 -> 74065828 | E10: ='Borrowing Base'!F11*E9 -> 64807599
A11: Coverage | B11: =B10/'Inputs & Assumptions'!C36 -> 1.2344305 | C11: =C10/'Inputs & Assumptions'!C36 -> 1.1109874 | D11: =D10/'Inputs & Assumptions'!C36 -> 0.98754437 | E11: =E10/'Inputs & Assumptions'!C36 -> 0.86410132
A13: Interest Rate Sensitivity
A14: Rate Increase | B14: 0 | C14: 0.01 | D14: 0.02 | E14: 0.03
A15: DSCR | B15: ='Revenue Waterfall'!B11/('Debt Service'!B7+'Debt Service'!B5*('Debt Structure'!B8+B14)) -> 1.8961253 | C15: ='Revenue Waterfall'!B11/('Debt Service'!B7+'Debt Service'!B5*('Debt Structure'!B8+C14)) -> 1.7517136 | D15: ='Revenue Waterfall'!B11/('Debt Service'!B7+'Debt Service'!B5*('Debt Structure'!B8+D14)) -> 1.6277424 | E15: ='Revenue Waterfall'!B11/('Debt Service'!B7+'Debt Service'!B5*('Debt Structure'!B8+E14)) -> 1.5201586
A17: Advance Rate Sensitivity
A18: Library Advance Rate | B18: 0.4 | C18: 0.5 | D18: 0.6 | E18: 0.7
A19: Borrowing Base | B19: ='Borrowing Base'!E5*B18+SUM('Borrowing Base'!F6:F10) -> 80698078 | C19: ='Borrowing Base'!E5*C18+SUM('Borrowing Base'!F6:F10) -> 92582285 | D19: ='Borrowing Base'!E5*D18+SUM('Borrowing Base'!F6:F10) -> 1.0446649e+08 | E19: ='Borrowing Base'!E5*E18+SUM('Borrowing Base'!F6:F10) -> 1.163507e+08
A20: Facility Utilization | B20: ='Inputs & Assumptions'!C36/B19 -> 0.92939017 | C20: ='Inputs & Assumptions'!C36/C19 -> 0.81009018 | D20: ='Inputs & Assumptions'!C36/D19 -> 0.71793356 | E20: ='Inputs & Assumptions'!C36/E19 -> 0.64460292
A22: Lender Takeaway
A23: ="Coverage falls below 1.00x at an approximately 20% borrowing-base reduction, while rate stress remains manageable in Year 1; collateral deterioration is the more binding risk." -> Coverage falls below 1.00x at an approximately 20% borrowing-base reduction, while rate stress remains manageable in Year 1; collateral deterioration is the more binding risk.

Sheet Scenario Analysis
A1: Scenario Analysis
A2: Investment question: How does the facility perform under coordinated revenue, collateral, and rate stress?
A4: Driver | B4: Base Case | C4: Downside Case | D4: Severe Downside
A5: Revenue Multiplier | B5: 1 | C5: 0.85 | D5: 0.7
A6: Tax Credits Multiplier | B6: 1 | C6: 0.9 | D6: 0.75
A7: Pre-sales Multiplier | B7: 1 | C7: 0.85 | D7: 0.65
A8: Distribution Fee | B8: ='Inputs & Assumptions'!C25 -> 0.2 | C8: =B8+0.03 -> 0.23 | D8: =B8+0.07 -> 0.27
A9: Interest Rate Increase | B9: 0 | C9: 0.02 | D9: 0.04
A10: Additional Haircut | B10: 0 | C10: 0.1 | D10: 0.2
A12: Library Value | B12: ='Library Valuation'!B32 -> 1.3204674e+08 | C12: =B12*C5*(1-C10) -> 1.0101576e+08 | D12: =B12*D5*(1-D10) -> 73946177
A13: Borrowing Base | B13: ='Borrowing Base'!F11 -> 92582285 | C13: =('Borrowing Base'!F5*C5*(1-C10))+('Borrowing Base'!F6*C6*(1-C10))+('Borrowing Base'!F7*C7*(1-C10))+SUM('Borrowing Base'!F8:F10)*(1-C10) -> 72937129 | D13: =('Borrowing Base'!F5*D5*(1-D10))+('Borrowing Base'!F6*D6*(1-D10))+('Borrowing Base'!F7*D7*(1-D10))+SUM('Borrowing Base'!F8:F10)*(1-D10) -> 54700229
A14: Coverage | B14: =B13/'Inputs & Assumptions'!C36 -> 1.2344305 | C14: =C13/'Inputs & Assumptions'!C36 -> 0.97249505 | D14: =D13/'Inputs & Assumptions'!C36 -> 0.72933639
A15: DSCR | B15: ='Debt Service'!B12 -> 1.8961253 | C15: =('Revenue Waterfall'!B5*C5-'Revenue Waterfall'!B5*C5*C8-'Revenue Waterfall'!B5*C5*SUM('Inputs & Assumptions'!C26:C29))/('Debt Service'!B7+'Debt Service'!B5*('Debt Structure'!B8+C9)) -> 1.3234253 | D15: =('Revenue Waterfall'!B5*D5-'Revenue Waterfall'!B5*D5*D8-'Revenue Waterfall'!B5*D5*SUM('Inputs & Assumptions'!C26:C29))/('Debt Service'!B7+'Debt Service'!B5*('Debt Structure'!B8+D9)) -> 0.89687952
A16: Facility Utilization | B16: ='Inputs & Assumptions'!C36/B13 -> 0.81009018 | C16: ='Inputs & Assumptions'!C36/C13 -> 1.0282829 | D16: ='Inputs & Assumptions'!C36/D13 -> 1.3711094
A18: Lender Takeaway
A19: ="Downside DSCR remains "&TEXT(C15,"0.00x")&", but borrowing-base coverage declines to "&TEXT(C14,"0.00x")&" and requires an equity cure or mandatory paydown." -> Downside DSCR remains 1.32x, but borrowing-base coverage declines to 0.97x and requires an equity cure or mandatory paydown.

Sheet Comparable Transactions
A1: Comparable Transactions
A2: Investment question: How do publicly disclosed media credit structures inform pricing and covenant design?
A4: Company | B4: Year | C4: Facility | D4: Lender | E4: Collateral | F4: Interest Margin | G4: Advance Rate | H4: LTV | I4: Purpose | J4: Source | K4: Date
A5: Reservoir Media, Inc. | B5: 2025 | C5: 550000000 | D5: Truist Bank, as administrative agent; lender syndicate | E5: Substantially all tangible and intangible assets of borrower and guarantors | F5: SOFR + 2.00% to 2.25% under total leverage grid | G5: Not publicly disclosed | H5: 0.45x maximum value-to-loan ratio covenant | I5: Amended revolving credit facility; general corporate and acquisition capacity | J5: SEC Form 8-K / Credit Agreement | K5: 45735
A6: Lions Gate Capital Holdings LLC | B6: 2024 | C6: 1250000000 | D6: JPMorgan Chase Bank, N.A., as administrative agent; lender syndicate | E6: First-priority liens on substantially all assets of the credit parties | F6: SOFR + 1.75% to 2.25% depending on leverage | G6: Not publicly disclosed | H6: Not publicly disclosed | I6: Post-Starz separation revolving credit facility | J6: SEC Form 10-Q / credit facilities disclosure | K6: 45623
A7: Sphere Entertainment Co. | B7: 2024 | C7: 1400000000 | D7: JPMorgan Chase Bank, N.A., as administrative agent; lender syndicate | E7: First-priority lien on substantially all assets of Sphere and subsidiary guarantors | F7: SOFR + 2.50% to 2.75% depending on leverage | G7: Not publicly disclosed | H7: Not publicly disclosed | I7: Refinancing of legacy credit facility and transaction costs | J7: SEC Form 8-K / Term Loan Facility | K7: 45628
A8: AMC Networks Inc. | B8: 2023 | C8: 400000000 | D8: JPMorgan Chase Bank, N.A., as administrative agent; lender syndicate | E8: Senior secured revolving credit facility | F8: Not publicly disclosed in cited summary | G8: Not publicly disclosed | H8: Not publicly disclosed | I8: Replacement revolving credit facility and liquidity | J8: SEC Form 8-K / Credit Agreement | K8: 45258
A10: Lender Takeaway
A11: Public transactions support first-lien collateral packages and floating-rate pricing, but disclosed terms are not directly comparable to the modeled borrowing-base risk.

Sheet Risk Matrix
A1: Risk Matrix
A2: Investment question: What can impair repayment, and which mitigants must be embedded in documentation?
A4: Risk | B4: Probability | C4: Impact | D4: Mitigation | E4: Residual Risk | F4: Status
A5: Library revenue decay exceeds base case | B5: Medium | C5: High | D5: Conservative advance rate, reappraisals, cash sweep | E5: Medium | F5: Monitor
A6: Platform or distributor concentration | B6: Medium | C6: High | D6: Eligibility limits, concentration caps, account control | E6: Medium | F6: Monitor
A7: Tax credit timing delay | B7: Medium | C7: Medium | D7: Haircuts, jurisdictional diligence, reserves | E7: Low-Medium | F7: Monitor
A8: Pre-sale counterparty default | B8: Low-Medium | C8: Medium | D8: Approved counterparties and lender-controlled notices | E8: Low-Medium | F8: Monitor
A9: Floating-rate burden | B9: Medium | C9: Medium | D9: Minimum DSCR, hedging requirement, cash sweep | E9: Medium | F9: Monitor
A10: Documentation / chain-of-title deficiency | B10: Low | C10: High | D10: Legal diligence, perfection, title representations | E10: Low-Medium | F10: Critical diligence
A11: Valuation volatility and appraisal risk | B11: Medium | C11: High | D11: Independent appraisal and borrowing base redetermination | E11: Medium | F11: Monitor
A13: Lender Takeaway
A14: The highest-severity risks are revenue decay, valuation volatility, platform concentration, and chain-of-title defects; mitigation depends on controls, not forecast precision.

Sheet Credit Scorecard
A1: Credit Committee Scorecard
A2: Investment question: Does the weighted credit profile justify approval at the proposed structure?
A4: Category | B4: Weight | C4: Score | D4: Weighted Score | E4: Rationale
A5: Collateral Quality | B5: 0.2 | C5: ='Inputs & Assumptions'!C78 -> 4 | D5: =B5*C5 -> 0.8 | E5: Diversified collateral with modeled haircuts
A6: Cash Flow Stability | B6: 0.18 | C6: ='Inputs & Assumptions'!C79 -> 3 | D6: =B6*C6 -> 0.54 | E6: Contractual and long-tail revenues offset decay risk
A7: Diversification | B7: 0.12 | C7: ='Inputs & Assumptions'!C80 -> 3 | D7: =B7*C7 -> 0.36 | E7: Multiple channels; counterparty limits required
A8: Management | B8: 0.1 | C8: ='Inputs & Assumptions'!C81 -> 3 | D8: =B8*C8 -> 0.3 | E8: Hypothetical; full diligence required
A9: Legal Structure | B9: 0.12 | C9: ='Inputs & Assumptions'!C82 -> 4 | D9: =B9*C9 -> 0.48 | E9: First lien, controlled accounts, covenant package
A10: Liquidity | B10: 0.1 | C10: ='Inputs & Assumptions'!C83 -> 3 | D10: =B10*C10 -> 0.3 | E10: Borrowing base headroom subject to stress
A11: Counterparty Risk | B11: 0.08 | C11: ='Inputs & Assumptions'!C84 -> 3 | D11: =B11*C11 -> 0.24 | E11: Requires approved obligor and concentration framework
A12: Market Risk | B12: 0.1 | C12: ='Inputs & Assumptions'!C85 -> 2 | D12: =B12*C12 -> 0.2 | E12: Secular content monetization and rate volatility
A14: Overall Score | B14: =SUM(D5:D12) -> 3.22
A15: Recommendation | B15: =IF(AND(B14>=3.25,'Scenario Analysis'!C14>=1.1,'Scenario Analysis'!C15>=1.15),"CONDITIONAL APPROVAL",IF(B14>=2.75,"WATCH / RESTRUCTURE TERMS","DECLINE")) -> WATCH / RESTRUCTURE TERMS
A17: Lender Takeaway
A18: ="The weighted score of "&TEXT(B14,"0.00")&" supports only a conditional outcome because downside collateral coverage does not meet the approval threshold." -> The weighted score of 3.22 supports only a conditional outcome because downside collateral coverage does not meet the approval threshold.

Sheet Recovery Analysis
A1: Recovery Analysis
A2: Investment question: What principal recovery is expected after liquidation haircuts and timing discounts?
A4: Collateral | B4: Eligible Value | C4: Recovery Rate | D4: Gross Recovery | E4: Timing (Years) | F4: PV Recovery
A5: Library | B5: ='Borrowing Base'!E5 -> 1.1884207e+08 | C5: ='Inputs & Assumptions'!C62 -> 0.65 | D5: =B5*C5 -> 77247345 | E5: ='Inputs & Assumptions'!C65 -> 2 | F5: =D5/(1+'Inputs & Assumptions'!C5)^E5 -> 66227148
A6: Receivables | B6: ='Borrowing Base'!E8 -> 6800000 | C6: ='Inputs & Assumptions'!C72 -> 0.75 | D6: =B6*C6 -> 5100000 | E6: ='Inputs & Assumptions'!C65 -> 2 | F6: =D6/(1+'Inputs & Assumptions'!C5)^E6 -> 4372428
A7: Tax Credits | B7: ='Borrowing Base'!E6 -> 17575000 | C7: ='Inputs & Assumptions'!C73 -> 0.9 | D7: =B7*C7 -> 15817500 | E7: ='Inputs & Assumptions'!C65 -> 2 | F7: =D7/(1+'Inputs & Assumptions'!C5)^E7 -> 13560957
A8: Pre-sales | B8: ='Borrowing Base'!E7 -> 10800000 | C8: ='Inputs & Assumptions'!C74 -> 0.7 | D8: =B8*C8 -> 7560000 | E8: ='Inputs & Assumptions'!C65 -> 2 | F8: =D8/(1+'Inputs & Assumptions'!C5)^E8 -> 6481481.5
A9: Cash | B9: ='Borrowing Base'!E9 -> 5000000 | C9: ='Inputs & Assumptions'!C75 -> 1 | D9: =B9*C9 -> 5000000 | E9: 0 | F9: =D9 -> 5000000
A10: Other Assets | B10: ='Borrowing Base'!E10 -> 2250000 | C10: ='Inputs & Assumptions'!C76 -> 0.25 | D10: =B10*C10 -> 562500 | E10: ='Inputs & Assumptions'!C65 -> 2 | F10: =D10/(1+'Inputs & Assumptions'!C5)^E10 -> 482253.09
A12: Total PV Recovery | B12: =SUM(F5:F10) -> 96124267
A13: Principal Recovery | B13: =MIN(B12,'Inputs & Assumptions'!C36) -> 75000000
A14: Recovery % | B14: =B13/'Inputs & Assumptions'!C36 -> 1
A15: Loss | B15: ='Inputs & Assumptions'!C36-B13 -> 0
A16: Loss Severity | B16: =B15/'Inputs & Assumptions'!C36 -> 0
A17: Expected Recovery Timeline | B17: =((D5*E5)+(D6*E6)+(D7*E7)+(D8*E8)+(D9*E9)+(D10*E10))/SUM(D5:D10) -> 1.9101425
A19: Lender Takeaway
A20: ="Modeled recovery is "&TEXT(B14,"0.0%")&" with an expected timeline of "&TEXT(B17,"0.0")&" years; legal enforceability and appraisal quality remain the key execution risks." -> Modeled recovery is 100.0% with an expected timeline of 1.9 years; legal enforceability and appraisal quality remain the key execution risks.

Sheet Market Data
A1: Market Data
A2: Investment question: Which public market references are verifiable and relevant to underwriting?
A4: Metric | B4: Value | C4: Source | D4: Publication / As-of Date | E4: Citation | F4: Comments
A5: Global Private Credit AUM | B5: 1700000000000 | C5: International Monetary Fund, Global Financial Stability Report, April 2024 | D5: 45398 | E5: IMF GFSR Chapter 2, private credit AUM estimated at about $1.7 trillion | F5: 2023 market estimate cited by IMF
A6: Entertainment Financing Market | B6: Not publicly available | C6: No reliable public aggregate identified | D6: 46215 | E6: N/A | F6: No estimate used
A9: SOFR | B9: 0.0363 | C9: Federal Reserve Bank of New York / FRED | D9: 46209 | E9: Secured Overnight Financing Rate series observation: 3.63% | F9: pull latest
A10: Private Credit Market Size incl. Committed Capital | B10: 2100000000000 | C10: International Monetary Fund, Global Financial Stability Report, April 2024 | D10: 45398 | E10: IMF notes assets and committed capital totaling about $2.1 trillion globally | F10: Market size, not pure AUM
A15: Lender Takeaway
A16: Market references provide context only; transaction approval must rely on deal-specific collateral, contracts, diligence, and covenant protection.

Sheet Sources
A1: Sources & Bibliography
A2: Investment question: Can every external figure and precedent be traced to a verifiable source?
A4: Item | B4: Organization | C4: Publication | D4: Author | E4: Publication Date | F4: URL | G4: Access Date | H4: Reference / Notes
A5: Global Private Credit AUM and Market Size | B5: International Monetary Fund | C5: Global Financial Stability Report, April 2024 — Chapter 2 | D5: International Monetary Fund staff | E5: 45398 | F5: https://www.imf.org/en/publications/gfsr/issues/2024/04/16/global-financial-stability-report-april-2024 | G5: 46215 | H5: Private credit AUM about $1.7tn; assets plus committed capital about $2.1tn
A6: SOFR | B6: Federal Reserve Bank of New York / Federal Reserve Bank of St. Louis | C6: Secured Overnight Financing Rate (SOFR) series | D6: Federal Reserve System | E6: 46209 | F6: https://fred.stlouisfed.org/series/SOFR | G6: 46215 | H6: Observed rate used: 3.63%
A7: Reservoir Media Credit Facility | B7: U.S. Securities and Exchange Commission | C7: Reservoir Media, Inc. Form 8-K and Credit Agreement | D7: Reservoir Media, Inc. | E7: 45735 | F7: https://www.sec.gov/Archives/edgar/data/1824403/000119312525057180/d844452dex101.htm | G7: 46215 | H7: $550m revolving facility; SOFR margin; collateral; value-to-loan covenant
A8: Lions Gate Credit Facilities | B8: U.S. Securities and Exchange Commission | C8: Lions Gate Entertainment Corp. Form 10-Q | D8: Lions Gate Entertainment Corp. | E8: 45623 | F8: confirm cite | G8: 46215 | H8: $1.25bn revolver; SOFR spread; first-priority collateral
A9: Sphere Entertainment Term Loan | B9: U.S. Securities and Exchange Commission | C9: Sphere 8-K | D9: Sphere Entertainment Co. | E9: 45628 | F9: https://www.sec.gov/Archives/edgar/data/1795250/000179525024000191/sphr-20241202.htm | G9: 46215 | H9: $1.4bn term loan; SOFR margin; asset collateral
A10: AMC Networks Revolving Credit Facility | B10: U.S. Securities and Exchange Commission | C10: AMC Networks Inc. Form 8-K | D10: AMC Networks Inc. | E10: 45258 | F10: https://www.sec.gov/Archives/edgar/data/1514991/000151499123000038/amcx-20231128.htm | G10: 46215 | H10: $400m revolver
A12: Lender Takeaway
A13: Only cited public sources are retained; illustrative assumptions remain explicitly labeled and should not be represented as market observations.
