Workbook

Sheet Read Me
A1: PROJECT NIGHTFALL
A2: AVOD content acquisition valuation model
A3: Prepared by Tanmay Srivastava
A4: Independent analytical case study using synthetic assumptions. Not based on proprietary company information.
A6: THE QUESTION
A7: Should an ad-supported streaming platform acquire Project Nightfall, under what deal structure, and what is the maximum economically supportable bid?
A8: Project Nightfall is a fictional package of five action and thriller features offered on a 24-month exclusive U.S. AVOD licence. All titles, performance assumptions, costs and deal terms are invented for this exercise.
A10: HOW TO USE THE MODEL
A11: 1. Set the scenario on the Scenarios sheet. The selector drives every downstream sheet. Scenarios move operating drivers only; no output is overridden.
A12: 2. Read the answer on the Executive Summary sheet. Price, returns, preferred structure and portfolio risk are all model outputs.
A13: 3. Check the QA Controls sheet before relying on any number. Fourteen automated controls reconcile the model.
A14: 4. Edit inputs only in the blue cells on Assumptions, Title Inputs and the scenario driver table.
A16: SHEET MAP
A17: Assumptions | B17: Term, required return, monetisation and cost globals, and the terms of all three deal structures.
A18: Title Inputs | B18: Twenty-three assumptions for each of the five titles, including judgement overlays.
A19: Monthly Viewing Forecast | B19: Monthly viewers, viewing hours, monetised impressions and gross advertising revenue, by title and scenario.
A20: Title Economics | B20: Monthly incremental revenue, follow-on value, costs and contribution by title and scenario, plus the active-scenario title summary.
A21: Deal Structures | B21: Monthly payment mechanics for the fixed fee, the guarantee plus revenue share, and the performance fee with earn-outs.
A22: Scenarios | B22: Scenario selector, operating drivers, scenario results and the pricing conclusions.
A23: Sensitivities | B23: Two-way sensitivity grids, break-even analysis, title ranking, concentration and the cash flow profile.
A24: Executive Summary | B24: The recommendation and the figures used in the accompanying presentation.
A25: QA Controls | B25: Automated reconciliation controls with PASS or FAIL results.
A27: COLOUR AND FORMATTING CONVENTION
A28: Blue text on a pale fill: a direct input. Edit these.
A29: Black text: a formula calculated on the same sheet.
A30: Green text: a link to another sheet.
A31: Shaded cells: totals and headline outputs.
A33: CORE FORMULAS
A34: Viewing hours = unique viewers x starts per viewer x runtime x completion rate / 60
A35: Monetised ad impressions = viewing hours x ad opportunities per hour x fill rate
A36: Advertising revenue = monetised impressions / 1,000 x net CPM
A37: Incremental advertising revenue = advertising revenue x incrementality rate
A38: Contribution before licence fee = incremental advertising revenue + follow-on engagement value - marketing - delivery and QC - variable serving costs
A39: Contribution after licence fee = contribution before licence fee - allocated licence fee
... A55: Sensitivity grids scale the Base monthly profile uniformly and therefore hold the shape of the decay curve constant.

Sheet Assumptions
A1: PROJECT NIGHTFALL
A2: Global assumptions and deal terms
A3: Independent analytical case study using synthetic assumptions. Not based on proprietary company information.
A5: PACKAGE AND LICENCE TERM
A6: Package name | C6: Project Nightfall
A7: Rights granted | C7: U.S. exclusive AVOD, all devices
A8: Licence term (months) | C8: 24 | E8: Model horizon; no renewal value assumed
A9: Titles in package | C9: 5
A10: Seller initial ask - fixed fee ($) | C10: 2500000 | E10: Opening position quoted by the distributor
A12: RETURN AND DISCOUNTING
A13: Required return (annual, nominal) | C13: 0.12 | E13: Hurdle applied to content acquisition capital
A14: Monthly discount rate | C14: =(1+Assumptions!$C$13)^(1/12)-1 -> 0.0094887929 | E14: Cash flows discounted at end of each month
A15: Target portfolio ROI for pricing test | C15: 0.2 | E15: Second pricing test alongside downside break-even
A16: Opening offer as % of target price | C16: 0.88 | E16: Leaves negotiating room below the target
A18: MONETISATION AND COST GLOBALS
A19: Follow-on engagement value ($ per incremental viewing hour) | C19: 0.045 | E19: Modelled incremental benefit; held separate from attributable ad revenue
A20: Variable serving cost ($ per viewing hour) | C20: 0.019 | E20: CDN, encoding, packaging and DRM
A22: MARKETING SPEND PROFILE (% OF TITLE MARKETING SUPPORT)
A23: Month 1 | C23: 0.55
A24: Month 2 | C24: 0.25
A25: Month 3 | C25: 0.12
A26: Month 4 | C26: 0.08
A27: Check: profile sums to 100% | C27: =SUM(C23:C26) -> 1
A29: FIXED-FEE PAYMENT TERMS (STRUCTURE A)
A30: First instalment (% of fee) | C30: 0.5 | E30: Paid on delivery and acceptance
A31: First instalment month | C31: 1
A32: Second instalment (% of fee) | C32: 0.5 | E32: Paid on the six-month anniversary
A33: Second instalment month | C33: 7
A34: PV factor on one dollar of fixed fee | C34: =Assumptions!$C$30/(1+Assumptions!$C$14)^Assumptions!$C$31+Assumptions!$C$32/(1+Assumptions!$C$14)^Assumptions!$C$33 -> 0.9633149 | E34: Used to convert a headline fee into present value
A36: STRUCTURE B - MINIMUM GUARANTEE PLUS REVENUE SHARE
A37: Minimum guarantee ($) | C37: 950000 | E37: Paid month 1, creditable against revenue share
A38: Licensor share of attributable gross ad revenue | C38: 0.28
A40: STRUCTURE C - PERFORMANCE FEE WITH EARN-OUTS
A41: Base fee ($) | C41: 850000 | E41: Paid month 1 on delivery
A42: Earn-out 1 payment ($) | C42: 250000
A43: Earn-out 1 trigger - cumulative viewing hours by month 12 | C43: 12750000
A44: Earn-out 2 payment ($) | C44: 250000
A45: Earn-out 2 trigger - cumulative viewing hours by month 18 | C45: 14500000
A46: Earn-out 3 payment ($) | C46: 300000
A47: Earn-out 3 trigger - cumulative viewing hours by month 24 | C47: 17000000
...

Sheet Title Inputs
A1: PROJECT NIGHTFALL
A2: Title-level assumptions (five titles)
A3: Independent analytical case study using synthetic assumptions. Not based on proprietary company information.
A5: TITLE PROFILE
A6: Line item | C6: Title 1 | D6: Title 2 | E6: Title 3 | F6: Title 4 | G6: Title 5 | H6: Portfolio | I6: Notes
A7: Fictional title | C7: Nightfall Protocol | D7: Ash Ridge | E7: Cold Harbor | F7: The Quiet Depth | G7: Vector Nine
A8: Genre | C8: Action | D8: Action | E8: Thriller | F8: Thriller | G8: Thriller
A9: Subgenre | C9: Special-ops thriller | D9: Survival action | E9: Espionage thriller | F9: Submarine thriller | G9: Cyber thriller
A10: Release year | C10: 2021 | D10: 2022 | E10: 2019 | F10: 2018 | G10: 2023 | I10: Held as text so it is not formatted as a number
A11: Runtime (minutes) | C11: 118 | D11: 112 | E11: 106 | F11: 124 | G11: 99
A12: Comparable-performance tier | C12: Tier 1 - Wide theatrical | D12: Tier 2 - Limited theatrical | E12: Tier 2 - Limited theatrical | F12: Tier 3 - Direct to streaming | G12: Tier 4 - Festival / niche | I12: Internal tiering of comparable library performance
A14: AUDIENCE AND VIEWING
A15: Projected unique viewers - lifetime, base curve | C15: 3600000 | D15: 3050000 | E15: 2500000 | F15: 1650000 | G15: 850000 | H15: =SUM(C15:G15) -> 11650000 | I15: Lifetime total over the 24-month window at the base decay rate
A16: Starts per viewer | C16: 1.3 | D16: 1.24 | E16: 1.2 | F16: 1.13 | G16: 1.08 | I16: Total starts divided by unique viewers
A17: Repeat viewing rate | C17: =C16-1 -> 0.3 | D17: =D16-1 -> 0.24 | E17: =E16-1 -> 0.2 | F17: =F16-1 -> 0.13 | G17: =G16-1 -> 0.08 | I17: Starts per viewer less one; the share of viewing that is a return visit
A18: Completion rate | C18: 0.64 | D18: 0.61 | E18: 0.59 | F18: 0.51 | G18: 0.45
A19: Average minutes viewed per start | C19: =C11*C18 -> 75.52 | D19: =D11*D18 -> 68.32 | E19: =E11*E18 -> 62.54 | F19: =F11*F18 -> 63.24 | G19: =G11*G18 -> 44.55 | I19: Runtime multiplied by completion rate
A20: Monthly viewing decay rate | C20: 0.115 | D20: 0.12 | E20: 0.128 | F20: 0.14 | G20: 0.15 | I20: Month-on-month decline in unique viewers
A21: Decay curve normaliser (24 months) | C21: =(1-(1-C20)^Assumptions!$C$8)/C20 -> 8.2322686 | D21: =(1-(1-D20)^Assumptions!$C$8)/D20 -> 7.9457163 | E21: =(1-(1-E20)^Assumptions!$C$8)/E20 -> 7.5206325 | F21: =(1-(1-F20)^Assumptions!$C$8)/F20 -> 6.9515044 | G21: =(1-(1-G20)^Assumptions!$C$8)/G20 -> 6.5317819 | I21: Geometric sum of the base decay curve; converts lifetime viewers into a month-1 base
A23: ADVERTISING MONETISATION
A24: Ad opportunities per viewing hour | C24: 16 | D24: 16 | E24: 15.5 | F24: 15 | G24: 15 | I24: 30-second equivalent impressions available per hour
A25: Ad fill rate | C25: 0.82 | D25: 0.81 | E25: 0.8 | F25: 0.77 | G25: 0.75
A26: Net advertising CPM ($) | C26: 25.5 | D26: 24 | E26: 23 | F26: 21 | G26: 19.5 | I26: Net of ad-serving and sales costs
A27: Incrementality rate | C27: 0.62 | D27: 0.58 | E27: 0.55 | F27: 0.47 | G27: 0.4 | I27: Share of viewing not displaced from other owned content
A28: Cannibalisation rate | C28: =1-C27 -> 0.38 | D28: =1-D27 -> 0.42 | E28: =1-E27 -> 0.45 | F28: =1-F27 -> 0.53 | G28: =1-G27 -> 0.6 | I28: One less the incrementality rate
A30: COSTS AND ALLOCATION
A31: Marketing support ($) | C31: 165000 | D31: 130000 | E31: 100000 | F31: 72000 | G31: 58000 | H31: =SUM(C31:G31) -> 525000
A32: Delivery, localisation and QC ($) | C32: 58000 | D32: 52000 | E32: 46000 | F32: 44000 | G32: 40000 | H32: =SUM(C32:G32) -> 240000
A33: Variable serving cost ($ per viewing hour) | C33: =Assumptions!$C$20 -> 0.019 | D33: =Assumptions!$C$20 -> 0.019 | E33: =Assumptions!$C$20 -> 0.019 | F33: =Assumptions!$C$20 -> 0.019 | G33: =Assumptions!$C$20 -> 0.019 | I33: Linked to the global rate on Assumptions
A34: Follow-on engagement value ($ per incremental viewing hour) | C34: =Assumptions!$C$19 -> 0.045 | D34: =Assumptions!$C$19 -> 0.045 | E34: =Assumptions!$C$19 -> 0.045 | F34: =Assumptions!$C$19 -> 0.045 | G34: =Assumptions!$C$19 -> 0.045 | I34: Linked to the global rate on Assumptions; reported separately from ad revenue
A35: Allocated licence fee share of package | C35: 0.32 | D35: 0.26 | E35: 0.2 | F35: 0.13 | G35: 0.09 | H35: =SUM(C35:G35) -> 1 | I35: Negotiated allocation used for title-level economics; must total 100%
A37: JUDGEMENT OVERLAYS
A38: Forecast confidence | C38: High | D38: High | E38: Medium | F38: Medium | G38: Low
A39: Risk rating | C39: Low | D39: Low | E39: Medium | F39: Medium | G39: High
A40: Portfolio role | C40: Anchor | D40: Anchor | E40: Supporting | F40: Filler | G40: Dilutive
A42: Blue cells are direct inputs. Green cells link to another sheet. Black cells are formulas. All values are illustrative.

Sheet Monthly Viewing Forecast
A1: PROJECT NIGHTFALL
A2: Monthly viewing, impressions and gross advertising revenue by title
A3: Independent analytical case study using synthetic assumptions. Not based on proprietary company information.
A4: Scenario | B4: Title | C4: Month | D4: Total | E4: 1 | F4: 2 | G4: 3 | H4: 4 | I4: 5 | J4: 6 | K4: 7 | L4: 8 | M4: 9 | N4: 10 | O4: 11 | P4: 12 | Q4: 13 | R4: 14 | S4: 15 | T4: 16 | U4: 17 | V4: 18 | W4: 19 | X4: 20 | Y4: 21 | Z4: 22 | AA4: 23 | AB4: 24
A6: DOWNSIDE SCENARIO
A7: Downside | B7: Nightfall Protocol | C7: Monthly unique viewers | D7: =SUM(E7:AB7) -> 3334895.1 | E7: =Scenarios!$C$23*(1-Scenarios!$C$22)^(E$4-1) -> 428557.45 | F7: =Scenarios!$C$23*(1-Scenarios!$C$22)^(F$4-1) -> 375844.88 | G7: =Scenarios!$C$23*(1-Scenarios!$C$22)^(G$4-1) -> 329615.96 | H7: =Scenarios!$C$23*(1-Scenarios!$C$22)^(H$4-1) -> 289073.2 | I7: =Scenarios!$C$23*(1-Scenarios!$C$22)^(I$4-1) -> 253517.19 | J7: =Scenarios!$C$23*(1-Scenarios!$C$22)^(J$4-1) -> 222334.58 | K7: =Scenarios!$C$23*(1-Scenarios!$C$22)^(K$4-1) -> 194987.43 | L7: =Scenarios!$C$23*(1-Scenarios!$C$22)^(L$4-1) -> 171003.97 | ... AB7: =Scenarios!$C$23*(1-Scenarios!$C$22)^(AB$4-1) -> 20941.11
C8: Share of modelled lifetime viewers | D8: =SUM(E8:AB8) -> 1 | E8: =E7/$D$7 -> 0.12850703 | F8: =F7/$D$7 -> 0.11270066 | G8: =G7/$D$7 -> 0.09883848 | H8: =H7/$D$7 -> 0.086681347 | I8: =I7/$D$7 -> 0.076019541 | J8: =J7/$D$7 -> 0.066669138 | K8: =K7/$D$7 -> 0.058468834 | L8: =L7/$D$7 -> 0.051277167 | ... AB8: =AB7/$D$7 -> 0.0062793909
C9: Viewing hours | D9: =SUM(E9:AB9) -> 5347642.1 | E9: =E7*'Title Inputs'!$C$16*'Title Inputs'!$C$11*Scenarios!$C$24/60 -> 687209.58 | F9: =F7*'Title Inputs'!$C$16*'Title Inputs'!$C$11*Scenarios!$C$24/60 -> 602682.8 | G9: =G7*'Title Inputs'!$C$16*'Title Inputs'!$C$11*Scenarios!$C$24/60 -> 528552.82 | H9: =H7*'Title Inputs'!$C$16*'Title Inputs'!$C$11*Scenarios!$C$24/60 -> 463540.82 | I9: =I7*'Title Inputs'!$C$16*'Title Inputs'!$C$11*Scenarios!$C$24/60 -> 406525.3 | J9: =J7*'Title Inputs'!$C$16*'Title Inputs'!$C$11*Scenarios!$C$24/60 -> 356522.69 | K9: =K7*'Title Inputs'!$C$16*'Title Inputs'!$C$11*Scenarios!$C$24/60 -> 312670.4 | L9: =L7*'Title Inputs'!$C$16*'Title Inputs'!$C$11*Scenarios!$C$24/60 -> 274211.94 | ... AB9: =AB7*'Title Inputs'!$C$16*'Title Inputs'!$C$11*Scenarios!$C$24/60 -> 33579.935
C10: Monetised ad impressions | D10: =SUM(E10:AB10) -> 68757843 | E10: =E9*'Title Inputs'!$C$24*Scenarios!$C$25 -> 8835865.9 | F10: =F9*'Title Inputs'!$C$24*Scenarios!$C$25 -> 7749054.4 | G10: =G9*'Title Inputs'!$C$24*Scenarios!$C$25 -> 6795920.7 | H10: =H9*'Title Inputs'!$C$24*Scenarios!$C$25 -> 5960022.4 | I10: =I9*'Title Inputs'!$C$24*Scenarios!$C$25 -> 5226939.7 | J10: =J9*'Title Inputs'!$C$24*Scenarios!$C$25 -> 4584026.1 | K10: =K9*'Title Inputs'!$C$24*Scenarios!$C$25 -> 4020190.9 | L10: =L9*'Title Inputs'!$C$24*Scenarios!$C$25 -> 3525707.4 | ... AB10: =AB9*'Title Inputs'!$C$24*Scenarios!$C$25 -> 431757.37
C11: Gross advertising revenue ($) | D11: =SUM(E11:AB11) -> 1683192 | E11: =E10/1000*Scenarios!$C$26 -> 216302 | F11: =F10/1000*Scenarios!$C$26 -> 189696.85 | G11: =G10/1000*Scenarios!$C$26 -> 166364.14 | H11: =H10/1000*Scenarios!$C$26 -> 145901.35 | I11: =I10/1000*Scenarios!$C$26 -> 127955.48 | J11: =J10/1000*Scenarios!$C$26 -> 112216.96 | K11: =K10/1000*Scenarios!$C$26 -> 98414.273 | L11: =L10/1000*Scenarios!$C$26 -> 86309.317 | ... AB11: =AB10/1000*Scenarios!$C$26 -> 10569.42
A13: Downside | B13: Ash Ridge | C13: Monthly unique viewers | D13: =SUM(E13:AB13) -> 2829093.1 | E13: =Scenarios!$D$23*(1-Scenarios!$D$22)^(E$4-1) -> 376177.54 | F13: =Scenarios!$D$23*(1-Scenarios!$D$22)^(F$4-1) -> 328026.81 | G13: =Scenarios!$D$23*(1-Scenarios!$D$22)^(G$4-1) -> 286039.38 | H13: =Scenarios!$D$23*(1-Scenarios!$D$22)^(H$4-1) -> 249426.34 | I13: =Scenarios!$D$23*(1-Scenarios!$D$22)^(I$4-1) -> 217499.77 | J13: =Scenarios!$D$23*(1-Scenarios!$D$22)^(J$4-1) -> 189659.8 | K13: =Scenarios!$D$23*(1-Scenarios!$D$22)^(K$4-1) -> 165383.34 | L13: =Scenarios!$D$23*(1-Scenarios!$D$22)^(L$4-1) -> 144214.28 | ... AB13: =Scenarios!$D$23*(1-Scenarios!$D$22)^(AB$4-1) -> 16116.548
C14: Share of modelled lifetime viewers | D14: =SUM(E14:AB14) -> 1 | E14: =E13/$D$13 -> 0.13296754 | F14: =F13/$D$13 -> 0.11594769 | G14: =G13/$D$13 -> 0.10110639 | H14: =H13/$D$13 -> 0.088164771 | I14: =I13/$D$13 -> 0.076879681 | J14: =J13/$D$13 -> 0.067039081 | K14: =K13/$D$13 -> 0.058458079 | L14: =L13/$D$13 -> 0.050975445 | ... AB14: =AB13/$D$13 -> 0.0056967188
C15: Viewing hours | D15: =SUM(E15:AB15) -> 3914637.9 | E15: =E13*'Title Inputs'!$D$16*'Title Inputs'!$D$11*Scenarios!$D$24/60 -> 520519.77 | F15: =F13*'Title Inputs'!$D$16*'Title Inputs'!$D$11*Scenarios!$D$24/60 -> 453893.24 | G15: =G13*'Title Inputs'!$D$16*'Title Inputs'!$D$11*Scenarios!$D$24/60 -> 395794.91 | H15: =H13*'Title Inputs'!$D$16*'Title Inputs'!$D$11*Scenarios!$D$24/60 -> 345133.16 | I15: =I13*'Title Inputs'!$D$16*'Title Inputs'!$D$11*Scenarios!$D$24/60 -> 300956.11 | J15: =J13*'Title Inputs'!$D$16*'Title Inputs'!$D$11*Scenarios!$D$24/60 -> 262433.73 | K15: =K13*'Title Inputs'!$D$16*'Title Inputs'!$D$11*Scenarios!$D$24/60 -> 228842.21 | L15: =L13*'Title Inputs'!$D$16*'Title Inputs'!$D$11*Scenarios!$D$24/60 -> 199550.41 | ... AB15: =AB13*'Title Inputs'!$D$16*'Title Inputs'!$D$11*Scenarios!$D$24/60 -> 22300.592
C16: Monetised ad impressions | D16: =SUM(E16:AB16) -> 49719033 | E16: =E15*'Title Inputs'!$D$24*Scenarios!$D$25 -> 6611017.5 | F16: =F15*'Title Inputs'!$D$24*Scenarios!$D$25 -> 5764807.3 | G16: =G15*'Title Inputs'!$D$24*Scenarios!$D$25 -> 5026911.9 | H16: =H15*'Title Inputs'!$D$24*Scenarios!$D$25 -> 4383467.2 | I16: =I15*'Title Inputs'!$D$24*Scenarios!$D$25 -> 3822383.4 | J16: =J15*'Title Inputs'!$D$24*Scenarios!$D$25 -> 3333118.3 | K16: =K15*'Title Inputs'!$D$24*Scenarios!$D$25 -> 2906479.2 | L16: =L15*'Title Inputs'!$D$24*Scenarios!$D$25 -> 2534449.8 | ... AB16: =AB15*'Title Inputs'!$D$24*Scenarios!$D$25 -> 283235.35
C17: Gross advertising revenue ($) | D17: =SUM(E17:AB17) -> 1145526.5 | E17: =E16/1000*Scenarios!$D$26 -> 152317.84 | F17: =F16/1000*Scenarios!$D$26 -> 132821.16 | G17: =G16/1000*Scenarios!$D$26 -> 115820.05 | H17: =H16/1000*Scenarios!$D$26 -> 100995.08 | I17: =I16/1000*Scenarios!$D$26 -> 88067.714 | J17: =J16/1000*Scenarios!$D$26 -> 76795.046 | K17: =K16/1000*Scenarios!$D$26 -> 66965.28 | L17: =L16/1000*Scenarios!$D$26 -> 58393.725 | ... AB17: =AB16/1000*Scenarios!$D$26 -> 6525.7425
A19: Downside | B19: Cold Harbor | C19: Monthly unique viewers | D19: =SUM(E19:AB19) -> 2323640.8 | E19: =Scenarios!$E$23*(1-Scenarios!$E$22)^(E$4-1) -> 325770.47 | F19: =Scenarios!$E$23*(1-Scenarios!$E$22)^(F$4-1) -> 281465.69 | G19: =Scenarios!$E$23*(1-Scenarios!$E$22)^(G$4-1) -> 243186.35 | H19: =Scenarios!$E$23*(1-Scenarios!$E$22)^(H$4-1) -> 210113.01 | I19: =Scenarios!$E$23*(1-Scenarios!$E$22)^(I$4-1) -> 181537.64 | J19: =Scenarios!$E$23*(1-Scenarios!$E$22)^(J$4-1) -> 156848.52 | K19: =Scenarios!$E$23*(1-Scenarios!$E$22)^(K$4-1) -> 135517.12 | L19: =Scenarios!$E$23*(1-Scenarios!$E$22)^(L$4-1) -> 117086.79 | ... AB19: =Scenarios!$E$23*(1-Scenarios!$E$22)^(AB$4-1) -> 11290.88
C20: Share of modelled lifetime viewers | D20: =SUM(E20:AB20) -> 1 | E20: =E19/$D$19 -> 0.14019829 | F20: =F19/$D$19 -> 0.12113132 | G20: =G19/$D$19 -> 0.10465746 | H20: =H19/$D$19 -> 0.090424048 | I20: =I19/$D$19 -> 0.078126378 | J20: =J19/$D$19 -> 0.06750119 | K20: =K19/$D$19 -> 0.058321029 | L20: =L19/$D$19 -> 0.050389369 | ... AB20: =AB19/$D$19 -> 0.0048591331
C21: Viewing hours | D21: =SUM(E21:AB21) -> 2848281.7 | E21: =E19*'Title Inputs'!$E$16*'Title Inputs'!$E$11*Scenarios!$E$24/60 -> 399324.23 | F21: =F19*'Title Inputs'!$E$16*'Title Inputs'!$E$11*Scenarios!$E$24/60 -> 345016.13 | G21: =G19*'Title Inputs'!$E$16*'Title Inputs'!$E$11*Scenarios!$E$24/60 -> 298093.94 | H21: =H19*'Title Inputs'!$E$16*'Title Inputs'!$E$11*Scenarios!$E$24/60 -> 257553.16 | I21: =I19*'Title Inputs'!$E$16*'Title Inputs'!$E$11*Scenarios!$E$24/60 -> 222525.93 | J21: =J19*'Title Inputs'!$E$16*'Title Inputs'!$E$11*Scenarios!$E$24/60 -> 192262.41 | K21: =K19*'Title Inputs'!$E$16*'Title Inputs'!$E$11*Scenarios!$E$24/60 -> 166114.72 | L21: =L19*'Title Inputs'!$E$16*'Title Inputs'!$E$11*Scenarios!$E$24/60 -> 143523.12 | ... AB21: =AB19*'Title Inputs'!$E$16*'Title Inputs'!$E$11*Scenarios!$E$24/60 -> 13840.18
C22: Monetised ad impressions | D22: =SUM(E22:AB22) -> 34612319 | E22: =E21*'Title Inputs'!$E$24*Scenarios!$E$25 -> 4852588 | F22: =F21*'Title Inputs'!$E$24*Scenarios!$E$25 -> 4192636.1 | G22: =G21*'Title Inputs'!$E$24*Scenarios!$E$25 -> 3622437.6 | H22: =H21*'Title Inputs'!$E$24*Scenarios!$E$25 -> 3129786.1 | I22: =I21*'Title Inputs'!$E$24*Scenarios!$E$25 -> 2704135.2 | J22: =J21*'Title Inputs'!$E$24*Scenarios!$E$25 -> 2336372.8 | K22: =K21*'Title Inputs'!$E$24*Scenarios!$E$25 -> 2018626.1 | L22: =L21*'Title Inputs'!$E$24*Scenarios!$E$25 -> 1744092.9 | ... AB22: =AB21*'Title Inputs'!$E$24*Scenarios!$E$25 -> 168185.87
C23: Gross advertising revenue ($) | D23: =SUM(E23:AB23) -> 764240.01 | E23: =E22/1000*Scenarios!$E$26 -> 107145.14 | F23: =F22/1000*Scenarios!$E$26 -> 92573.404 | G23: =G22/1000*Scenarios!$E$26 -> 79983.421 | H23: =H22/1000*Scenarios!$E$26 -> 69105.676 | I23: =I22/1000*Scenarios!$E$26 -> 59707.304 | J23: =J22/1000*Scenarios!$E$26 -> 51587.111 | K23: =K22/1000*Scenarios!$E$26 -> 44571.264 | L23: =L22/1000*Scenarios!$E$26 -> 38509.572 | ... AB23: =AB22/1000*Scenarios!$E$26 -> 3713.544
A25: Downside | B25: The Quiet Depth | C25: Monthly unique viewers | D25: =SUM(E25:AB25) -> 1538054.5 | E25: =Scenarios!$F$23*(1-Scenarios!$F$22)^(E$4-1) -> 232611.52 | F25: =Scenarios!$F$23*(1-Scenarios!$F$22)^(F$4-1) -> 198185.02 | G25: =Scenarios!$F$23*(1-Scenarios!$F$22)^(G$4-1) -> 168853.63 | H25: =Scenarios!$F$23*(1-Scenarios!$F$22)^(H$4-1) -> 143863.3 | I25: =Scenarios!$F$23*(1-Scenarios!$F$22)^(I$4-1) -> 122571.53 | J25: =Scenarios!$F$23*(1-Scenarios!$F$22)^(J$4-1) -> 104430.94 | K25: =Scenarios!$F$23*(1-Scenarios!$F$22)^(K$4-1) -> 88975.162 | L25: =Scenarios!$F$23*(1-Scenarios!$F$22)^(L$4-1) -> 75806.838 | ... AB25: =Scenarios!$F$23*(1-Scenarios!$F$22)^(AB$4-1) -> 5844.4265
C26: Share of modelled lifetime viewers | D26: =SUM(E26:AB26) -> 1 | E26: =E25/$D$25 -> 0.1512375 | F26: =F25/$D$25 -> 0.12885435 | G26: =G25/$D$25 -> 0.10978391 | H26: =H25/$D$25 -> 0.093535888 | I26: =I25/$D$25 -> 0.079692577 | J26: =J25/$D$25 -> 0.067898075 | K26: =K25/$D$25 -> 0.05784916 | L26: =L25/$D$25 -> 0.049287484 | ... AB26: =AB25/$D$25 -> 0.0037998825
C27: Viewing hours | D27: =SUM(E27:AB27) -> 1795216.6 | E27: =E25*'Title Inputs'!$F$16*'Title Inputs'!$F$11*Scenarios!$F$24/60 -> 271504.07 | F27: =F25*'Title Inputs'!$F$16*'Title Inputs'!$F$11*Scenarios!$F$24/60 -> 231321.47 | G27: =G25*'Title Inputs'!$F$16*'Title Inputs'!$F$11*Scenarios!$F$24/60 -> 197085.89 | H27: =H25*'Title Inputs'!$F$16*'Title Inputs'!$F$11*Scenarios!$F$24/60 -> 167917.18 | I27: =I25*'Title Inputs'!$F$16*'Title Inputs'!$F$11*Scenarios!$F$24/60 -> 143065.44 | J27: =J25*'Title Inputs'!$F$16*'Title Inputs'!$F$11*Scenarios!$F$24/60 -> 121891.75 | K27: =K25*'Title Inputs'!$F$16*'Title Inputs'!$F$11*Scenarios!$F$24/60 -> 103851.77 | L27: =L25*'Title Inputs'!$F$16*'Title Inputs'!$F$11*Scenarios!$F$24/60 -> 88481.711 | ... AB27: =AB25*'Title Inputs'!$F$16*'Title Inputs'!$F$11*Scenarios!$F$24/60 -> 6821.6123
C28: Monetised ad impressions | D28: =SUM(E28:AB28) -> 20320057 | E28: =E27*'Title Inputs'!$F$24*Scenarios!$F$25 -> 3073154.6 | F28: =F27*'Title Inputs'!$F$24*Scenarios!$F$25 -> 2618327.7 | G28: =G27*'Title Inputs'!$F$24*Scenarios!$F$25 -> 2230815.2 | H28: =H27*'Title Inputs'!$F$24*Scenarios!$F$25 -> 1900654.6 | I28: =I27*'Title Inputs'!$F$24*Scenarios!$F$25 -> 1619357.7 | J28: =J27*'Title Inputs'!$F$24*Scenarios!$F$25 -> 1379692.8 | K28: =K27*'Title Inputs'!$F$24*Scenarios!$F$25 -> 1175498.2 | L28: =L27*'Title Inputs'!$F$24*Scenarios!$F$25 -> 1001524.5 | ... AB28: =AB27*'Title Inputs'!$F$24*Scenarios!$F$25 -> 77213.829
C29: Gross advertising revenue ($) | D29: =SUM(E29:AB29) -> 409652.35 | E29: =E28/1000*Scenarios!$F$26 -> 61954.797 | F29: =F28/1000*Scenarios!$F$26 -> 52785.487 | G29: =G28/1000*Scenarios!$F$26 -> 44973.235 | H29: =H28/1000*Scenarios!$F$26 -> 38317.196 | I29: =I28/1000*Scenarios!$F$26 -> 32646.251 | J29: =J28/1000*Scenarios!$F$26 -> 27814.606 | K29: =K28/1000*Scenarios!$F$26 -> 23698.044 | L29: =L28/1000*Scenarios!$F$26 -> 20190.734 | ... AB29: =AB28/1000*Scenarios!$F$26 -> 1556.6308
A31: Downside | B31: Vector Nine | C31: Monthly unique viewers | D31: =SUM(E31:AB31) -> 794138.63 | E31: =Scenarios!$G$23*(1-Scenarios!$G$22)^(E$4-1) -> 127530.28 | F31: =Scenarios!$G$23*(1-Scenarios!$G$22)^(F$4-1) -> 107380.5 | G31: =Scenarios!$G$23*(1-Scenarios!$G$22)^(G$4-1) -> 90414.38 | H31: =Scenarios!$G$23*(1-Scenarios!$G$22)^(H$4-1) -> 76128.908 | I31: =Scenarios!$G$23*(1-Scenarios!$G$22)^(I$4-1) -> 64100.541 | J31: =Scenarios!$G$23*(1-Scenarios!$G$22)^(J$4-1) -> 53972.655 | K31: =Scenarios!$G$23*(1-Scenarios!$G$22)^(K$4-1) -> 45444.976 | L31: =Scenarios!$G$23*(1-Scenarios!$G$22)^(L$4-1) -> 38264.67 | ... AB31: =Scenarios!$G$23*(1-Scenarios!$G$22)^(AB$4-1) -> 2442.2574
C32: Share of modelled lifetime viewers | D32: =SUM(E32:AB32) -> 1 | E32: =E31/$D$31 -> 0.16058945 | F32: =F31/$D$31 -> 0.13521632 | G32: =G31/$D$31 -> 0.11385214 | H32: =H31/$D$31 -> 0.0958635 | I32: =I31/$D$31 -> 0.080717067 | J32: =J31/$D$31 -> 0.06796377 | K32: =K31/$D$31 -> 0.057225495 | L32: =L31/$D$31 -> 0.048183866 | ... AB32: =AB31/$D$31 -> 0.003075354
C33: Viewing hours | D33: =SUM(E33:AB33) -> 624083.37 | E33: =E31*'Title Inputs'!$G$16*'Title Inputs'!$G$11*Scenarios!$G$24/60 -> 100221.2 | F33: =F31*'Title Inputs'!$G$16*'Title Inputs'!$G$11*Scenarios!$G$24/60 -> 84386.254 | G33: =G31*'Title Inputs'!$G$16*'Title Inputs'!$G$11*Scenarios!$G$24/60 -> 71053.226 | H33: =H31*'Title Inputs'!$G$16*'Title Inputs'!$G$11*Scenarios!$G$24/60 -> 59826.816 | I33: =I31*'Title Inputs'!$G$16*'Title Inputs'!$G$11*Scenarios!$G$24/60 -> 50374.179 | J33: =J31*'Title Inputs'!$G$16*'Title Inputs'!$G$11*Scenarios!$G$24/60 -> 42415.059 | K33: =K31*'Title Inputs'!$G$16*'Title Inputs'!$G$11*Scenarios!$G$24/60 -> 35713.48 | L33: =L31*'Title Inputs'!$G$16*'Title Inputs'!$G$11*Scenarios!$G$24/60 -> 30070.75 | ... AB33: =AB31*'Title Inputs'!$G$16*'Title Inputs'!$G$11*Scenarios!$G$24/60 -> 1919.2773
C34: Monetised ad impressions | D34: =SUM(E34:AB34) -> 6880519.2 | E34: =E33*'Title Inputs'!$G$24*Scenarios!$G$25 -> 1104938.8 | F34: =F33*'Title Inputs'!$G$24*Scenarios!$G$25 -> 930358.45 | G34: =G33*'Title Inputs'!$G$24*Scenarios!$G$25 -> 783361.81 | H34: =H33*'Title Inputs'!$G$24*Scenarios!$G$25 -> 659590.65 | I34: =I33*'Title Inputs'!$G$24*Scenarios!$G$25 -> 555375.33 | J34: =J33*'Title Inputs'!$G$24*Scenarios!$G$25 -> 467626.02 | K34: =K33*'Title Inputs'!$G$24*Scenarios!$G$25 -> 393741.11 | L34: =L33*'Title Inputs'!$G$24*Scenarios!$G$25 -> 331530.02 | ... AB34: =AB33*'Title Inputs'!$G$24*Scenarios!$G$25 -> 21160.032
C35: Gross advertising revenue ($) | D35: =SUM(E35:AB35) -> 128803.32 | E35: =E34/1000*Scenarios!$G$26 -> 20684.454 | F35: =F34/1000*Scenarios!$G$26 -> 17416.31 | G35: =G34/1000*Scenarios!$G$26 -> 14664.533 | H35: =H34/1000*Scenarios!$G$26 -> 12347.537 | I35: =I34/1000*Scenarios!$G$26 -> 10396.626 | J35: =J34/1000*Scenarios!$G$26 -> 8753.9592 | K35: =K34/1000*Scenarios!$G$26 -> 7370.8336 | L35: =L34/1000*Scenarios!$G$26 -> 6206.2419 | ... AB35: =AB34/1000*Scenarios!$G$26 -> 396.1158
B37: PORTFOLIO | C37: Portfolio unique viewers | D37: =$D$7+$D$13+$D$19+$D$25+$D$31 -> 10819822 | E37: =E7+E13+E19+E25+E31 -> 1490647.3 | F37: =F7+F13+F19+F25+F31 -> 1290902.9 | G37: =G7+G13+G19+G25+G31 -> 1118109.7 | H37: =H7+H13+H19+H25+H31 -> 968604.75 | I37: =I7+I13+I19+I25+I31 -> 839226.67 | J37: =J7+J13+J19+J25+J31 -> 727246.5 | K37: =K7+K13+K19+K25+K31 -> 630308.03 | L37: =L7+L13+L19+L25+L31 -> 546376.55 | ... AB37: =AB7+AB13+AB19+AB25+AB31 -> 56635.221
B38: PORTFOLIO | C38: Portfolio viewing hours | D38: =$D$9+$D$15+$D$21+$D$27+$D$33 -> 14529862 | E38: =E9+E15+E21+E27+E33 -> 1978778.9 | F38: =F9+F15+F21+F27+F33 -> 1717299.9 | G38: =G9+G15+G21+G27+G33 -> 1490580.8 | H38: =H9+H15+H21+H27+H33 -> 1293971.1 | I38: =I9+I15+I21+I27+I33 -> 1123447 | J38: =J9+J15+J21+J27+J33 -> 975525.64 | K38: =K9+K15+K21+K27+K33 -> 847192.58 | L38: =L9+L15+L21+L27+L33 -> 735837.93 | ... AB38: =AB9+AB15+AB21+AB27+AB33 -> 78461.596
B39: PORTFOLIO | C39: Portfolio monetised impressions | D39: =$D$10+$D$16+$D$22+$D$28+$D$34 -> 1.8028977e+08 | E39: =E10+E16+E22+E28+E34 -> 24477565 | F39: =F10+F16+F22+F28+F34 -> 21255184 | G39: =G10+G16+G22+G28+G34 -> 18459447 | H39: =H10+H16+H22+H28+H34 -> 16033521 | I39: =I10+I16+I22+I28+I34 -> 13928191 | J39: =J10+J16+J22+J28+J34 -> 12100836 | K39: =K10+K16+K22+K28+K34 -> 10514535 | L39: =L10+L16+L22+L28+L34 -> 9137304.7 | ... AB39: =AB10+AB16+AB22+AB28+AB34 -> 981552.46
B40: PORTFOLIO | C40: Portfolio gross advertising revenue ($) | D40: =$D$11+$D$17+$D$23+$D$29+$D$35 -> 4131414.2 | E40: =E11+E17+E23+E29+E35 -> 558404.24 | F40: =F11+F17+F23+F29+F35 -> 485293.21 | G40: =G11+G17+G23+G29+G35 -> 421805.38 | H40: =H11+H17+H23+H29+H35 -> 366666.84 | I40: =I11+I17+I23+I29+I35 -> 318773.38 | J40: =J11+J17+J23+J29+J35 -> 277167.68 | K40: =K11+K17+K23+K29+K35 -> 241019.7 | L40: =L11+L17+L23+L29+L35 -> 209609.59 | ... AB40: =AB11+AB17+AB23+AB29+AB35 -> 22761.454
C41: Cumulative viewing hours | D41: =AB41 -> 14529862 | E41: =SUM(E38:E38) -> 1978778.9 | F41: =SUM(E38:F38) -> 3696078.8 | G41: =SUM(E38:G38) -> 5186659.5 | H41: =SUM(E38:H38) -> 6480630.7 | I41: =SUM(E38:I38) -> 7604077.6 | J41: =SUM(E38:J38) -> 8579603.3 | K41: =SUM(E38:K38) -> 9426795.9 | L41: =SUM(E38:L38) -> 10162634 | M41: =SUM(E38:M38) -> 10801836 | N41: =SUM(E38:N38) -> 11357163 | O41: =SUM(E38:O38) -> 11839681 | P41: =SUM(E38:P38) -> 12258988 | Q41: =SUM(E38:Q38) -> 12623410 | R41: =SUM(E38:R38) -> 12940167 | S41: =SUM(E38:S38) -> 13215528 | T41: =SUM(E38:T38) -> 13454929 | U41: =SUM(E38:U38) -> 13663091 | V41: =SUM(E38:V38) -> 13844110 | W41: =SUM(E38:W38) -> 14001544 | X41: =SUM(E38:X38) -> 14138480 | Y41: =SUM(E38:Y38) -> 14257599 | Z41: =SUM(E38:Z38) -> 14361232 | AA41: =SUM(E38:AA38) -> 14451400 | AB41: =SUM(E38:AB38) -> 14529862
C42: Cumulative gross advertising revenue ($) | D42: =AB42 -> 4131414.2 | E42: =SUM(E40:E40) -> 558404.24 | F42: =SUM(E40:F40) -> 1043697.4 | G42: =SUM(E40:G40) -> 1465502.8 | H42: =SUM(E40:H40) -> 1832169.7 | I42: =SUM(E40:I40) -> 2150943 | J42: =SUM(E40:J40) -> 2428110.7 | K42: =SUM(E40:K40) -> 2669130.4 | L42: =SUM(E40:L40) -> 2878740 | M42: =SUM(E40:M40) -> 3061053 | N42: =SUM(E40:N40) -> 3219641.5 | O42: =SUM(E40:O40) -> 3357607.4 | P42: =SUM(E40:P40) -> 3477645.2 | Q42: =SUM(E40:Q40) -> 3582095.4 | R42: =SUM(E40:R40) -> 3672991.4 | S42: =SUM(E40:S40) -> 3752100.1 | T42: =SUM(E40:T40) -> 3820956.9 | U42: =SUM(E40:U40) -> 3880896.2 | V42: =SUM(E40:V40) -> 3933078 | W42: =SUM(E40:W40) -> 3978510.4 | X42: =SUM(E40:X40) -> 4018070.3 | Y42: =SUM(E40:Y40) -> 4052519.8 | Z42: =SUM(E40:Z40) -> 4082521.8 | AA42: =SUM(E40:AA40) -> 4108652.8 | AB42: =SUM(E40:AB40) -> 4131414.2
A45: BASE SCENARIO
A46: Base | B46: Nightfall Protocol | C46: Monthly unique viewers | D46: =SUM(E46:AB46) -> 3600000 | E46: =Scenarios!$C$32*(1-Scenarios!$C$31)^(E$4-1) -> 437303.52 | F46: =Scenarios!$C$32*(1-Scenarios!$C$31)^(F$4-1) -> 387013.61 | G46: =Scenarios!$C$32*(1-Scenarios!$C$31)^(G$4-1) -> 342507.05 | H46: =Scenarios!$C$32*(1-Scenarios!$C$31)^(H$4-1) -> 303118.74 | I46: =Scenarios!$C$32*(1-Scenarios!$C$31)^(I$4-1) -> 268260.08 | J46: =Scenarios!$C$32*(1-Scenarios!$C$31)^(J$4-1) -> 237410.17 | K46: =Scenarios!$C$32*(1-Scenarios!$C$31)^(K$4-1) -> 210108 | L46: =Scenarios!$C$32*(1-Scenarios!$C$31)^(L$4-1) -> 185945.58 | ... AB46: =Scenarios!$C$32*(1-Scenarios!$C$31)^(AB$4-1) -> 26331.657
C47: Share of modelled lifetime viewers | D47: =SUM(E47:AB47) -> 1 | E47: =E46/$D$46 -> 0.1214732 | F47: =F46/$D$46 -> 0.10750378 | G47: =G46/$D$46 -> 0.095140846 | H47: =H46/$D$46 -> 0.084199649 | I47: =I46/$D$46 -> 0.074516689 | J47: =J46/$D$46 -> 0.06594727 | K47: =K46/$D$46 -> 0.058363334 | L47: =L46/$D$46 -> 0.051651551 | ... AB47: =AB46/$D$46 -> 0.0073143493
C48: Viewing hours | D48: =SUM(E48:AB48) -> 5890560 | E48: =E46*'Title Inputs'!$C$16*'Title Inputs'!$C$11*Scenarios!$C$33/60 -> 715545.17 | F48: =F46*'Title Inputs'!$C$16*'Title Inputs'!$C$11*Scenarios!$C$33/60 -> 633257.47 | G48: =G46*'Title Inputs'!$C$16*'Title Inputs'!$C$11*Scenarios!$C$33/60 -> 560432.86 | H48: =H46*'Title Inputs'!$C$16*'Title Inputs'!$C$11*Scenarios!$C$33/60 -> 495983.08 | I48: =I46*'Title Inputs'!$C$16*'Title Inputs'!$C$11*Scenarios!$C$33/60 -> 438945.03 | J48: =J46*'Title Inputs'!$C$16*'Title Inputs'!$C$11*Scenarios!$C$33/60 -> 388466.35 | K48: =K46*'Title Inputs'!$C$16*'Title Inputs'!$C$11*Scenarios!$C$33/60 -> 343792.72 | L48: =L46*'Title Inputs'!$C$16*'Title Inputs'!$C$11*Scenarios!$C$33/60 -> 304256.56 | ... AB48: =AB46*'Title Inputs'!$C$16*'Title Inputs'!$C$11*Scenarios!$C$33/60 -> 43085.613
...

Sheet Title Economics
A1: PROJECT NIGHTFALL
A2: Monthly contribution by title and scenario
A3: Independent analytical case study using synthetic assumptions. Not based on proprietary company information.
A4: Scenario | B4: Title | C4: Month | D4: Total | E4: 1 | F4: 2 | G4: 3 | H4: 4 | I4: 5 | J4: 6 | K4: 7 | L4: 8 | M4: 9 | N4: 10 | O4: 11 | P4: 12 | Q4: 13 | R4: 14 | S4: 15 | T4: 16 | U4: 17 | V4: 18 | W4: 19 | X4: 20 | Y4: 21 | Z4: 22 | AA4: 23 | AB4: 24
C6: Discount factor (end of month) | E6: =1/(1+Assumptions!$C$14)^E$4 -> 0.9906004 | F6: =1/(1+Assumptions!$C$14)^F$4 -> 0.98128915 | G6: =1/(1+Assumptions!$C$14)^G$4 -> 0.97206542 | H6: =1/(1+Assumptions!$C$14)^H$4 -> 0.96292839 | I6: =1/(1+Assumptions!$C$14)^I$4 -> 0.95387725 | J6: =1/(1+Assumptions!$C$14)^J$4 -> 0.94491118 | K6: =1/(1+Assumptions!$C$14)^K$4 -> 0.93602939 | L6: =1/(1+Assumptions!$C$14)^L$4 -> 0.92723109 | ... AB6: =1/(1+Assumptions!$C$14)^AB$4 -> 0.79719388
A8: DOWNSIDE SCENARIO
A9: Downside | B9: Nightfall Protocol | C9: Incremental advertising revenue ($) | D9: =SUM(E9:AB9) -> 1012271.7 | E9: ='Monthly Viewing Forecast'!E11*Scenarios!$C$27 -> 130084.02 | F9: ='Monthly Viewing Forecast'!F11*Scenarios!$C$27 -> 114083.69 | G9: ='Monthly Viewing Forecast'!G11*Scenarios!$C$27 -> 100051.39 | H9: ='Monthly Viewing Forecast'!H11*Scenarios!$C$27 -> 87745.072 | I9: ='Monthly Viewing Forecast'!I11*Scenarios!$C$27 -> 76952.428 | J9: ='Monthly Viewing Forecast'!J11*Scenarios!$C$27 -> 67487.279 | K9: ='Monthly Viewing Forecast'!K11*Scenarios!$C$27 -> 59186.344 | L9: ='Monthly Viewing Forecast'!L11*Scenarios!$C$27 -> 51906.424 | ... AB9: ='Monthly Viewing Forecast'!AB11*Scenarios!$C$27 -> 6356.4495
C10: Follow-on engagement value ($) | D10: =SUM(E10:AB10) -> 144723.24 | E10: ='Monthly Viewing Forecast'!E9*Scenarios!$C$27*'Title Inputs'!$C$34 -> 18597.953 | F10: ='Monthly Viewing Forecast'!F9*Scenarios!$C$27*'Title Inputs'!$C$34 -> 16310.405 | G10: ='Monthly Viewing Forecast'!G9*Scenarios!$C$27*'Title Inputs'!$C$34 -> 14304.225 | H10: ='Monthly Viewing Forecast'!H9*Scenarios!$C$27*'Title Inputs'!$C$34 -> 12544.805 | I10: ='Monthly Viewing Forecast'!I9*Scenarios!$C$27*'Title Inputs'!$C$34 -> 11001.794 | J10: ='Monthly Viewing Forecast'!J9*Scenarios!$C$27*'Title Inputs'!$C$34 -> 9648.5735 | K10: ='Monthly Viewing Forecast'!K9*Scenarios!$C$27*'Title Inputs'!$C$34 -> 8461.7989 | L10: ='Monthly Viewing Forecast'!L9*Scenarios!$C$27*'Title Inputs'!$C$34 -> 7420.9977 | ... AB10: ='Monthly Viewing Forecast'!AB9*Scenarios!$C$27*'Title Inputs'!$C$34 -> 908.77378
C11: Marketing support ($) | D11: =SUM(E11:AB11) -> 173250 | E11: =Scenarios!$C$28*INDEX(Assumptions!$C$23:$C$26,E$4) -> 95287.5 | F11: =Scenarios!$C$28*INDEX(Assumptions!$C$23:$C$26,F$4) -> 43312.5 | G11: =Scenarios!$C$28*INDEX(Assumptions!$C$23:$C$26,G$4) -> 20790 | H11: =Scenarios!$C$28*INDEX(Assumptions!$C$23:$C$26,H$4) -> 13860 | I11: =0 -> 0 | J11: =0 -> 0 | K11: =0 -> 0 | L11: =0 -> 0 | M11: =0 -> 0 | N11: =0 -> 0 | O11: =0 -> 0 | P11: =0 -> 0 | ... AB11: =0 -> 0
C12: Delivery, localisation and QC ($) | D12: =SUM(E12:AB12) -> 58000 | E12: ='Title Inputs'!$C$32 -> 58000 | F12: =0 -> 0 | G12: =0 -> 0 | H12: =0 -> 0 | I12: =0 -> 0 | J12: =0 -> 0 | K12: =0 -> 0 | L12: =0 -> 0 | M12: =0 -> 0 | ... AB12: =0 -> 0
C13: Variable serving costs ($) | D13: =SUM(E13:AB13) -> 101605.2 | E13: ='Monthly Viewing Forecast'!E9*'Title Inputs'!$C$33 -> 13056.982 | F13: ='Monthly Viewing Forecast'!F9*'Title Inputs'!$C$33 -> 11450.973 | G13: ='Monthly Viewing Forecast'!G9*'Title Inputs'!$C$33 -> 10042.504 | H13: ='Monthly Viewing Forecast'!H9*'Title Inputs'!$C$33 -> 8807.2756 | I13: ='Monthly Viewing Forecast'!I9*'Title Inputs'!$C$33 -> 7723.9807 | J13: ='Monthly Viewing Forecast'!J9*'Title Inputs'!$C$33 -> 6773.9311 | K13: ='Monthly Viewing Forecast'!K9*'Title Inputs'!$C$33 -> 5940.7375 | L13: ='Monthly Viewing Forecast'!L9*'Title Inputs'!$C$33 -> 5210.0268 | ... AB13: ='Monthly Viewing Forecast'!AB9*'Title Inputs'!$C$33 -> 638.01877
C14: Contribution before licence fee ($) | D14: =SUM(E14:AB14) -> 824139.7 | E14: =E9+E10-E11-E12-E13 -> -17662.508 | F14: =F9+F10-F11-F12-F13 -> 75630.618 | G14: =G9+G10-G11-G12-G13 -> 83523.114 | H14: =H9+H10-H11-H12-H13 -> 77622.601 | I14: =I9+I10-I11-I12-I13 -> 80230.241 | J14: =J9+J10-J11-J12-J13 -> 70361.922 | K14: =K9+K10-K11-K12-K13 -> 61707.405 | L14: =L9+L10-L11-L12-L13 -> 54117.394 | ... AB14: =AB9+AB10-AB11-AB12-AB13 -> 6627.2045
A16: Downside | B16: Ash Ridge | C16: Incremental advertising revenue ($) | D16: =SUM(E16:AB16) -> 644473.23 | E16: ='Monthly Viewing Forecast'!E17*Scenarios!$D$27 -> 85694.019 | F16: ='Monthly Viewing Forecast'!F17*Scenarios!$D$27 -> 74725.184 | G16: ='Monthly Viewing Forecast'!G17*Scenarios!$D$27 -> 65160.361 | H16: ='Monthly Viewing Forecast'!H17*Scenarios!$D$27 -> 56819.835 | I16: ='Monthly Viewing Forecast'!I17*Scenarios!$D$27 -> 49546.896 | J16: ='Monthly Viewing Forecast'!J17*Scenarios!$D$27 -> 43204.893 | K16: ='Monthly Viewing Forecast'!K17*Scenarios!$D$27 -> 37674.667 | L16: ='Monthly Viewing Forecast'!L17*Scenarios!$D$27 -> 32852.309 | ... AB16: ='Monthly Viewing Forecast'!AB17*Scenarios!$D$27 -> 3671.3828
C17: Follow-on engagement value ($) | D17: =SUM(E17:AB17) -> 99106.889 | E17: ='Monthly Viewing Forecast'!E15*Scenarios!$D$27*'Title Inputs'!$D$34 -> 13177.999 | F17: ='Monthly Viewing Forecast'!F15*Scenarios!$D$27*'Title Inputs'!$D$34 -> 11491.215 | G17: ='Monthly Viewing Forecast'!G15*Scenarios!$D$27*'Title Inputs'!$D$34 -> 10020.34 | H17: ='Monthly Viewing Forecast'!H15*Scenarios!$D$27*'Title Inputs'!$D$34 -> 8737.7362 | I17: ='Monthly Viewing Forecast'!I15*Scenarios!$D$27*'Title Inputs'!$D$34 -> 7619.3059 | J17: ='Monthly Viewing Forecast'!J15*Scenarios!$D$27*'Title Inputs'!$D$34 -> 6644.0348 | K17: ='Monthly Viewing Forecast'!K15*Scenarios!$D$27*'Title Inputs'!$D$34 -> 5793.5983 | L17: ='Monthly Viewing Forecast'!L15*Scenarios!$D$27*'Title Inputs'!$D$34 -> 5052.0177 | ... AB17: ='Monthly Viewing Forecast'!AB15*Scenarios!$D$27*'Title Inputs'!$D$34 -> 564.58408
C18: Marketing support ($) | D18: =SUM(E18:AB18) -> 136500 | E18: =Scenarios!$D$28*INDEX(Assumptions!$C$23:$C$26,E$4) -> 75075 | F18: =Scenarios!$D$28*INDEX(Assumptions!$C$23:$C$26,F$4) -> 34125 | G18: =Scenarios!$D$28*INDEX(Assumptions!$C$23:$C$26,G$4) -> 16380 | H18: =Scenarios!$D$28*INDEX(Assumptions!$C$23:$C$26,H$4) -> 10920 | I18: =0 -> 0 | J18: =0 -> 0 | K18: =0 -> 0 | L18: =0 -> 0 | M18: =0 -> 0 | N18: =0 -> 0 | O18: =0 -> 0 | P18: =0 -> 0 | ... AB18: =0 -> 0
C19: Delivery, localisation and QC ($) | D19: =SUM(E19:AB19) -> 52000 | E19: ='Title Inputs'!$D$32 -> 52000 | F19: =0 -> 0 | G19: =0 -> 0 | H19: =0 -> 0 | I19: =0 -> 0 | J19: =0 -> 0 | K19: =0 -> 0 | L19: =0 -> 0 | M19: =0 -> 0 | ... AB19: =0 -> 0
C20: Variable serving costs ($) | D20: =SUM(E20:AB20) -> 74378.121 | E20: ='Monthly Viewing Forecast'!E15*'Title Inputs'!$D$33 -> 9889.8757 | F20: ='Monthly Viewing Forecast'!F15*'Title Inputs'!$D$33 -> 8623.9716 | G20: ='Monthly Viewing Forecast'!G15*'Title Inputs'!$D$33 -> 7520.1032 | H20: ='Monthly Viewing Forecast'!H15*'Title Inputs'!$D$33 -> 6557.53 | I20: ='Monthly Viewing Forecast'!I15*'Title Inputs'!$D$33 -> 5718.1662 | J20: ='Monthly Viewing Forecast'!J15*'Title Inputs'!$D$33 -> 4986.2409 | K20: ='Monthly Viewing Forecast'!K15*'Title Inputs'!$D$33 -> 4348.0021 | L20: ='Monthly Viewing Forecast'!L15*'Title Inputs'!$D$33 -> 3791.4578 | ... AB20: ='Monthly Viewing Forecast'!AB15*'Title Inputs'!$D$33 -> 423.71124
C21: Contribution before licence fee ($) | D21: =SUM(E21:AB21) -> 480701.99 | E21: =E16+E17-E18-E19-E20 -> -38092.858 | F21: =F16+F17-F18-F19-F20 -> 43467.428 | G21: =G16+G17-G18-G19-G20 -> 51280.597 | H21: =H16+H17-H18-H19-H20 -> 48080.041 | I21: =I16+I17-I18-I19-I20 -> 51448.035 | J21: =J16+J17-J18-J19-J20 -> 44862.687 | K21: =K16+K17-K18-K19-K20 -> 39120.263 | L21: =L16+L17-L18-L19-L20 -> 34112.869 | ... AB21: =AB16+AB17-AB18-AB19-AB20 -> 3812.2556
A23: Downside | B23: Cold Harbor | C23: Incremental advertising revenue ($) | D23: =SUM(E23:AB23) -> 407722.05 | E23: ='Monthly Viewing Forecast'!E23*Scenarios!$E$27 -> 57161.934 | F23: ='Monthly Viewing Forecast'!F23*Scenarios!$E$27 -> 49387.911 | G23: ='Monthly Viewing Forecast'!G23*Scenarios!$E$27 -> 42671.155 | H23: ='Monthly Viewing Forecast'!H23*Scenarios!$E$27 -> 36867.878 | I23: ='Monthly Viewing Forecast'!I23*Scenarios!$E$27 -> 31853.847 | J23: ='Monthly Viewing Forecast'!J23*Scenarios!$E$27 -> 27521.724 | K23: ='Monthly Viewing Forecast'!K23*Scenarios!$E$27 -> 23778.769 | L23: ='Monthly Viewing Forecast'!L23*Scenarios!$E$27 -> 20544.857 | ... AB23: ='Monthly Viewing Forecast'!AB23*Scenarios!$E$27 -> 1981.1757
C24: Follow-on engagement value ($) | D24: =SUM(E24:AB24) -> 68380.123 | E24: ='Monthly Viewing Forecast'!E21*Scenarios!$E$27*'Title Inputs'!$E$34 -> 9586.7764 | F24: ='Monthly Viewing Forecast'!F21*Scenarios!$E$27*'Title Inputs'!$E$34 -> 8282.9749 | G24: ='Monthly Viewing Forecast'!G21*Scenarios!$E$27*'Title Inputs'!$E$34 -> 7156.4903 | H24: ='Monthly Viewing Forecast'!H21*Scenarios!$E$27*'Title Inputs'!$E$34 -> 6183.2076 | I24: ='Monthly Viewing Forecast'!I21*Scenarios!$E$27*'Title Inputs'!$E$34 -> 5342.2914 | J24: ='Monthly Viewing Forecast'!J21*Scenarios!$E$27*'Title Inputs'!$E$34 -> 4615.7397 | K24: ='Monthly Viewing Forecast'!K21*Scenarios!$E$27*'Title Inputs'!$E$34 -> 3987.9991 | L24: ='Monthly Viewing Forecast'!L21*Scenarios!$E$27*'Title Inputs'!$E$34 -> 3445.6313 | ... AB24: ='Monthly Viewing Forecast'!AB21*Scenarios!$E$27*'Title Inputs'!$E$34 -> 332.26812
C25: Marketing support ($) | D25: =SUM(E25:AB25) -> 105000 | E25: =Scenarios!$E$28*INDEX(Assumptions!$C$23:$C$26,E$4) -> 57750 | F25: =Scenarios!$E$28*INDEX(Assumptions!$C$23:$C$26,F$4) -> 26250 | G25: =Scenarios!$E$28*INDEX(Assumptions!$C$23:$C$26,G$4) -> 12600 | H25: =Scenarios!$E$28*INDEX(Assumptions!$C$23:$C$26,H$4) -> 8400 | I25: =0 -> 0 | J25: =0 -> 0 | K25: =0 -> 0 | L25: =0 -> 0 | M25: =0 -> 0 | N25: =0 -> 0 | O25: =0 -> 0 | P25: =0 -> 0 | ... AB25: =0 -> 0
C26: Delivery, localisation and QC ($) | D26: =SUM(E26:AB26) -> 46000 | E26: ='Title Inputs'!$E$32 -> 46000 | F26: =0 -> 0 | G26: =0 -> 0 | H26: =0 -> 0 | I26: =0 -> 0 | J26: =0 -> 0 | K26: =0 -> 0 | L26: =0 -> 0 | M26: =0 -> 0 | ... AB26: =0 -> 0
C27: Variable serving costs ($) | D27: =SUM(E27:AB27) -> 54117.353 | E27: ='Monthly Viewing Forecast'!E21*'Title Inputs'!$E$33 -> 7587.1604 | F27: ='Monthly Viewing Forecast'!F21*'Title Inputs'!$E$33 -> 6555.3066 | G27: ='Monthly Viewing Forecast'!G21*'Title Inputs'!$E$33 -> 5663.7849 | H27: ='Monthly Viewing Forecast'!H21*'Title Inputs'!$E$33 -> 4893.5101 | I27: ='Monthly Viewing Forecast'!I21*'Title Inputs'!$E$33 -> 4227.9927 | J27: ='Monthly Viewing Forecast'!J21*'Title Inputs'!$E$33 -> 3652.9857 | K27: ='Monthly Viewing Forecast'!K21*'Title Inputs'!$E$33 -> 3156.1797 | L27: ='Monthly Viewing Forecast'!L21*'Title Inputs'!$E$33 -> 2726.9392 | ... AB27: ='Monthly Viewing Forecast'!AB21*'Title Inputs'!$E$33 -> 262.96342
C28: Contribution before licence fee ($) | D28: =SUM(E28:AB28) -> 270984.82 | E28: =E23+E24-E25-E26-E27 -> -44588.45 | F28: =F23+F24-F25-F26-F27 -> 24865.58 | G28: =G23+G24-G25-G26-G27 -> 31563.861 | H28: =H23+H24-H25-H26-H27 -> 29757.576 | I28: =I23+I24-I25-I26-I27 -> 32968.145 | J28: =J23+J24-J25-J26-J27 -> 28484.478 | K28: =K23+K24-K25-K26-K27 -> 24610.589 | L28: =L23+L24-L25-L26-L27 -> 21263.549 | ... AB28: =AB23+AB24-AB25-AB26-AB27 -> 2050.4804
A30: Downside | B30: The Quiet Depth | C30: Incremental advertising revenue ($) | D30: =SUM(E30:AB30) -> 186760.51 | E30: ='Monthly Viewing Forecast'!E29*Scenarios!$F$27 -> 28245.192 | F30: ='Monthly Viewing Forecast'!F29*Scenarios!$F$27 -> 24064.904 | G30: ='Monthly Viewing Forecast'!G29*Scenarios!$F$27 -> 20503.298 | H30: ='Monthly Viewing Forecast'!H29*Scenarios!$F$27 -> 17468.81 | I30: ='Monthly Viewing Forecast'!I29*Scenarios!$F$27 -> 14883.426 | J30: ='Monthly Viewing Forecast'!J29*Scenarios!$F$27 -> 12680.679 | K30: ='Monthly Viewing Forecast'!K29*Scenarios!$F$27 -> 10803.938 | L30: ='Monthly Viewing Forecast'!L29*Scenarios!$F$27 -> 9204.9555 | ... AB30: ='Monthly Viewing Forecast'!AB29*Scenarios!$F$27 -> 709.66798
C31: Follow-on engagement value ($) | D31: =SUM(E31:AB31) -> 36829.767 | E31: ='Monthly Viewing Forecast'!E27*Scenarios!$F$27*'Title Inputs'!$F$34 -> 5570.0418 | F31: ='Monthly Viewing Forecast'!F27*Scenarios!$F$27*'Title Inputs'!$F$34 -> 4745.6756 | G31: ='Monthly Viewing Forecast'!G27*Scenarios!$F$27*'Title Inputs'!$F$34 -> 4043.3156 | H31: ='Monthly Viewing Forecast'!H27*Scenarios!$F$27*'Title Inputs'!$F$34 -> 3444.9049 | I31: ='Monthly Viewing Forecast'!I27*Scenarios!$F$27*'Title Inputs'!$F$34 -> 2935.059 | J31: ='Monthly Viewing Forecast'!J27*Scenarios!$F$27*'Title Inputs'!$F$34 -> 2500.6703 | K31: ='Monthly Viewing Forecast'!K27*Scenarios!$F$27*'Title Inputs'!$F$34 -> 2130.5711 | L31: ='Monthly Viewing Forecast'!L27*Scenarios!$F$27*'Title Inputs'!$F$34 -> 1815.2466 | ... AB31: ='Monthly Viewing Forecast'!AB27*Scenarios!$F$27*'Title Inputs'!$F$34 -> 139.94879
C32: Marketing support ($) | D32: =SUM(E32:AB32) -> 75600 | E32: =Scenarios!$F$28*INDEX(Assumptions!$C$23:$C$26,E$4) -> 41580 | F32: =Scenarios!$F$28*INDEX(Assumptions!$C$23:$C$26,F$4) -> 18900 | G32: =Scenarios!$F$28*INDEX(Assumptions!$C$23:$C$26,G$4) -> 9072 | H32: =Scenarios!$F$28*INDEX(Assumptions!$C$23:$C$26,H$4) -> 6048 | I32: =0 -> 0 | J32: =0 -> 0 | K32: =0 -> 0 | L32: =0 -> 0 | M32: =0 -> 0 | N32: =0 -> 0 | O32: =0 -> 0 | P32: =0 -> 0 | ... AB32: =0 -> 0
C33: Delivery, localisation and QC ($) | D33: =SUM(E33:AB33) -> 44000 | E33: ='Title Inputs'!$F$32 -> 44000 | F33: =0 -> 0 | G33: =0 -> 0 | H33: =0 -> 0 | I33: =0 -> 0 | J33: =0 -> 0 | K33: =0 -> 0 | L33: =0 -> 0 | M33: =0 -> 0 | ... AB33: =0 -> 0
C34: Variable serving costs ($) | D34: =SUM(E34:AB34) -> 34109.116 | E34: ='Monthly Viewing Forecast'!E27*'Title Inputs'!$F$33 -> 5158.5774 | F34: ='Monthly Viewing Forecast'!F27*'Title Inputs'!$F$33 -> 4395.108 | G34: ='Monthly Viewing Forecast'!G27*'Title Inputs'!$F$33 -> 3744.632 | H34: ='Monthly Viewing Forecast'!H27*'Title Inputs'!$F$33 -> 3190.4264 | I34: ='Monthly Viewing Forecast'!I27*'Title Inputs'!$F$33 -> 2718.2433 | J34: ='Monthly Viewing Forecast'!J27*'Title Inputs'!$F$33 -> 2315.9433 | K34: ='Monthly Viewing Forecast'!K27*'Title Inputs'!$F$33 -> 1973.1837 | L34: ='Monthly Viewing Forecast'!L27*'Title Inputs'!$F$33 -> 1681.1525 | ... AB34: ='Monthly Viewing Forecast'!AB27*'Title Inputs'!$F$33 -> 129.61063
C35: Contribution before licence fee ($) | D35: =SUM(E35:AB35) -> 69881.157 | E35: =E30+E31-E32-E33-E34 -> -56923.344 | F35: =F30+F31-F32-F33-F34 -> 5515.4712 | G35: =G30+G31-G32-G33-G34 -> 11729.981 | H35: =H30+H31-H32-H33-H34 -> 11675.288 | I35: =I30+I31-I32-I33-I34 -> 15100.242 | J35: =J30+J31-J32-J33-J34 -> 12865.406 | K35: =K30+K31-K32-K33-K34 -> 10961.326 | L35: =L30+L31-L32-L33-L34 -> 9339.0495 | ... AB35: =AB30+AB31-AB32-AB33-AB34 -> 720.00613
A37: Downside | B37: Vector Nine | C37: Incremental advertising revenue ($) | D37: =SUM(E37:AB37) -> 49975.688 | E37: ='Monthly Viewing Forecast'!E35*Scenarios!$G$27 -> 8025.5681 | F37: ='Monthly Viewing Forecast'!F35*Scenarios!$G$27 -> 6757.5283 | G37: ='Monthly Viewing Forecast'!G35*Scenarios!$G$27 -> 5689.8389 | H37: ='Monthly Viewing Forecast'!H35*Scenarios!$G$27 -> 4790.8443 | I37: ='Monthly Viewing Forecast'!I35*Scenarios!$G$27 -> 4033.8909 | J37: ='Monthly Viewing Forecast'!J35*Scenarios!$G$27 -> 3396.5362 | K37: ='Monthly Viewing Forecast'!K35*Scenarios!$G$27 -> 2859.8834 | L37: ='Monthly Viewing Forecast'!L35*Scenarios!$G$27 -> 2408.0219 | ... AB37: ='Monthly Viewing Forecast'!AB35*Scenarios!$G$27 -> 153.69293
C38: Follow-on engagement value ($) | D38: =SUM(E38:AB38) -> 10896.496 | E38: ='Monthly Viewing Forecast'!E33*Scenarios!$G$27*'Title Inputs'!$G$34 -> 1749.8622 | F38: ='Monthly Viewing Forecast'!F33*Scenarios!$G$27*'Title Inputs'!$G$34 -> 1473.384 | G38: ='Monthly Viewing Forecast'!G33*Scenarios!$G$27*'Title Inputs'!$G$34 -> 1240.5893 | H38: ='Monthly Viewing Forecast'!H33*Scenarios!$G$27*'Title Inputs'!$G$34 -> 1044.5762 | I38: ='Monthly Viewing Forecast'!I33*Scenarios!$G$27*'Title Inputs'!$G$34 -> 879.53317 | J38: ='Monthly Viewing Forecast'!J33*Scenarios!$G$27*'Title Inputs'!$G$34 -> 740.56693 | K38: ='Monthly Viewing Forecast'!K33*Scenarios!$G$27*'Title Inputs'!$G$34 -> 623.55735 | L38: ='Monthly Viewing Forecast'!L33*Scenarios!$G$27*'Title Inputs'!$G$34 -> 525.03529 | ... AB38: ='Monthly Viewing Forecast'!AB33*Scenarios!$G$27*'Title Inputs'!$G$34 -> 33.510581
C39: Marketing support ($) | D39: =SUM(E39:AB39) -> 60900 | E39: =Scenarios!$G$28*INDEX(Assumptions!$C$23:$C$26,E$4) -> 33495 | F39: =Scenarios!$G$28*INDEX(Assumptions!$C$23:$C$26,F$4) -> 15225 | G39: =Scenarios!$G$28*INDEX(Assumptions!$C$23:$C$26,G$4) -> 7308 | H39: =Scenarios!$G$28*INDEX(Assumptions!$C$23:$C$26,H$4) -> 4872 | I39: =0 -> 0 | J39: =0 -> 0 | K39: =0 -> 0 | L39: =0 -> 0 | M39: =0 -> 0 | N39: =0 -> 0 | O39: =0 -> 0 | P39: =0 -> 0 | ... AB39: =0 -> 0
C40: Delivery, localisation and QC ($) | D40: =SUM(E40:AB40) -> 40000 | E40: ='Title Inputs'!$G$32 -> 40000 | F40: =0 -> 0 | G40: =0 -> 0 | H40: =0 -> 0 | I40: =0 -> 0 | J40: =0 -> 0 | K40: =0 -> 0 | L40: =0 -> 0 | M40: =0 -> 0 | ... AB40: =0 -> 0
C41: Variable serving costs ($) | D41: =SUM(E41:AB41) -> 11857.584 | E41: ='Monthly Viewing Forecast'!E33*'Title Inputs'!$G$33 -> 1904.2029 | F41: ='Monthly Viewing Forecast'!F33*'Title Inputs'!$G$33 -> 1603.3388 | G41: ='Monthly Viewing Forecast'!G33*'Title Inputs'!$G$33 -> 1350.0113 | H41: ='Monthly Viewing Forecast'!H33*'Title Inputs'!$G$33 -> 1136.7095 | I41: ='Monthly Viewing Forecast'!I33*'Title Inputs'!$G$33 -> 957.1094 | J41: ='Monthly Viewing Forecast'!J33*'Title Inputs'!$G$33 -> 805.88612 | K41: ='Monthly Viewing Forecast'!K33*'Title Inputs'!$G$33 -> 678.55611 | L41: ='Monthly Viewing Forecast'!L33*'Title Inputs'!$G$33 -> 571.34425 | ... AB41: ='Monthly Viewing Forecast'!AB33*'Title Inputs'!$G$33 -> 36.466268
C42: Contribution before licence fee ($) | D42: =SUM(E42:AB42) -> -51885.401 | E42: =E37+E38-E39-E40-E41 -> -65623.773 | F42: =F37+F38-F39-F40-F41 -> -8597.4265 | G42: =G37+G38-G39-G40-G41 -> -1727.5831 | H42: =H37+H38-H39-H40-H41 -> -173.28897 | I42: =I37+I38-I39-I40-I41 -> 3956.3147 | J42: =J37+J38-J39-J40-J41 -> 3331.217 | K42: =K37+K38-K39-K40-K41 -> 2804.8847 | L42: =L37+L38-L39-L40-L41 -> 2361.7129 | ... AB42: =AB37+AB38-AB39-AB40-AB41 -> 150.73724
B44: PORTFOLIO | C44: Portfolio incremental advertising revenue ($) | D44: =$D$9+$D$16+$D$23+$D$30+$D$37 -> 2301203.1 | E44: =E9+E16+E23+E30+E37 -> 309210.73 | F44: =F9+F16+F23+F30+F37 -> 269019.21 | G44: =G9+G16+G23+G30+G37 -> 234076.05 | H44: =H9+H16+H23+H30+H37 -> 203692.44 | I44: =I9+I16+I23+I30+I37 -> 177270.49 | J44: =J9+J16+J23+J30+J37 -> 154291.11 | K44: =K9+K16+K23+K30+K37 -> 134303.6 | L44: =L9+L16+L23+L30+L37 -> 116916.57 | ... AB44: =AB9+AB16+AB23+AB30+AB37 -> 12872.369
B45: PORTFOLIO | C45: Portfolio follow-on engagement value ($) | D45: =$D$10+$D$17+$D$24+$D$31+$D$38 -> 359936.51 | E45: =E10+E17+E24+E31+E38 -> 48682.632 | F45: =F10+F17+F24+F31+F38 -> 42303.654 | G45: =G10+G17+G24+G31+G38 -> 36764.96 | H45: =H10+H17+H24+H31+H38 -> 31955.23 | I45: =I10+I17+I24+I31+I38 -> 27777.984 | J45: =J10+J17+J24+J31+J38 -> 24149.585 | K45: =K10+K17+K24+K31+K38 -> 20997.525 | L45: =L10+L17+L24+L31+L38 -> 18258.929 | ... AB45: =AB10+AB17+AB24+AB31+AB38 -> 1979.0853
B46: PORTFOLIO | C46: Portfolio marketing support ($) | D46: =$D$11+$D$18+$D$25+$D$32+$D$39 -> 551250 | E46: =E11+E18+E25+E32+E39 -> 303187.5 | F46: =F11+F18+F25+F32+F39 -> 137812.5 | G46: =G11+G18+G25+G32+G39 -> 66150 | H46: =H11+H18+H25+H32+H39 -> 44100 | I46: =I11+I18+I25+I32+I39 -> 0 | J46: =J11+J18+J25+J32+J39 -> 0 | K46: =K11+K18+K25+K32+K39 -> 0 | L46: =L11+L18+L25+L32+L39 -> 0 | ... AB46: =AB11+AB18+AB25+AB32+AB39 -> 0
B47: PORTFOLIO | C47: Portfolio delivery, localisation and QC ($) | D47: =$D$12+$D$19+$D$26+$D$33+$D$40 -> 240000 | E47: =E12+E19+E26+E33+E40 -> 240000 | F47: =F12+F19+F26+F33+F40 -> 0 | G47: =G12+G19+G26+G33+G40 -> 0 | H47: =H12+H19+H26+H33+H40 -> 0 | I47: =I12+I19+I26+I33+I40 -> 0 | J47: =J12+J19+J26+J33+J40 -> 0 | K47: =K12+K19+K26+K33+K40 -> 0 | L47: =L12+L19+L26+L33+L40 -> 0 | ... AB47: =AB12+AB19+AB26+AB33+AB40 -> 0
...

Sheet Deal Structures
A1: PROJECT NIGHTFALL
A2: Payment mechanics and comparison of three deal structures
A3: Independent analytical case study using synthetic assumptions. Not based on proprietary company information.
A4: Scenario | B4: Structure | C4: Month | D4: Total | E4: 1 | F4: 2 | G4: 3 | H4: 4 | I4: 5 | J4: 6 | K4: 7 | L4: 8 | M4: 9 | N4: 10 | O4: 11 | P4: 12 | Q4: 13 | R4: 14 | S4: 15 | T4: 16 | U4: 17 | V4: 18 | W4: 19 | X4: 20 | Y4: 21 | Z4: 22 | AA4: 23 | AB4: 24
C6: Structure A licence fee - recommended target price ($) | D6: =Scenarios!$C$66 -> 1498516.7 | F6: All three structures are priced from the same recommended target price so that they are comparable.
A8: DOWNSIDE SCENARIO
A9: Downside | B9: A - Fixed licence fee | C9: Licence payment ($) | D9: =SUM(E9:AB9) -> 1498516.7 | E9: =IF(E$4=Assumptions!$C$31,'Deal Structures'!$D$6*Assumptions!$C$30,0)+IF(E$4=Assumptions!$C$33,'Deal Structures'!$D$6*Assumptions!$C$32,0) -> 749258.33 | F9: =IF(F$4=Assumptions!$C$31,'Deal Structures'!$D$6*Assumptions!$C$30,0)+IF(F$4=Assumptions!$C$33,'Deal Structures'!$D$6*Assumptions!$C$32,0) -> 0 | G9: =IF(G$4=Assumptions!$C$31,'Deal Structures'!$D$6*Assumptions!$C$30,0)+IF(G$4=Assumptions!$C$33,'Deal Structures'!$D$6*Assumptions!$C$32,0) -> 0 | H9: =IF(H$4=Assumptions!$C$31,'Deal Structures'!$D$6*Assumptions!$C$30,0)+IF(H$4=Assumptions!$C$33,'Deal Structures'!$D$6*Assumptions!$C$32,0) -> 0 | I9: =IF(I$4=Assumptions!$C$31,'Deal Structures'!$D$6*Assumptions!$C$30,0)+IF(I$4=Assumptions!$C$33,'Deal Structures'!$D$6*Assumptions!$C$32,0) -> 0 | J9: =IF(J$4=Assumptions!$C$31,'Deal Structures'!$D$6*Assumptions!$C$30,0)+IF(J$4=Assumptions!$C$33,'Deal Structures'!$D$6*Assumptions!$C$32,0) -> 0 | K9: =IF(K$4=Assumptions!$C$31,'Deal Structures'!$D$6*Assumptions!$C$30,0)+IF(K$4=Assumptions!$C$33,'Deal Structures'!$D$6*Assumptions!$C$32,0) -> 749258.33 | L9: =IF(L$4=Assumptions!$C$31,'Deal Structures'!$D$6*Assumptions!$C$30,0)+IF(L$4=Assumptions!$C$33,'Deal Structures'!$D$6*Assumptions!$C$32,0) -> 0 | ... AB9: =IF(AB$4=Assumptions!$C$31,'Deal Structures'!$D$6*Assumptions!$C$30,0)+IF(AB$4=Assumptions!$C$33,'Deal Structures'!$D$6*Assumptions!$C$32,0) -> 0
C10: Net cash flow ($) | D10: =SUM(E10:AB10) -> 95305.615 | E10: ='Title Economics'!E51-E9 -> -972149.26 | F10: ='Title Economics'!F51-F9 -> 140881.67 | G10: ='Title Economics'!G51-G9 -> 176369.97 | H10: ='Title Economics'!H51-H9 -> 166962.22 | I10: ='Title Economics'!I51-I9 -> 183702.98 | J10: ='Title Economics'!J51-J9 -> 159905.71 | K10: ='Title Economics'!K51-K9 -> -610053.86 | L10: ='Title Economics'!L51-L9 -> 121194.57 | ... AB10: ='Title Economics'!AB51-AB9 -> 13360.684
C11: Cumulative net cash flow ($) | D11: =SUM(E11:AB11) -> -6742743.2 | E11: =SUM($E$10:E10) -> -972149.26 | F11: =SUM($E$10:F10) -> -831267.59 | G11: =SUM($E$10:G10) -> -654897.62 | H11: =SUM($E$10:H10) -> -487935.4 | I11: =SUM($E$10:I10) -> -304232.42 | J11: =SUM($E$10:J10) -> -144326.72 | K11: =SUM($E$10:K10) -> -754380.58 | L11: =SUM($E$10:L10) -> -633186 | ... AB11: =SUM($E$10:AB10) -> 95305.615
C12: Payback flag | D12: =IFERROR(MATCH(1,E12:AB12,0),"n/a") -> 19 | E12: =IF(MIN(E11:$AB$11)>0,1,0) -> 0 | F12: =IF(MIN(F11:$AB$11)>0,1,0) -> 0 | G12: =IF(MIN(G11:$AB$11)>0,1,0) -> 0 | H12: =IF(MIN(H11:$AB$11)>0,1,0) -> 0 | I12: =IF(MIN(I11:$AB$11)>0,1,0) -> 0 | J12: =IF(MIN(J11:$AB$11)>0,1,0) -> 0 | K12: =IF(MIN(K11:$AB$11)>0,1,0) -> 0 | L12: =IF(MIN(L11:$AB$11)>0,1,0) -> 0 | ... AB12: =IF(MIN(AB11:$AB$11)>0,1,0) -> 1
A14: Downside | B14: B - Minimum guarantee plus revenue share | C14: Revenue share accrued ($) | D14: =SUM(E14:AB14) -> 1156796 | E14: ='Monthly Viewing Forecast'!E40*Assumptions!$C$38 -> 156353.19 | F14: ='Monthly Viewing Forecast'!F40*Assumptions!$C$38 -> 135882.1 | G14: ='Monthly Viewing Forecast'!G40*Assumptions!$C$38 -> 118105.51 | H14: ='Monthly Viewing Forecast'!H40*Assumptions!$C$38 -> 102666.72 | I14: ='Monthly Viewing Forecast'!I40*Assumptions!$C$38 -> 89256.546 | J14: ='Monthly Viewing Forecast'!J40*Assumptions!$C$38 -> 77606.951 | K14: ='Monthly Viewing Forecast'!K40*Assumptions!$C$38 -> 67485.515 | L14: ='Monthly Viewing Forecast'!L40*Assumptions!$C$38 -> 58690.685 | ... AB14: ='Monthly Viewing Forecast'!AB40*Assumptions!$C$38 -> 6373.207
C15: Cumulative revenue share accrued ($) | D15: =AB15 -> 1156796 | E15: =SUM($E$14:E14) -> 156353.19 | F15: =SUM($E$14:F14) -> 292235.29 | G15: =SUM($E$14:G14) -> 410340.79 | H15: =SUM($E$14:H14) -> 513007.51 | I15: =SUM($E$14:I14) -> 602264.05 | J15: =SUM($E$14:J14) -> 679871 | K15: =SUM($E$14:K14) -> 747356.52 | L15: =SUM($E$14:L14) -> 806047.2 | ... AB15: =SUM($E$14:AB14) -> 1156796
C16: Cumulative obligation ($) | D16: =AB16 -> 1156796 | E16: =MAX(Assumptions!$C$37,E15) -> 950000 | F16: =MAX(Assumptions!$C$37,F15) -> 950000 | G16: =MAX(Assumptions!$C$37,G15) -> 950000 | H16: =MAX(Assumptions!$C$37,H15) -> 950000 | I16: =MAX(Assumptions!$C$37,I15) -> 950000 | J16: =MAX(Assumptions!$C$37,J15) -> 950000 | K16: =MAX(Assumptions!$C$37,K15) -> 950000 | L16: =MAX(Assumptions!$C$37,L15) -> 950000 | ... AB16: =MAX(Assumptions!$C$37,AB15) -> 1156796
C17: Licence payment ($) | D17: =SUM(E17:AB17) -> 1156796 | E17: =E16 -> 950000 | F17: =F16-E16 -> 0 | G17: =G16-F16 -> 0 | H17: =H16-G16 -> 0 | I17: =I16-H16 -> 0 | J17: =J16-I16 -> 0 | K17: =K16-J16 -> 0 | L17: =L16-K16 -> 0 | M17: =M16-L16 -> 0 | ... AB17: =AB16-AA16 -> 6373.207
C18: Net cash flow ($) | D18: =SUM(E18:AB18) -> 437026.29 | E18: ='Title Economics'!E51-E17 -> -1172890.9 | F18: ='Title Economics'!F51-F17 -> 140881.67 | G18: ='Title Economics'!G51-G17 -> 176369.97 | H18: ='Title Economics'!H51-H17 -> 166962.22 | I18: ='Title Economics'!I51-I17 -> 183702.98 | J18: ='Title Economics'!J51-J17 -> 159905.71 | K18: ='Title Economics'!K51-K17 -> 139204.47 | L18: ='Title Economics'!L51-L17 -> 121194.57 | ... AB18: ='Title Economics'!AB51-AB17 -> 6987.4769
C19: Cumulative net cash flow ($) | D19: =SUM(E19:AB19) -> 138499.98 | E19: =SUM($E$18:E18) -> -1172890.9 | F19: =SUM($E$18:F18) -> -1032009.3 | G19: =SUM($E$18:G18) -> -855639.29 | H19: =SUM($E$18:H18) -> -688677.07 | I19: =SUM($E$18:I18) -> -504974.1 | J19: =SUM($E$18:J18) -> -345068.39 | K19: =SUM($E$18:K18) -> -205863.92 | L19: =SUM($E$18:L18) -> -84669.345 | ... AB19: =SUM($E$18:AB18) -> 437026.29
C20: Payback flag | D20: =IFERROR(MATCH(1,E20:AB20,0),"n/a") -> 9 | E20: =IF(MIN(E19:$AB$19)>0,1,0) -> 0 | F20: =IF(MIN(F19:$AB$19)>0,1,0) -> 0 | G20: =IF(MIN(G19:$AB$19)>0,1,0) -> 0 | H20: =IF(MIN(H19:$AB$19)>0,1,0) -> 0 | I20: =IF(MIN(I19:$AB$19)>0,1,0) -> 0 | J20: =IF(MIN(J19:$AB$19)>0,1,0) -> 0 | K20: =IF(MIN(K19:$AB$19)>0,1,0) -> 0 | L20: =IF(MIN(L19:$AB$19)>0,1,0) -> 0 | ... AB20: =IF(MIN(AB19:$AB$19)>0,1,0) -> 1
A22: Downside | B22: C - Performance fee with earn-outs | C22: Cumulative viewing hours | D22: =AB22 -> 14529862 | E22: ='Monthly Viewing Forecast'!E41 -> 1978778.9 | F22: ='Monthly Viewing Forecast'!F41 -> 3696078.8 | G22: ='Monthly Viewing Forecast'!G41 -> 5186659.5 | H22: ='Monthly Viewing Forecast'!H41 -> 6480630.7 | I22: ='Monthly Viewing Forecast'!I41 -> 7604077.6 | J22: ='Monthly Viewing Forecast'!J41 -> 8579603.3 | K22: ='Monthly Viewing Forecast'!K41 -> 9426795.9 | L22: ='Monthly Viewing Forecast'!L41 -> 10162634 | ... AB22: ='Monthly Viewing Forecast'!AB41 -> 14529862
