Workbook

Sheet Cover
B2: U.S. Streaming Subscription Pricing Analysis, 2018–2026
B3: What has actually risen since 2018, in nominal and real terms, and whether ad tiers and bundles are absorbing it
B5: Work sample · Subscription & pricing analytics
B6: Tanmay Srivastava · srivasta@mail.uc.edu · linkedin.com/in/srivasta26
B7: Version 2.0 · Prices as of 29 July 2026 · All current prices re-verified 29–30 July 2026
B9: WHAT'S IN THIS WORKBOOK
B10: Standalone subscriber growth has matured, so price and packaging are the levers services pull to manage revenue and churn. This workbook quantifies (1) how U.S. list prices have moved since each service launched, nominal and real; (2) whether the ad-supported tier is functioning as the cheap entry point the industry narrative assumes; and (3) how far bundles discount against standalone pricing. Every headline figure is derived in-sheet from the Price History table.
B13: Tab | C13: Contents
B14: Price History | C14: 67 dated price points, 8 services, 17 tiers, 2018–2026. Every row carries a clickable source link, a publication date and a confidence flag.
B15: Panel | C15: Year-end price for every tracked tier, derived by formula from Price History. Everything downstream reads from here.
B16: Price Analysis | C16: Total change and CAGR per flagship tier, over each service's own window and a common 2022–2026 window. Mean, median and n.
B17: Real vs Nominal | C17: Each endpoint deflated by the CPI-U index of its own period.
B18: Ad vs No-Ad | C18: Category-average price by tier type, averaged from the Panel — no typed figures.
B19: Bundles | C19: Bundle price vs. component standalone prices at a stated date, split by archetype, with eligibility noted.
B20: Price Event Cadence | C20: Price changes per year, counted from Price History with COUNTIFS, and normalized per active tier.
B21: Subscriber & ARPU | C21: Company-reported figures where disclosed, with the scope of each metric recorded. Not used in any calculation.
B22: CPI Deflator | C22: BLS CPI-U annual averages to 2024; 2025 and 2026 are flagged provisional inputs with a sensitivity note.
B23: Methodology | C23: Definitions, limitations and a changelog of every correction made across two revisions.
B25: METHODOLOGY & CAVEATS
B26: • | C26: All figures are U.S. list prices, monthly, in USD, for a new direct subscriber. Promotional, annual, student, partner and app-store prices are excluded.
B27: • | C27: The panel is not claimed to be exhaustive. It records every price change that could be sourced and dated for the tracked tiers. Where a step could not be tied to a contemporaneous report it is flagged Medium confidence.
B28: • | C28: CAGR windows differ by service (5.4 to 8.3 years) and are not directly comparable. The common 2022–2026 window exists for that comparison. Mean, median, range and n are shown together.
B29: • | C29: Real figures deflate each price by the CPI-U index of the year it took effect, at both ends.
B30: • | C30: ESPN Select has no ad-free tier. Its ad-supported plan is its flagship and is excluded from all ad-free category averages.
B31: • | C31: 2025 and 2026 CPI values are provisional. BLS did not publish an October 2025 index, so any 2025 annual average is non-standard; see the CPI Deflator tab for the sensitivity.
B32: • | C32: Subscriber and ARPU figures are reported values only, with the scope of each recorded. They feed no calculation in this workbook.
B33: • | C33: Nothing here measures churn, retention, elasticity, ad ARPU or contribution margin, and no claim in this workbook depends on them.

Sheet Dashboard
B2: Dashboard
B3: Every figure on this tab is a link or a formula. Nothing here is typed.
B5: Mean CAGR, common window | C5: CPI-U, same window | D5: Mean real price change | E5: Price points tracked
B6: ='Price Analysis'!G29 -> 0.1115279 | C6: ='Price Analysis'!G31 -> 0.037122115 | D6: ='Real vs Nominal'!I14 -> 0.4813177 | E6: =COUNTA('Price History'!B6:B72) -> 67
B7: ="All prices as of "&TEXT('Price Analysis'!$C$4,"dd mmm yyyy")&". Median CAGR over the same window is "&TEXT('Price Analysis'!G30,"0.0%")&", across "&COUNTA('Price Analysis'!B7:B14)&" services." -> All prices as of 29 Jul 2026. Median CAGR over the same window is 8.7%, across 8 services.
B9: Flagship tier inflation summary
B10: Service | C10: Launch | D10: Total % chg | E10: CAGR | F10: Real % chg
B11: ='Price Analysis'!B7 -> Netflix | C11: ='Price Analysis'!D7 -> 43480 | D11: ='Price Analysis'!H7 -> 0.53887606 | E11: ='Price Analysis'!I7 -> 0.058878128 | F11: ='Real vs Nominal'!I6 -> 0.1800373
B12: ='Price Analysis'!B8 -> Disney+ | C12: ='Price Analysis'!D8 -> 43781 | D12: ='Price Analysis'!H8 -> 1.7167382 | E12: ='Price Analysis'!I8 -> 0.16059889 | F12: ='Real vs Nominal'!I7 -> 1.0832428
B13: ='Price Analysis'!B9 -> Hulu | C13: ='Price Analysis'!D9 -> 43466 | D13: ='Price Analysis'!H9 -> 0.58381985 | E13: ='Price Analysis'!I9 -> 0.062603218 | F13: ='Real vs Nominal'!I8 -> 0.21450099
B14: ='Price Analysis'!B10 -> HBO Max | C14: ='Price Analysis'!D10 -> 43978 | D14: ='Price Analysis'!H10 -> 0.23348899 | E14: ='Price Analysis'!I10 -> 0.034592875 | F14: ='Real vs Nominal'!I9 -> -0.042469947
B15: ='Price Analysis'!B11 -> Peacock | C15: ='Price Analysis'!D11 -> 44027 | D15: ='Price Analysis'!H11 -> 0.7007007 | E15: ='Price Analysis'!I11 -> 0.091959127 | F15: ='Real vs Nominal'!I10 -> 0.3202161
B16: ='Price Analysis'!B12 -> Paramount+ | C16: ='Price Analysis'!D12 -> 44259 | D16: ='Price Analysis'!H12 -> 0.4004004 | E16: ='Price Analysis'!I12 -> 0.064311233 | F16: ='Real vs Nominal'!I11 -> 0.13817186
B17: ='Price Analysis'!B13 -> Apple TV | C17: ='Price Analysis'!D13 -> 43770 | D17: ='Price Analysis'!H13 -> 1.6032064 | E17: ='Price Analysis'!I13 -> 0.15250489 | F17: ='Real vs Nominal'!I12 -> 0.99618459
B18: ='Price Analysis'!B14 -> ESPN Select | C18: ='Price Analysis'!D14 -> 43202 | D18: ='Price Analysis'!H14 -> 1.6032064 | E18: ='Price Analysis'!I14 -> 0.12223418 | F18: ='Real vs Nominal'!I13 -> 0.96065793
B20: What the panel shows
B21: 1. | C21: Flagship prices rose at roughly three times CPI over the common 2022–2026 window, and about half the increase survives deflation.
B23: 2. | C23: The growth is concentrated. Three of the eight services account for almost all of the real increase; two are flat or negative in real terms.
B25: 3. | C25: The ad tier has risen slightly faster than the ad-free tier since end-2022, and the implied discount has held flat near 36%.
B27: 4. | C27: Bundles discount roughly a third to two thirds against standalone pricing, so list price is a weak proxy for realized revenue.
B29: 5. | C29: Services that launched cheapest have compounded fastest. That is descriptive across eight observations; no convergence test is performed.
B31: Not tested | C31: Whether ad tiers or bundles protect retention. This panel cannot show it, and churn, cohort and ad-ARPU data would be the next input.
B34: Automation (VBA)
B35: RunDataAudit | C35: Checks all 67 price points and writes a timestamped Audit Log sheet: missing source URLs, Medium-confidence rows, bad dates, duplicate service/tier/date rows, formula errors on any sheet, and any tier whose current price is over 24 months old.
B37: AddPriceChange | C37: Adds a price point in sort order inside the existing data block, so the absolute ranges the Panel depends on expand with it, then rebuilds the Event type column and offers to move the as-of date.
B39: RebuildEventTypes | C39: Re-flags each tier's first observed price as Baseline and the rest as Change. The cadence counts read this column.
B41: SetAsOfDate | C41: Moves the single as-of date cell, forces a full rebuild and reports the refreshed headline figures.
B43: Alt+F8 to run. Modules mPriceModel and mAudit; source is readable in the VBA editor (Alt+F11).

Sheet Price History
B2: Price History — U.S. Monthly List Prices
B3: One row per service, tier and effective date. Dates are true date values and drive every calculation downstream. Blue text marks a sourced hardcoded input. Event type separates a tier's first observed price (Baseline) from a subsequent change.
B5: Service | C5: Tier | D5: Effective date | E5: Price $/mo | F5: Event type | G5: Source | H5: URL | I5: Published | J5: Confidence
B6: Apple TV | C6: Standard (no ads) | D6: 43770 | E6: 4.99 | F6: Baseline | G6: Launch price (company) | H6: https://variety.com/2023/digital/news/apple-tv-plus-increases-monthly-price-1235768060/ | I6: 25 Oct 2023 | J6: High
B7: Apple TV | C7: Standard (no ads) | D7: 44858 | E7: 6.99 | F7: Change | G7: Oct 2022 increase (company) | H7: https://variety.com/2023/digital/news/apple-tv-plus-increases-monthly-price-1235768060/ | I7: 25 Oct 2023 | J7: High
B8: Apple TV | C8: Standard (no ads) | D8: 45224 | E8: 9.99 | F8: Change | G8: Oct 2023 increase (company) | H8: https://www.cnbc.com/2023/10/25/apple-raises-price-of-apple-tv-to-9point99-a-month.html | I8: 25 Oct 2023 | J8: High
B9: Apple TV | C9: Standard (no ads) | D9: 45890 | E9: 12.99 | F9: Change | G9: Aug 2025 increase, +30% (eMarketer; trade press) | H9: https://www.macrumors.com/2025/08/21/apple-tv-plus-price-increase-announced/ | I9: 21 Aug 2025 | J9: High
B10: Disney+ | C10: Basic w/ ads | D10: 44903 | E10: 7.99 | F10: Baseline | G10: Ad tier launch (TechCrunch) | H10: https://variety.com/2022/digital/news/disney-plus-ads-launch-price-increase-hulu-1235338148/ | I10: 10 Aug 2022 | J10: High
B11: Disney+ | C11: Basic w/ ads | D11: 45582 | E11: 9.99 | F11: Change | G11: Oct 2024 increase (TechCrunch) | H11: https://variety.com/2023/digital/news/disney-plus-price-increase-hulu-espn-plus-1235692057/ | I11: 9 Aug 2023 | J11: High
B12: Disney+ | C12: Basic w/ ads | D12: 45951 | E12: 11.99 | F12: Change | G12: Oct 2025 increase, +$2 (Variety; TechCrunch) | H12: https://variety.com/2025/digital/news/disney-plus-hulu-price-increases-october-2025-1236527241/ | I12: 23 Sep 2025 | J12: High
B13: Disney+ | C13: Premium (no ads) | D13: 43781 | E13: 6.99 | F13: Baseline | G13: US launch price (company announcement) | H13: https://variety.com/2023/digital/news/disney-plus-price-increase-hulu-espn-plus-1235692057/ | I13: 9 Aug 2023 | J13: High
B14: Disney+ | C14: Premium (no ads) | D14: 44281 | E14: 7.99 | F14: Change | G14: First increase, Mar 2021 (company) | H14: https://www.tvline.com/news/disney-plus-with-ads-price-launch-date-hulu-cost-increase-1234860250/ | I14: 10 Aug 2022 | J14: High
B15: Disney+ | C15: Premium (no ads) | D15: 44903 | E15: 10.99 | F15: Change | G15: Ad tier launch; Premium repriced (TechCrunch) | H15: https://variety.com/2022/digital/news/disney-plus-ads-launch-price-increase-hulu-1235338148/ | I15: 10 Aug 2022 | J15: High
B16: Disney+ | C16: Premium (no ads) | D16: 45211 | E16: 13.99 | F16: Change | G16: Oct 2023 increase (CNBC/NBC News) | H16: https://www.nbcnews.com/business/business-news/disney-raise-monthly-price-ad-free-disney-1399-rcna99126 | I16: 3 Aug 2023 | J16: High
B17: Disney+ | C17: Premium (no ads) | D17: 45582 | E17: 15.99 | F17: Change | G17: Oct 2024 increase (TechCrunch) | H17: https://techcrunch.com/2025/09/23/disney-is-raising-the-price-of-disney-hulu-subscriptions-next-month/ | I17: 23 Sep 2025 | J17: High
... B72: Peacock | C72: Select w/ ads | D72: 45861 | E72: 7.99 | F72: Baseline | G72: New low tier introduced (Variety) | H72: https://www.aol.com/entertainment/nbcuniversal-peacock-hiking-prices-3-182638817.html | I72: 17 Jul 2025 | J72: High
B74: ="Records: "&COUNTA(B6:B72)&" · Services: "&SUMPRODUCT((COUNTIF(B6:B72,B6:B72)>0)/COUNTIF(B6:B72,B6:B72))&" · As-of date: "&TEXT('Price Analysis'!$C$4,"dd mmm yyyy") -> Records: 67 · Services: 8 · As-of date: 29 Jul 2026
B75: Every row carries a live source link. Confidence: High means the change is confirmed in a dated company announcement or a contemporaneous trade-press report covering that specific change. Medium means the date or amount was corroborated from a later report or a price-history aggregator rather than reporting published at the time; those rows are all intermediate steps, never an endpoint used in the analysis.

Sheet Panel
B2: Panel — Year-End Price by Tier
B3: Every cell is the last documented price on or before 31 December of that year (or the as-of date for 2026), looked up from Price History by formula. Blank means the tier did not exist yet. This is the single source for every category average in the workbook.
B5: Service | C5: Tier | D5: Tier type | E5: 2019 | F5: 2020 | G5: 2021 | H5: 2022 | I5: 2023 | J5: 2024 | K5: 2025 | L5: 2026
B6: Netflix | C6: Standard (no ads) | D6: Ad-free | E6: =IF(SUMPRODUCT(MAX(('Price History'!$B$6:$B$72=$B6)*('Price History'!$C$6:$C$72=$C6)*('Price History'!$D$6:$D$72<=MIN(DATE(2019,12,31),'Price Analysis'!$C$4))*ROW('Price History'!$E$6:$E$72)))=0,"",INDEX('Price History'!$E$6:$E$72,SUMPRODUCT(MAX(('Price History'!$B$6:$B$72=$B6)*('Price History'!$C$6:$C$72=$C6)*('Price History'!$D$6:$D$72<=MIN(DATE(2019,12,31),'Price Analysis'!$C$4))*ROW('Price History'!$E$6:$E$72)))-5)) -> 12.99 | F6: =IF(SUMPRODUCT(MAX(('Price History'!$B$6:$B$72=$B6)*('Price History'!$C$6:$C$72=$C6)*('Price History'!$D$6:$D$72<=MIN(DATE(2020,12,31),'Price Analysis'!$C$4))*ROW('Price History'!$E$6:$E$72)))=0,"",INDEX('Price History'!$E$6:$E$72,SUMPRODUCT(MAX(('Price History'!$B$6:$B$72=$B6)*('Price History'!$C$6:$C$72=$C6)*('Price History'!$D$6:$D$72<=MIN(DATE(2020,12,31),'Price Analysis'!$C$4))*ROW('Price History'!$E$6:$E$72)))-5)) -> 13.99 | G6: =IF(SUMPRODUCT(MAX(('Price History'!$B$6:$B$72=$B6)*('Price History'!$C$6:$C$72=$C6)*('Price History'!$D$6:$D$72<=MIN(DATE(2021,12,31),'Price Analysis'!$C$4))*ROW('Price History'!$E$6:$E$72)))=0,"",INDEX('Price History'!$E$6:$E$72,SUMPRODUCT(MAX(('Price History'!$B$6:$B$72=$B6)*('Price History'!$C$6:$C$72=$C6)*('Price History'!$D$6:$D$72<=MIN(DATE(2021,12,31),'Price Analysis'!$C$4))*ROW('Price History'!$E$6:$E$72)))-5)) -> 13.99 | H6: =IF(SUMPRODUCT(MAX(('Price History'!$B$6:$B$72=$B6)*('Price History'!$C$6:$C$72=$C6)*('Price History'!$D$6:$D$72<=MIN(DATE(2022,12,31),'Price Analysis'!$C$4))*ROW('Price History'!$E$6:$E$72)))=0,"",INDEX('Price History'!$E$6:$E$72,SUMPRODUCT(MAX(('Price History'!$B$6:$B$72=$B6)*('Price History'!$C$6:$C$72=$C6)*('Price History'!$D$6:$D$72<=MIN(DATE(2022,12,31),'Price Analysis'!$C$4))*ROW('Price History'!$E$6:$E$72)))-5)) -> 15.49 | I6: =IF(SUMPRODUCT(MAX(('Price History'!$B$6:$B$72=$B6)*('Price History'!$C$6:$C$72=$C6)*('Price History'!$D$6:$D$72<=MIN(DATE(2023,12,31),'Price Analysis'!$C$4))*ROW('Price History'!$E$6:$E$72)))=0,"",INDEX('Price History'!$E$6:$E$72,SUMPRODUCT(MAX(('Price History'!$B$6:$B$72=$B6)*('Price History'!$C$6:$C$72=$C6)*('Price History'!$D$6:$D$72<=MIN(DATE(2023,12,31),'Price Analysis'!$C$4))*ROW('Price History'!$E$6:$E$72)))-5)) -> 15.49 | J6: =IF(SUMPRODUCT(MAX(('Price History'!$B$6:$B$72=$B6)*('Price History'!$C$6:$C$72=$C6)*('Price History'!$D$6:$D$72<=MIN(DATE(2024,12,31),'Price Analysis'!$C$4))*ROW('Price History'!$E$6:$E$72)))=0,"",INDEX('Price History'!$E$6:$E$72,SUMPRODUCT(MAX(('Price History'!$B$6:$B$72=$B6)*('Price History'!$C$6:$C$72=$C6)*('Price History'!$D$6:$D$72<=MIN(DATE(2024,12,31),'Price Analysis'!$C$4))*ROW('Price History'!$E$6:$E$72)))-5)) -> 15.49 | K6: =IF(SUMPRODUCT(MAX(('Price History'!$B$6:$B$72=$B6)*('Price History'!$C$6:$C$72=$C6)*('Price History'!$D$6:$D$72<=MIN(DATE(2025,12,31),'Price Analysis'!$C$4))*ROW('Price History'!$E$6:$E$72)))=0,"",INDEX('Price History'!$E$6:$E$72,SUMPRODUCT(MAX(('Price History'!$B$6:$B$72=$B6)*('Price History'!$C$6:$C$72=$C6)*('Price History'!$D$6:$D$72<=MIN(DATE(2025,12,31),'Price Analysis'!$C$4))*ROW('Price History'!$E$6:$E$72)))-5)) -> 17.99 | L6: =IF(SUMPRODUCT(MAX(('Price History'!$B$6:$B$72=$B6)*('Price History'!$C$6:$C$72=$C6)*('Price History'!$D$6:$D$72<=MIN(DATE(2026,12,31),'Price Analysis'!$C$4))*ROW('Price History'!$E$6:$E$72)))=0,"",INDEX('Price History'!$E$6:$E$72,SUMPRODUCT(MAX(('Price History'!$B$6:$B$72=$B6)*('Price History'!$C$6:$C$72=$C6)*('Price History'!$D$6:$D$72<=MIN(DATE(2026,12,31),'Price Analysis'!$C$4))*ROW('Price History'!$E$6:$E$72)))-5)) -> 19.99
B7: Disney+ | C7: Premium (no ads) | D7: Ad-free | E7: =IF(SUMPRODUCT(MAX(('Price History'!$B$6:$B$72=$B7)*('Price History'!$C$6:$C$72=$C7)*('Price History'!$D$6:$D$72<=MIN(DATE(2019,12,31),'Price Analysis'!$C$4))*ROW('Price History'!$E$6:$E$72)))=0,"",INDEX('Price History'!$E$6:$E$72,SUMPRODUCT(MAX(('Price History'!$B$6:$B$72=$B7)*('Price History'!$C$6:$C$72=$C7)*('Price History'!$D$6:$D$72<=MIN(DATE(2019,12,31),'Price Analysis'!$C$4))*ROW('Price History'!$E$6:$E$72)))-5)) -> 6.99 | F7: =IF(SUMPRODUCT(MAX(('Price History'!$B$6:$B$72=$B7)*('Price History'!$C$6:$C$72=$C7)*('Price History'!$D$6:$D$72<=MIN(DATE(2020,12,31),'Price Analysis'!$C$4))*ROW('Price History'!$E$6:$E$72)))=0,"",INDEX('Price History'!$E$6:$E$72,SUMPRODUCT(MAX(('Price History'!$B$6:$B$72=$B7)*('Price History'!$C$6:$C$72=$C7)*('Price History'!$D$6:$D$72<=MIN(DATE(2020,12,31),'Price Analysis'!$C$4))*ROW('Price History'!$E$6:$E$72)))-5)) -> 6.99 | G7: =IF(SUMPRODUCT(MAX(('Price History'!$B$6:$B$72=$B7)*('Price History'!$C$6:$C$72=$C7)*('Price History'!$D$6:$D$72<=MIN(DATE(2021,12,31),'Price Analysis'!$C$4))*ROW('Price History'!$E$6:$E$72)))=0,"",INDEX('Price History'!$E$6:$E$72,SUMPRODUCT(MAX(('Price History'!$B$6:$B$72=$B7)*('Price History'!$C$6:$C$72=$C7)*('Price History'!$D$6:$D$72<=MIN(DATE(2021,12,31),'Price Analysis'!$C$4))*ROW('Price History'!$E$6:$E$72)))-5)) -> 7.99 | H7: =IF(SUMPRODUCT(MAX(('Price History'!$B$6:$B$72=$B7)*('Price History'!$C$6:$C$72=$C7)*('Price History'!$D$6:$D$72<=MIN(DATE(2022,12,31),'Price Analysis'!$C$4))*ROW('Price History'!$E$6:$E$72)))=0,"",INDEX('Price History'!$E$6:$E$72,SUMPRODUCT(MAX(('Price History'!$B$6:$B$72=$B7)*('Price History'!$C$6:$C$72=$C7)*('Price History'!$D$6:$D$72<=MIN(DATE(2022,12,31),'Price Analysis'!$C$4))*ROW('Price History'!$E$6:$E$72)))-5)) -> 10.99 | I7: =IF(SUMPRODUCT(MAX(('Price History'!$B$6:$B$72=$B7)*('Price History'!$C$6:$C$72=$C7)*('Price History'!$D$6:$D$72<=MIN(DATE(2023,12,31),'Price Analysis'!$C$4))*ROW('Price History'!$E$6:$E$72)))=0,"",INDEX('Price History'!$E$6:$E$72,SUMPRODUCT(MAX(('Price History'!$B$6:$B$72=$B7)*('Price History'!$C$6:$C$72=$C7)*('Price History'!$D$6:$D$72<=MIN(DATE(2023,12,31),'Price Analysis'!$C$4))*ROW('Price History'!$E$6:$E$72)))-5)) -> 13.99 | J7: =IF(SUMPRODUCT(MAX(('Price History'!$B$6:$B$72=$B7)*('Price History'!$C$6:$C$72=$C7)*('Price History'!$D$6:$D$72<=MIN(DATE(2024,12,31),'Price Analysis'!$C$4))*ROW('Price History'!$E$6:$E$72)))=0,"",INDEX('Price History'!$E$6:$E$72,SUMPRODUCT(MAX(('Price History'!$B$6:$B$72=$B7)*('Price History'!$C$6:$C$72=$C7)*('Price History'!$D$6:$D$72<=MIN(DATE(2024,12,31),'Price Analysis'!$C$4))*ROW('Price History'!$E$6:$E$72)))-5)) -> 15.99 | K7: =IF(SUMPRODUCT(MAX(('Price History'!$B$6:$B$72=$B7)*('Price History'!$C$6:$C$72=$C7)*('Price History'!$D$6:$D$72<=MIN(DATE(2025,12,31),'Price Analysis'!$C$4))*ROW('Price History'!$E$6:$E$72)))=0,"",INDEX('Price History'!$E$6:$E$72,SUMPRODUCT(MAX(('Price History'!$B$6:$B$72=$B7)*('Price History'!$C$6:$C$72=$C7)*('Price History'!$D$6:$D$72<=MIN(DATE(2025,12,31),'Price Analysis'!$C$4))*ROW('Price History'!$E$6:$E$72)))-5)) -> 18.99 | L7: =IF(SUMPRODUCT(MAX(('Price History'!$B$6:$B$72=$B7)*('Price History'!$C$6:$C$72=$C7)*('Price History'!$D$6:$D$72<=MIN(DATE(2026,12,31),'Price Analysis'!$C$4))*ROW('Price History'!$E$6:$E$72)))=0,"",INDEX('Price History'!$E$6:$E$72,SUMPRODUCT(MAX(('Price History'!$B$6:$B$72=$B7)*('Price History'!$C$6:$C$72=$C7)*('Price History'!$D$6:$D$72<=MIN(DATE(2026,12,31),'Price Analysis'!$C$4))*ROW('Price History'!$E$6:$E$72)))-5)) -> 18.99
B8: Hulu | C8: No ads | D8: Ad-free | E8: =IF(SUMPRODUCT(MAX(('Price History'!$B$6:$B$72=$B8)*('Price History'!$C$6:$C$72=$C8)*('Price History'!$D$6:$D$72<=MIN(DATE(2019,12,31),'Price Analysis'!$C$4))*ROW('Price History'!$E$6:$E$72)))=0,"",INDEX('Price History'!$E$6:$E$72,SUMPRODUCT(MAX(('Price History'!$B$6:$B$72=$B8)*('Price History'!$C$6:$C$72=$C8)*('Price History'!$D$6:$D$72<=MIN(DATE(2019,12,31),'Price Analysis'!$C$4))*ROW('Price History'!$E$6:$E$72)))-5)) -> 11.99 | F8: =IF(SUMPRODUCT(MAX(('Price History'!$B$6:$B$72=$B8)*('Price History'!$C$6:$C$72=$C8)*('Price History'!$D$6:$D$72<=MIN(DATE(2020,12,31),'Price Analysis'!$C$4))*ROW('Price History'!$E$6:$E$72)))=0,"",INDEX('Price History'!$E$6:$E$72,SUMPRODUCT(MAX(('Price History'!$B$6:$B$72=$B8)*('Price History'!$C$6:$C$72=$C8)*('Price History'!$D$6:$D$72<=MIN(DATE(2020,12,31),'Price Analysis'!$C$4))*ROW('Price History'!$E$6:$E$72)))-5)) -> 11.99 | G8: =IF(SUMPRODUCT(MAX(('Price History'!$B$6:$B$72=$B8)*('Price History'!$C$6:$C$72=$C8)*('Price History'!$D$6:$D$72<=MIN(DATE(2021,12,31),'Price Analysis'!$C$4))*ROW('Price History'!$E$6:$E$72)))=0,"",INDEX('Price History'!$E$6:$E$72,SUMPRODUCT(MAX(('Price History'!$B$6:$B$72=$B8)*('Price History'!$C$6:$C$72=$C8)*('Price History'!$D$6:$D$72<=MIN(DATE(2021,12,31),'Price Analysis'!$C$4))*ROW('Price History'!$E$6:$E$72)))-5)) -> 11.99 | H8: =IF(SUMPRODUCT(MAX(('Price History'!$B$6:$B$72=$B8)*('Price History'!$C$6:$C$72=$C8)*('Price History'!$D$6:$D$72<=MIN(DATE(2022,12,31),'Price Analysis'!$C$4))*ROW('Price History'!$E$6:$E$72)))=0,"",INDEX('Price History'!$E$6:$E$72,SUMPRODUCT(MAX(('Price History'!$B$6:$B$72=$B8)*('Price History'!$C$6:$C$72=$C8)*('Price History'!$D$6:$D$72<=MIN(DATE(2022,12,31),'Price Analysis'!$C$4))*ROW('Price History'!$E$6:$E$72)))-5)) -> 14.99 | I8: =IF(SUMPRODUCT(MAX(('Price History'!$B$6:$B$72=$B8)*('Price History'!$C$6:$C$72=$C8)*('Price History'!$D$6:$D$72<=MIN(DATE(2023,12,31),'Price Analysis'!$C$4))*ROW('Price History'!$E$6:$E$72)))=0,"",INDEX('Price History'!$E$6:$E$72,SUMPRODUCT(MAX(('Price History'!$B$6:$B$72=$B8)*('Price History'!$C$6:$C$72=$C8)*('Price History'!$D$6:$D$72<=MIN(DATE(2023,12,31),'Price Analysis'!$C$4))*ROW('Price History'!$E$6:$E$72)))-5)) -> 17.99 | J8: =IF(SUMPRODUCT(MAX(('Price History'!$B$6:$B$72=$B8)*('Price History'!$C$6:$C$72=$C8)*('Price History'!$D$6:$D$72<=MIN(DATE(2024,12,31),'Price Analysis'!$C$4))*ROW('Price History'!$E$6:$E$72)))=0,"",INDEX('Price History'!$E$6:$E$72,SUMPRODUCT(MAX(('Price History'!$B$6:$B$72=$B8)*('Price History'!$C$6:$C$72=$C8)*('Price History'!$D$6:$D$72<=MIN(DATE(2024,12,31),'Price Analysis'!$C$4))*ROW('Price History'!$E$6:$E$72)))-5)) -> 18.99 | K8: =IF(SUMPRODUCT(MAX(('Price History'!$B$6:$B$72=$B8)*('Price History'!$C$6:$C$72=$C8)*('Price History'!$D$6:$D$72<=MIN(DATE(2025,12,31),'Price Analysis'!$C$4))*ROW('Price History'!$E$6:$E$72)))=0,"",INDEX('Price History'!$E$6:$E$72,SUMPRODUCT(MAX(('Price History'!$B$6:$B$72=$B8)*('Price History'!$C$6:$C$72=$C8)*('Price History'!$D$6:$D$72<=MIN(DATE(2025,12,31),'Price Analysis'!$C$4))*ROW('Price History'!$E$6:$E$72)))-5)) -> 18.99 | L8: =IF(SUMPRODUCT(MAX(('Price History'!$B$6:$B$72=$B8)*('Price History'!$C$6:$C$72=$C8)*('Price History'!$D$6:$D$72<=MIN(DATE(2026,12,31),'Price Analysis'!$C$4))*ROW('Price History'!$E$6:$E$72)))=0,"",INDEX('Price History'!$E$6:$E$72,SUMPRODUCT(MAX(('Price History'!$B$6:$B$72=$B8)*('Price History'!$C$6:$C$72=$C8)*('Price History'!$D$6:$D$72<=MIN(DATE(2026,12,31),'Price Analysis'!$C$4))*ROW('Price History'!$E$6:$E$72)))-5)) -> 18.99
B9: HBO Max | C9: Standard (no ads) | D9: Ad-free | E9: =IF(SUMPRODUCT(MAX(('Price History'!$B$6:$B$72=$B9)*('Price History'!$C$6:$C$72=$C9)*('Price History'!$D$6:$D$72<=MIN(DATE(2019,12,31),'Price Analysis'!$C$4))*ROW('Price History'!$E$6:$E$72)))=0,"",INDEX('Price History'!$E$6:$E$72,SUMPRODUCT(MAX(('Price History'!$B$6:$B$72=$B9)*('Price History'!$C$6:$C$72=$C9)*('Price History'!$D$6:$D$72<=MIN(DATE(2019,12,31),'Price Analysis'!$C$4))*ROW('Price History'!$E$6:$E$72)))-5)) | F9: =IF(SUMPRODUCT(MAX(('Price History'!$B$6:$B$72=$B9)*('Price History'!$C$6:$C$72=$C9)*('Price History'!$D$6:$D$72<=MIN(DATE(2020,12,31),'Price Analysis'!$C$4))*ROW('Price History'!$E$6:$E$72)))=0,"",INDEX('Price History'!$E$6:$E$72,SUMPRODUCT(MAX(('Price History'!$B$6:$B$72=$B9)*('Price History'!$C$6:$C$72=$C9)*('Price History'!$D$6:$D$72<=MIN(DATE(2020,12,31),'Price Analysis'!$C$4))*ROW('Price History'!$E$6:$E$72)))-5)) -> 14.99 | G9: =IF(SUMPRODUCT(MAX(('Price History'!$B$6:$B$72=$B9)*('Price History'!$C$6:$C$72=$C9)*('Price History'!$D$6:$D$72<=MIN(DATE(2021,12,31),'Price Analysis'!$C$4))*ROW('Price History'!$E$6:$E$72)))=0,"",INDEX('Price History'!$E$6:$E$72,SUMPRODUCT(MAX(('Price History'!$B$6:$B$72=$B9)*('Price History'!$C$6:$C$72=$C9)*('Price History'!$D$6:$D$72<=MIN(DATE(2021,12,31),'Price Analysis'!$C$4))*ROW('Price History'!$E$6:$E$72)))-5)) -> 14.99 | H9: =IF(SUMPRODUCT(MAX(('Price History'!$B$6:$B$72=$B9)*('Price History'!$C$6:$C$72=$C9)*('Price History'!$D$6:$D$72<=MIN(DATE(2022,12,31),'Price Analysis'!$C$4))*ROW('Price History'!$E$6:$E$72)))=0,"",INDEX('Price History'!$E$6:$E$72,SUMPRODUCT(MAX(('Price History'!$B$6:$B$72=$B9)*('Price History'!$C$6:$C$72=$C9)*('Price History'!$D$6:$D$72<=MIN(DATE(2022,12,31),'Price Analysis'!$C$4))*ROW('Price History'!$E$6:$E$72)))-5)) -> 14.99 | I9: =IF(SUMPRODUCT(MAX(('Price History'!$B$6:$B$72=$B9)*('Price History'!$C$6:$C$72=$C9)*('Price History'!$D$6:$D$72<=MIN(DATE(2023,12,31),'Price Analysis'!$C$4))*ROW('Price History'!$E$6:$E$72)))=0,"",INDEX('Price History'!$E$6:$E$72,SUMPRODUCT(MAX(('Price History'!$B$6:$B$72=$B9)*('Price History'!$C$6:$C$72=$C9)*('Price History'!$D$6:$D$72<=MIN(DATE(2023,12,31),'Price Analysis'!$C$4))*ROW('Price History'!$E$6:$E$72)))-5)) -> 15.99 | J9: =IF(SUMPRODUCT(MAX(('Price History'!$B$6:$B$72=$B9)*('Price History'!$C$6:$C$72=$C9)*('Price History'!$D$6:$D$72<=MIN(DATE(2024,12,31),'Price Analysis'!$C$4))*ROW('Price History'!$E$6:$E$72)))=0,"",INDEX('Price History'!$E$6:$E$72,SUMPRODUCT(MAX(('Price History'!$B$6:$B$72=$B9)*('Price History'!$C$6:$C$72=$C9)*('Price History'!$D$6:$D$72<=MIN(DATE(2024,12,31),'Price Analysis'!$C$4))*ROW('Price History'!$E$6:$E$72)))-5)) -> 16.99 | K9: =IF(SUMPRODUCT(MAX(('Price History'!$B$6:$B$72=$B9)*('Price History'!$C$6:$C$72=$C9)*('Price History'!$D$6:$D$72<=MIN(DATE(2025,12,31),'Price Analysis'!$C$4))*ROW('Price History'!$E$6:$E$72)))=0,"",INDEX('Price History'!$E$6:$E$72,SUMPRODUCT(MAX(('Price History'!$B$6:$B$72=$B9)*('Price History'!$C$6:$C$72=$C9)*('Price History'!$D$6:$D$72<=MIN(DATE(2025,12,31),'Price Analysis'!$C$4))*ROW('Price History'!$E$6:$E$72)))-5)) -> 18.49 | L9: =IF(SUMPRODUCT(MAX(('Price History'!$B$6:$B$72=$B9)*('Price History'!$C$6:$C$72=$C9)*('Price History'!$D$6:$D$72<=MIN(DATE(2026,12,31),'Price Analysis'!$C$4))*ROW('Price History'!$E$6:$E$72)))=0,"",INDEX('Price History'!$E$6:$E$72,SUMPRODUCT(MAX(('Price History'!$B$6:$B$72=$B9)*('Price History'!$C$6:$C$72=$C9)*('Price History'!$D$6:$D$72<=MIN(DATE(2026,12,31),'Price Analysis'!$C$4))*ROW('Price History'!$E$6:$E$72)))-5)) -> 18.49
B10: Peacock | C10: Premium Plus (no ads) | D10: Ad-free | E10: =IF(SUMPRODUCT(MAX(('Price History'!$B$6:$B$72=$B10)*('Price History'!$C$6:$C$72=$C10)*('Price History'!$D$6:$D$72<=MIN(DATE(2019,12,31),'Price Analysis'!$C$4))*ROW('Price History'!$E$6:$E$72)))=0,"",INDEX('Price History'!$E$6:$E$72,SUMPRODUCT(MAX(('Price History'!$B$6:$B$72=$B10)*('Price History'!$C$6:$C$72=$C10)*('Price History'!$D$6:$D$72<=MIN(DATE(2019,12,31),'Price Analysis'!$C$4))*ROW('Price History'!$E$6:$E$72)))-5)) | F10: =IF(SUMPRODUCT(MAX(('Price History'!$B$6:$B$72=$B10)*('Price History'!$C$6:$C$72=$C10)*('Price History'!$D$6:$D$72<=MIN(DATE(2020,12,31),'Price Analysis'!$C$4))*ROW('Price History'!$E$6:$E$72)))=0,"",INDEX('Price History'!$E$6:$E$72,SUMPRODUCT(MAX(('Price History'!$B$6:$B$72=$B10)*('Price History'!$C$6:$C$72=$C10)*('Price History'!$D$6:$D$72<=MIN(DATE(2020,12,31),'Price Analysis'!$C$4))*ROW('Price History'!$E$6:$E$72)))-5)) -> 9.99 | G10: =IF(SUMPRODUCT(MAX(('Price History'!$B$6:$B$72=$B10)*('Price History'!$C$6:$C$72=$C10)*('Price History'!$D$6:$D$72<=MIN(DATE(2021,12,31),'Price Analysis'!$C$4))*ROW('Price History'!$E$6:$E$72)))=0,"",INDEX('Price History'!$E$6:$E$72,SUMPRODUCT(MAX(('Price History'!$B$6:$B$72=$B10)*('Price History'!$C$6:$C$72=$C10)*('Price History'!$D$6:$D$72<=MIN(DATE(2021,12,31),'Price Analysis'!$C$4))*ROW('Price History'!$E$6:$E$72)))-5)) -> 9.99 | H10: =IF(SUMPRODUCT(MAX(('Price History'!$B$6:$B$72=$B10)*('Price History'!$C$6:$C$72=$C10)*('Price History'!$D$6:$D$72<=MIN(DATE(2022,12,31),'Price Analysis'!$C$4))*ROW('Price History'!$E$6:$E$72)))=0,"",INDEX('Price History'!$E$6:$E$72,SUMPRODUCT(MAX(('Price History'!$B$6:$B$72=$B10)*('Price History'!$C$6:$C$72=$C10)*('Price History'!$D$6:$D$72<=MIN(DATE(2022,12,31),'Price Analysis'!$C$4))*ROW('Price History'!$E$6:$E$72)))-5)) -> 9.99 | I10: =IF(SUMPRODUCT(MAX(('Price History'!$B$6:$B$72=$B10)*('Price History'!$C$6:$C$72=$C10)*('Price History'!$D$6:$D$72<=MIN(DATE(2023,12,31),'Price Analysis'!$C$4))*ROW('Price History'!$E$6:$E$72)))=0,"",INDEX('Price History'!$E$6:$E$72,SUMPRODUCT(MAX(('Price History'!$B$6:$B$72=$B10)*('Price History'!$C$6:$C$72=$C10)*('Price History'!$D$6:$D$72<=MIN(DATE(2023,12,31),'Price Analysis'!$C$4))*ROW('Price History'!$E$6:$E$72)))-5)) -> 11.99 | J10: =IF(SUMPRODUCT(MAX(('Price History'!$B$6:$B$72=$B10)*('Price History'!$C$6:$C$72=$C10)*('Price History'!$D$6:$D$72<=MIN(DATE(2024,12,31),'Price Analysis'!$C$4))*ROW('Price History'!$E$6:$E$72)))=0,"",INDEX('Price History'!$E$6:$E$72,SUMPRODUCT(MAX(('Price History'!$B$6:$B$72=$B10)*('Price History'!$C$6:$C$72=$C10)*('Price History'!$D$6:$D$72<=MIN(DATE(2024,12,31),'Price Analysis'!$C$4))*ROW('Price History'!$E$6:$E$72)))-5)) -> 13.99 | K10: =IF(SUMPRODUCT(MAX(('Price History'!$B$6:$B$72=$B10)*('Price History'!$C$6:$C$72=$C10)*('Price History'!$D$6:$D$72<=MIN(DATE(2025,12,31),'Price Analysis'!$C$4))*ROW('Price History'!$E$6:$E$72)))=0,"",INDEX('Price History'!$E$6:$E$72,SUMPRODUCT(MAX(('Price History'!$B$6:$B$72=$B10)*('Price History'!$C$6:$C$72=$C10)*('Price History'!$D$6:$D$72<=MIN(DATE(2025,12,31),'Price Analysis'!$C$4))*ROW('Price History'!$E$6:$E$72)))-5)) -> 16.99 | L10: =IF(SUMPRODUCT(MAX(('Price History'!$B$6:$B$72=$B10)*('Price History'!$C$6:$C$72=$C10)*('Price History'!$D$6:$D$72<=MIN(DATE(2026,12,31),'Price Analysis'!$C$4))*ROW('Price History'!$E$6:$E$72)))=0,"",INDEX('Price History'!$E$6:$E$72,SUMPRODUCT(MAX(('Price History'!$B$6:$B$72=$B10)*('Price History'!$C$6:$C$72=$C10)*('Price History'!$D$6:$D$72<=MIN(DATE(2026,12,31),'Price Analysis'!$C$4))*ROW('Price History'!$E$6:$E$72)))-5)) -> 16.99
B11: Paramount+ | C11: Premium (no ads) | D11: Ad-free | E11: =IF(SUMPRODUCT(MAX(('Price History'!$B$6:$B$72=$B11)*('Price History'!$C$6:$C$72=$C11)*('Price History'!$D$6:$D$72<=MIN(DATE(2019,12,31),'Price Analysis'!$C$4))*ROW('Price History'!$E$6:$E$72)))=0,"",INDEX('Price History'!$E$6:$E$72,SUMPRODUCT(MAX(('Price History'!$B$6:$B$72=$B11)*('Price History'!$C$6:$C$72=$C11)*('Price History'!$D$6:$D$72<=MIN(DATE(2019,12,31),'Price Analysis'!$C$4))*ROW('Price History'!$E$6:$E$72)))-5)) | F11: =IF(SUMPRODUCT(MAX(('Price History'!$B$6:$B$72=$B11)*('Price History'!$C$6:$C$72=$C11)*('Price History'!$D$6:$D$72<=MIN(DATE(2020,12,31),'Price Analysis'!$C$4))*ROW('Price History'!$E$6:$E$72)))=0,"",INDEX('Price History'!$E$6:$E$72,SUMPRODUCT(MAX(('Price History'!$B$6:$B$72=$B11)*('Price History'!$C$6:$C$72=$C11)*('Price History'!$D$6:$D$72<=MIN(DATE(2020,12,31),'Price Analysis'!$C$4))*ROW('Price History'!$E$6:$E$72)))-5)) | G11: =IF(SUMPRODUCT(MAX(('Price History'!$B$6:$B$72=$B11)*('Price History'!$C$6:$C$72=$C11)*('Price History'!$D$6:$D$72<=MIN(DATE(2021,12,31),'Price Analysis'!$C$4))*ROW('Price History'!$E$6:$E$72)))=0,"",INDEX('Price History'!$E$6:$E$72,SUMPRODUCT(MAX(('Price History'!$B$6:$B$72=$B11)*('Price History'!$C$6:$C$72=$C11)*('Price History'!$D$6:$D$72<=MIN(DATE(2021,12,31),'Price Analysis'!$C$4))*ROW('Price History'!$E$6:$E$72)))-5)) -> 9.99 | H11: =IF(SUMPRODUCT(MAX(('Price History'!$B$6:$B$72=$B11)*('Price History'!$C$6:$C$72=$C11)*('Price History'!$D$6:$D$72<=MIN(DATE(2022,12,31),'Price Analysis'!$C$4))*ROW('Price History'!$E$6:$E$72)))=0,"",INDEX('Price History'!$E$6:$E$72,SUMPRODUCT(MAX(('Price History'!$B$6:$B$72=$B11)*('Price History'!$C$6:$C$72=$C11)*('Price History'!$D$6:$D$72<=MIN(DATE(2022,12,31),'Price Analysis'!$C$4))*ROW('Price History'!$E$6:$E$72)))-5)) -> 9.99 | I11: =IF(SUMPRODUCT(MAX(('Price History'!$B$6:$B$72=$B11)*('Price History'!$C$6:$C$72=$C11)*('Price History'!$D$6:$D$72<=MIN(DATE(2023,12,31),'Price Analysis'!$C$4))*ROW('Price History'!$E$6:$E$72)))=0,"",INDEX('Price History'!$E$6:$E$72,SUMPRODUCT(MAX(('Price History'!$B$6:$B$72=$B11)*('Price History'!$C$6:$C$72=$C11)*('Price History'!$D$6:$D$72<=MIN(DATE(2023,12,31),'Price Analysis'!$C$4))*ROW('Price History'!$E$6:$E$72)))-5)) -> 11.99 | J11: =IF(SUMPRODUCT(MAX(('Price History'!$B$6:$B$72=$B11)*('Price History'!$C$6:$C$72=$C11)*('Price History'!$D$6:$D$72<=MIN(DATE(2024,12,31),'Price Analysis'!$C$4))*ROW('Price History'!$E$6:$E$72)))=0,"",INDEX('Price History'!$E$6:$E$72,SUMPRODUCT(MAX(('Price History'!$B$6:$B$72=$B11)*('Price History'!$C$6:$C$72=$C11)*('Price History'!$D$6:$D$72<=MIN(DATE(2024,12,31),'Price Analysis'!$C$4))*ROW('Price History'!$E$6:$E$72)))-5)) -> 12.99 | K11: =IF(SUMPRODUCT(MAX(('Price History'!$B$6:$B$72=$B11)*('Price History'!$C$6:$C$72=$C11)*('Price History'!$D$6:$D$72<=MIN(DATE(2025,12,31),'Price Analysis'!$C$4))*ROW('Price History'!$E$6:$E$72)))=0,"",INDEX('Price History'!$E$6:$E$72,SUMPRODUCT(MAX(('Price History'!$B$6:$B$72=$B11)*('Price History'!$C$6:$C$72=$C11)*('Price History'!$D$6:$D$72<=MIN(DATE(2025,12,31),'Price Analysis'!$C$4))*ROW('Price History'!$E$6:$E$72)))-5)) -> 12.99 | L11: =IF(SUMPRODUCT(MAX(('Price History'!$B$6:$B$72=$B11)*('Price History'!$C$6:$C$72=$C11)*('Price History'!$D$6:$D$72<=MIN(DATE(2026,12,31),'Price Analysis'!$C$4))*ROW('Price History'!$E$6:$E$72)))=0,"",INDEX('Price History'!$E$6:$E$72,SUMPRODUCT(MAX(('Price History'!$B$6:$B$72=$B11)*('Price History'!$C$6:$C$72=$C11)*('Price History'!$D$6:$D$72<=MIN(DATE(2026,12,31),'Price Analysis'!$C$4))*ROW('Price History'!$E$6:$E$72)))-5)) -> 13.99
B12: Apple TV | C12: Standard (no ads) | D12: Ad-free | E12: =IF(SUMPRODUCT(MAX(('Price History'!$B$6:$B$72=$B12)*('Price History'!$C$6:$C$72=$C12)*('Price History'!$D$6:$D$72<=MIN(DATE(2019,12,31),'Price Analysis'!$C$4))*ROW('Price History'!$E$6:$E$72)))=0,"",INDEX('Price History'!$E$6:$E$72,SUMPRODUCT(MAX(('Price History'!$B$6:$B$72=$B12)*('Price History'!$C$6:$C$72=$C12)*('Price History'!$D$6:$D$72<=MIN(DATE(2019,12,31),'Price Analysis'!$C$4))*ROW('Price History'!$E$6:$E$72)))-5)) -> 4.99 | F12: =IF(SUMPRODUCT(MAX(('Price History'!$B$6:$B$72=$B12)*('Price History'!$C$6:$C$72=$C12)*('Price History'!$D$6:$D$72<=MIN(DATE(2020,12,31),'Price Analysis'!$C$4))*ROW('Price History'!$E$6:$E$72)))=0,"",INDEX('Price History'!$E$6:$E$72,SUMPRODUCT(MAX(('Price History'!$B$6:$B$72=$B12)*('Price History'!$C$6:$C$72=$C12)*('Price History'!$D$6:$D$72<=MIN(DATE(2020,12,31),'Price Analysis'!$C$4))*ROW('Price History'!$E$6:$E$72)))-5)) -> 4.99 | G12: =IF(SUMPRODUCT(MAX(('Price History'!$B$6:$B$72=$B12)*('Price History'!$C$6:$C$72=$C12)*('Price History'!$D$6:$D$72<=MIN(DATE(2021,12,31),'Price Analysis'!$C$4))*ROW('Price History'!$E$6:$E$72)))=0,"",INDEX('Price History'!$E$6:$E$72,SUMPRODUCT(MAX(('Price History'!$B$6:$B$72=$B12)*('Price History'!$C$6:$C$72=$C12)*('Price History'!$D$6:$D$72<=MIN(DATE(2021,12,31),'Price Analysis'!$C$4))*ROW('Price History'!$E$6:$E$72)))-5)) -> 4.99 | H12: =IF(SUMPRODUCT(MAX(('Price History'!$B$6:$B$72=$B12)*('Price History'!$C$6:$C$72=$C12)*('Price History'!$D$6:$D$72<=MIN(DATE(2022,12,31),'Price Analysis'!$C$4))*ROW('Price History'!$E$6:$E$72)))=0,"",INDEX('Price History'!$E$6:$E$72,SUMPRODUCT(MAX(('Price History'!$B$6:$B$72=$B12)*('Price History'!$C$6:$C$72=$C12)*('Price History'!$D$6:$D$72<=MIN(DATE(2022,12,31),'Price Analysis'!$C$4))*ROW('Price History'!$E$6:$E$72)))-5)) -> 6.99 | I12: =IF(SUMPRODUCT(MAX(('Price History'!$B$6:$B$72=$B12)*('Price History'!$C$6:$C$72=$C12)*('Price History'!$D$6:$D$72<=MIN(DATE(2023,12,31),'Price Analysis'!$C$4))*ROW('Price History'!$E$6:$E$72)))=0,"",INDEX('Price History'!$E$6:$E$72,SUMPRODUCT(MAX(('Price History'!$B$6:$B$72=$B12)*('Price History'!$C$6:$C$72=$C12)*('Price History'!$D$6:$D$72<=MIN(DATE(2023,12,31),'Price Analysis'!$C$4))*ROW('Price History'!$E$6:$E$72)))-5)) -> 9.99 | J12: =IF(SUMPRODUCT(MAX(('Price History'!$B$6:$B$72=$B12)*('Price History'!$C$6:$C$72=$C12)*('Price History'!$D$6:$D$72<=MIN(DATE(2024,12,31),'Price Analysis'!$C$4))*ROW('Price History'!$E$6:$E$72)))=0,"",INDEX('Price History'!$E$6:$E$72,SUMPRODUCT(MAX(('Price History'!$B$6:$B$72=$B12)*('Price History'!$C$6:$C$72=$C12)*('Price History'!$D$6:$D$72<=MIN(DATE(2024,12,31),'Price Analysis'!$C$4))*ROW('Price History'!$E$6:$E$72)))-5)) -> 9.99 | K12: =IF(SUMPRODUCT(MAX(('Price History'!$B$6:$B$72=$B12)*('Price History'!$C$6:$C$72=$C12)*('Price History'!$D$6:$D$72<=MIN(DATE(2025,12,31),'Price Analysis'!$C$4))*ROW('Price History'!$E$6:$E$72)))=0,"",INDEX('Price History'!$E$6:$E$72,SUMPRODUCT(MAX(('Price History'!$B$6:$B$72=$B12)*('Price History'!$C$6:$C$72=$C12)*('Price History'!$D$6:$D$72<=MIN(DATE(2025,12,31),'Price Analysis'!$C$4))*ROW('Price History'!$E$6:$E$72)))-5)) -> 12.99 | L12: =IF(SUMPRODUCT(MAX(('Price History'!$B$6:$B$72=$B12)*('Price History'!$C$6:$C$72=$C12)*('Price History'!$D$6:$D$72<=MIN(DATE(2026,12,31),'Price Analysis'!$C$4))*ROW('Price History'!$E$6:$E$72)))=0,"",INDEX('Price History'!$E$6:$E$72,SUMPRODUCT(MAX(('Price History'!$B$6:$B$72=$B12)*('Price History'!$C$6:$C$72=$C12)*('Price History'!$D$6:$D$72<=MIN(DATE(2026,12,31),'Price Analysis'!$C$4))*ROW('Price History'!$E$6:$E$72)))-5)) -> 12.99
B13: ESPN Select | C13: Standard w/ ads | D13: Ad-supported | E13: =IF(SUMPRODUCT(MAX(('Price History'!$B$6:$B$72=$B13)*('Price History'!$C$6:$C$72=$C13)*('Price History'!$D$6:$D$72<=MIN(DATE(2019,12,31),'Price Analysis'!$C$4))*ROW('Price History'!$E$6:$E$72)))=0,"",INDEX('Price History'!$E$6:$E$72,SUMPRODUCT(MAX(('Price History'!$B$6:$B$72=$B13)*('Price History'!$C$6:$C$72=$C13)*('Price History'!$D$6:$D$72<=MIN(DATE(2019,12,31),'Price Analysis'!$C$4))*ROW('Price History'!$E$6:$E$72)))-5)) -> 4.99 | F13: =IF(SUMPRODUCT(MAX(('Price History'!$B$6:$B$72=$B13)*('Price History'!$C$6:$C$72=$C13)*('Price History'!$D$6:$D$72<=MIN(DATE(2020,12,31),'Price Analysis'!$C$4))*ROW('Price History'!$E$6:$E$72)))=0,"",INDEX('Price History'!$E$6:$E$72,SUMPRODUCT(MAX(('Price History'!$B$6:$B$72=$B13)*('Price History'!$C$6:$C$72=$C13)*('Price History'!$D$6:$D$72<=MIN(DATE(2020,12,31),'Price Analysis'!$C$4))*ROW('Price History'!$E$6:$E$72)))-5)) -> 5.99 | G13: =IF(SUMPRODUCT(MAX(('Price History'!$B$6:$B$72=$B13)*('Price History'!$C$6:$C$72=$C13)*('Price History'!$D$6:$D$72<=MIN(DATE(2021,12,31),'Price Analysis'!$C$4))*ROW('Price History'!$E$6:$E$72)))=0,"",INDEX('Price History'!$E$6:$E$72,SUMPRODUCT(MAX(('Price History'!$B$6:$B$72=$B13)*('Price History'!$C$6:$C$72=$C13)*('Price History'!$D$6:$D$72<=MIN(DATE(2021,12,31),'Price Analysis'!$C$4))*ROW('Price History'!$E$6:$E$72)))-5)) -> 6.99 | H13: =IF(SUMPRODUCT(MAX(('Price History'!$B$6:$B$72=$B13)*('Price History'!$C$6:$C$72=$C13)*('Price History'!$D$6:$D$72<=MIN(DATE(2022,12,31),'Price Analysis'!$C$4))*ROW('Price History'!$E$6:$E$72)))=0,"",INDEX('Price History'!$E$6:$E$72,SUMPRODUCT(MAX(('Price History'!$B$6:$B$72=$B13)*('Price History'!$C$6:$C$72=$C13)*('Price History'!$D$6:$D$72<=MIN(DATE(2022,12,31),'Price Analysis'!$C$4))*ROW('Price History'!$E$6:$E$72)))-5)) -> 9.99 | I13: =IF(SUMPRODUCT(MAX(('Price History'!$B$6:$B$72=$B13)*('Price History'!$C$6:$C$72=$C13)*('Price History'!$D$6:$D$72<=MIN(DATE(2023,12,31),'Price Analysis'!$C$4))*ROW('Price History'!$E$6:$E$72)))=0,"",INDEX('Price History'!$E$6:$E$72,SUMPRODUCT(MAX(('Price History'!$B$6:$B$72=$B13)*('Price History'!$C$6:$C$72=$C13)*('Price History'!$D$6:$D$72<=MIN(DATE(2023,12,31),'Price Analysis'!$C$4))*ROW('Price History'!$E$6:$E$72)))-5)) -> 10.99 | J13: =IF(SUMPRODUCT(MAX(('Price History'!$B$6:$B$72=$B13)*('Price History'!$C$6:$C$72=$C13)*('Price History'!$D$6:$D$72<=MIN(DATE(2024,12,31),'Price Analysis'!$C$4))*ROW('Price History'!$E$6:$E$72)))=0,"",INDEX('Price History'!$E$6:$E$72,SUMPRODUCT(MAX(('Price History'!$B$6:$B$72=$B13)*('Price History'!$C$6:$C$72=$C13)*('Price History'!$D$6:$D$72<=MIN(DATE(2024,12,31),'Price Analysis'!$C$4))*ROW('Price History'!$E$6:$E$72)))-5)) -> 11.99 | K13: =IF(SUMPRODUCT(MAX(('Price History'!$B$6:$B$72=$B13)*('Price History'!$C$6:$C$72=$C13)*('Price History'!$D$6:$D$72<=MIN(DATE(2025,12,31),'Price Analysis'!$C$4))*ROW('Price History'!$E$6:$E$72)))=0,"",INDEX('Price History'!$E$6:$E$72,SUMPRODUCT(MAX(('Price History'!$B$6:$B$72=$B13)*('Price History'!$C$6:$C$72=$C13)*('Price History'!$D$6:$D$72<=MIN(DATE(2025,12,31),'Price Analysis'!$C$4))*ROW('Price History'!$E$6:$E$72)))-5)) -> 12.99 | L13: =IF(SUMPRODUCT(MAX(('Price History'!$B$6:$B$72=$B13)*('Price History'!$C$6:$C$72=$C13)*('Price History'!$D$6:$D$72<=MIN(DATE(2026,12,31),'Price Analysis'!$C$4))*ROW('Price History'!$E$6:$E$72)))=0,"",INDEX('Price History'!$E$6:$E$72,SUMPRODUCT(MAX(('Price History'!$B$6:$B$72=$B13)*('Price History'!$C$6:$C$72=$C13)*('Price History'!$D$6:$D$72<=MIN(DATE(2026,12,31),'Price Analysis'!$C$4))*ROW('Price History'!$E$6:$E$72)))-5)) -> 12.99
B14: Netflix | C14: Standard w/ ads | D14: Ad-supported | E14: =IF(SUMPRODUCT(MAX(('Price History'!$B$6:$B$72=$B14)*('Price History'!$C$6:$C$72=$C14)*('Price History'!$D$6:$D$72<=MIN(DATE(2019,12,31),'Price Analysis'!$C$4))*ROW('Price History'!$E$6:$E$72)))=0,"",INDEX('Price History'!$E$6:$E$72,SUMPRODUCT(MAX(('Price History'!$B$6:$B$72=$B14)*('Price History'!$C$6:$C$72=$C14)*('Price History'!$D$6:$D$72<=MIN(DATE(2019,12,31),'Price Analysis'!$C$4))*ROW('Price History'!$E$6:$E$72)))-5)) | F14: =IF(SUMPRODUCT(MAX(('Price History'!$B$6:$B$72=$B14)*('Price History'!$C$6:$C$72=$C14)*('Price History'!$D$6:$D$72<=MIN(DATE(2020,12,31),'Price Analysis'!$C$4))*ROW('Price History'!$E$6:$E$72)))=0,"",INDEX('Price History'!$E$6:$E$72,SUMPRODUCT(MAX(('Price History'!$B$6:$B$72=$B14)*('Price History'!$C$6:$C$72=$C14)*('Price History'!$D$6:$D$72<=MIN(DATE(2020,12,31),'Price Analysis'!$C$4))*ROW('Price History'!$E$6:$E$72)))-5)) | G14: =IF(SUMPRODUCT(MAX(('Price History'!$B$6:$B$72=$B14)*('Price History'!$C$6:$C$72=$C14)*('Price History'!$D$6:$D$72<=MIN(DATE(2021,12,31),'Price Analysis'!$C$4))*ROW('Price History'!$E$6:$E$72)))=0,"",INDEX('Price History'!$E$6:$E$72,SUMPRODUCT(MAX(('Price History'!$B$6:$B$72=$B14)*('Price History'!$C$6:$C$72=$C14)*('Price History'!$D$6:$D$72<=MIN(DATE(2021,12,31),'Price Analysis'!$C$4))*ROW('Price History'!$E$6:$E$72)))-5)) | H14: =IF(SUMPRODUCT(MAX(('Price History'!$B$6:$B$72=$B14)*('Price History'!$C$6:$C$72=$C14)*('Price History'!$D$6:$D$72<=MIN(DATE(2022,12,31),'Price Analysis'!$C$4))*ROW('Price History'!$E$6:$E$72)))=0,"",INDEX('Price History'!$E$6:$E$72,SUMPRODUCT(MAX(('Price History'!$B$6:$B$72=$B14)*('Price History'!$C$6:$C$72=$C14)*('Price History'!$D$6:$D$72<=MIN(DATE(2022,12,31),'Price Analysis'!$C$4))*ROW('Price History'!$E$6:$E$72)))-5)) -> 6.99 | I14: =IF(SUMPRODUCT(MAX(('Price History'!$B$6:$B$72=$B14)*('Price History'!$C$6:$C$72=$C14)*('Price History'!$D$6:$D$72<=MIN(DATE(2023,12,31),'Price Analysis'!$C$4))*ROW('Price History'!$E$6:$E$72)))=0,"",INDEX('Price History'!$E$6:$E$72,SUMPRODUCT(MAX(('Price History'!$B$6:$B$72=$B14)*('Price History'!$C$6:$C$72=$C14)*('Price History'!$D$6:$D$72<=MIN(DATE(2023,12,31),'Price Analysis'!$C$4))*ROW('Price History'!$E$6:$E$72)))-5)) -> 6.99 | J14: =IF(SUMPRODUCT(MAX(('Price History'!$B$6:$B$72=$B14)*('Price History'!$C$6:$C$72=$C14)*('Price History'!$D$6:$D$72<=MIN(DATE(2024,12,31),'Price Analysis'!$C$4))*ROW('Price History'!$E$6:$E$72)))=0,"",INDEX('Price History'!$E$6:$E$72,SUMPRODUCT(MAX(('Price History'!$B$6:$B$72=$B14)*('Price History'!$C$6:$C$72=$C14)*('Price History'!$D$6:$D$72<=MIN(DATE(2024,12,31),'Price Analysis'!$C$4))*ROW('Price History'!$E$6:$E$72)))-5)) -> 6.99 | K14: =IF(SUMPRODUCT(MAX(('Price History'!$B$6:$B$72=$B14)*('Price History'!$C$6:$C$72=$C14)*('Price History'!$D$6:$D$72<=MIN(DATE(2025,12,31),'Price Analysis'!$C$4))*ROW('Price History'!$E$6:$E$72)))=0,"",INDEX('Price History'!$E$6:$E$72,SUMPRODUCT(MAX(('Price History'!$B$6:$B$72=$B14)*('Price History'!$C$6:$C$72=$C14)*('Price History'!$D$6:$D$72<=MIN(DATE(2025,12,31),'Price Analysis'!$C$4))*ROW('Price History'!$E$6:$E$72)))-5)) -> 7.99 | L14: =IF(SUMPRODUCT(MAX(('Price History'!$B$6:$B$72=$B14)*('Price History'!$C$6:$C$72=$C14)*('Price History'!$D$6:$D$72<=MIN(DATE(2026,12,31),'Price Analysis'!$C$4))*ROW('Price History'!$E$6:$E$72)))=0,"",INDEX('Price History'!$E$6:$E$72,SUMPRODUCT(MAX(('Price History'!$B$6:$B$72=$B14)*('Price History'!$C$6:$C$72=$C14)*('Price History'!$D$6:$D$72<=MIN(DATE(2026,12,31),'Price Analysis'!$C$4))*ROW('Price History'!$E$6:$E$72)))-5)) -> 8.99
B15: Disney+ | C15: Basic w/ ads | D15: Ad-supported | E15: =IF(SUMPRODUCT(MAX(('Price History'!$B$6:$B$72=$B15)*('Price History'!$C$6:$C$72=$C15)*('Price History'!$D$6:$D$72<=MIN(DATE(2019,12,31),'Price Analysis'!$C$4))*ROW('Price History'!$E$6:$E$72)))=0,"",INDEX('Price History'!$E$6:$E$72,SUMPRODUCT(MAX(('Price History'!$B$6:$B$72=$B15)*('Price History'!$C$6:$C$72=$C15)*('Price History'!$D$6:$D$72<=MIN(DATE(2019,12,31),'Price Analysis'!$C$4))*ROW('Price History'!$E$6:$E$72)))-5)) | F15: =IF(SUMPRODUCT(MAX(('Price History'!$B$6:$B$72=$B15)*('Price History'!$C$6:$C$72=$C15)*('Price History'!$D$6:$D$72<=MIN(DATE(2020,12,31),'Price Analysis'!$C$4))*ROW('Price History'!$E$6:$E$72)))=0,"",INDEX('Price History'!$E$6:$E$72,SUMPRODUCT(MAX(('Price History'!$B$6:$B$72=$B15)*('Price History'!$C$6:$C$72=$C15)*('Price History'!$D$6:$D$72<=MIN(DATE(2020,12,31),'Price Analysis'!$C$4))*ROW('Price History'!$E$6:$E$72)))-5)) | G15: =IF(SUMPRODUCT(MAX(('Price History'!$B$6:$B$72=$B15)*('Price History'!$C$6:$C$72=$C15)*('Price History'!$D$6:$D$72<=MIN(DATE(2021,12,31),'Price Analysis'!$C$4))*ROW('Price History'!$E$6:$E$72)))=0,"",INDEX('Price History'!$E$6:$E$72,SUMPRODUCT(MAX(('Price History'!$B$6:$B$72=$B15)*('Price History'!$C$6:$C$72=$C15)*('Price History'!$D$6:$D$72<=MIN(DATE(2021,12,31),'Price Analysis'!$C$4))*ROW('Price History'!$E$6:$E$72)))-5)) | H15: =IF(SUMPRODUCT(MAX(('Price History'!$B$6:$B$72=$B15)*('Price History'!$C$6:$C$72=$C15)*('Price History'!$D$6:$D$72<=MIN(DATE(2022,12,31),'Price Analysis'!$C$4))*ROW('Price History'!$E$6:$E$72)))=0,"",INDEX('Price History'!$E$6:$E$72,SUMPRODUCT(MAX(('Price History'!$B$6:$B$72=$B15)*('Price History'!$C$6:$C$72=$C15)*('Price History'!$D$6:$D$72<=MIN(DATE(2022,12,31),'Price Analysis'!$C$4))*ROW('Price History'!$E$6:$E$72)))-5)) -> 7.99 | I15: =IF(SUMPRODUCT(MAX(('Price History'!$B$6:$B$72=$B15)*('Price History'!$C$6:$C$72=$C15)*('Price History'!$D$6:$D$72<=MIN(DATE(2023,12,31),'Price Analysis'!$C$4))*ROW('Price History'!$E$6:$E$72)))=0,"",INDEX('Price History'!$E$6:$E$72,SUMPRODUCT(MAX(('Price History'!$B$6:$B$72=$B15)*('Price History'!$C$6:$C$72=$C15)*('Price History'!$D$6:$D$72<=MIN(DATE(2023,12,31),'Price Analysis'!$C$4))*ROW('Price History'!$E$6:$E$72)))-5)) -> 7.99 | J15: =IF(SUMPRODUCT(MAX(('Price History'!$B$6:$B$72=$B15)*('Price History'!$C$6:$C$72=$C15)*('Price History'!$D$6:$D$72<=MIN(DATE(2024,12,31),'Price Analysis'!$C$4))*ROW('Price History'!$E$6:$E$72)))=0,"",INDEX('Price History'!$E$6:$E$72,SUMPRODUCT(MAX(('Price History'!$B$6:$B$72=$B15)*('Price History'!$C$6:$C$72=$C15)*('Price History'!$D$6:$D$72<=MIN(DATE(2024,12,31),'Price Analysis'!$C$4))*ROW('Price History'!$E$6:$E$72)))-5)) -> 9.99 | K15: =IF(SUMPRODUCT(MAX(('Price History'!$B$6:$B$72=$B15)*('Price History'!$C$6:$C$72=$C15)*('Price History'!$D$6:$D$72<=MIN(DATE(2025,12,31),'Price Analysis'!$C$4))*ROW('Price History'!$E$6:$E$72)))=0,"",INDEX('Price History'!$E$6:$E$72,SUMPRODUCT(MAX(('Price History'!$B$6:$B$72=$B15)*('Price History'!$C$6:$C$72=$C15)*('Price History'!$D$6:$D$72<=MIN(DATE(2025,12,31),'Price Analysis'!$C$4))*ROW('Price History'!$E$6:$E$72)))-5)) -> 11.99 | L15: =IF(SUMPRODUCT(MAX(('Price History'!$B$6:$B$72=$B15)*('Price History'!$C$6:$C$72=$C15)*('Price History'!$D$6:$D$72<=MIN(DATE(2026,12,31),'Price Analysis'!$C$4))*ROW('Price History'!$E$6:$E$72)))=0,"",INDEX('Price History'!$E$6:$E$72,SUMPRODUCT(MAX(('Price History'!$B$6:$B$72=$B15)*('Price History'!$C$6:$C$72=$C15)*('Price History'!$D$6:$D$72<=MIN(DATE(2026,12,31),'Price Analysis'!$C$4))*ROW('Price History'!$E$6:$E$72)))-5)) -> 11.99
B16: Hulu | C16: With ads | D16: Ad-supported | E16: =IF(SUMPRODUCT(MAX(('Price History'!$B$6:$B$72=$B16)*('Price History'!$C$6:$C$72=$C16)*('Price History'!$D$6:$D$72<=MIN(DATE(2019,12,31),'Price Analysis'!$C$4))*ROW('Price History'!$E$6:$E$72)))=0,"",INDEX('Price History'!$E$6:$E$72,SUMPRODUCT(MAX(('Price History'!$B$6:$B$72=$B16)*('Price History'!$C$6:$C$72=$C16)*('Price History'!$D$6:$D$72<=MIN(DATE(2019,12,31),'Price Analysis'!$C$4))*ROW('Price History'!$E$6:$E$72)))-5)) -> 5.99 | F16: =IF(SUMPRODUCT(MAX(('Price History'!$B$6:$B$72=$B16)*('Price History'!$C$6:$C$72=$C16)*('Price History'!$D$6:$D$72<=MIN(DATE(2020,12,31),'Price Analysis'!$C$4))*ROW('Price History'!$E$6:$E$72)))=0,"",INDEX('Price History'!$E$6:$E$72,SUMPRODUCT(MAX(('Price History'!$B$6:$B$72=$B16)*('Price History'!$C$6:$C$72=$C16)*('Price History'!$D$6:$D$72<=MIN(DATE(2020,12,31),'Price Analysis'!$C$4))*ROW('Price History'!$E$6:$E$72)))-5)) -> 5.99 | G16: =IF(SUMPRODUCT(MAX(('Price History'!$B$6:$B$72=$B16)*('Price History'!$C$6:$C$72=$C16)*('Price History'!$D$6:$D$72<=MIN(DATE(2021,12,31),'Price Analysis'!$C$4))*ROW('Price History'!$E$6:$E$72)))=0,"",INDEX('Price History'!$E$6:$E$72,SUMPRODUCT(MAX(('Price History'!$B$6:$B$72=$B16)*('Price History'!$C$6:$C$72=$C16)*('Price History'!$D$6:$D$72<=MIN(DATE(2021,12,31),'Price Analysis'!$C$4))*ROW('Price History'!$E$6:$E$72)))-5)) -> 6.99 | H16: =IF(SUMPRODUCT(MAX(('Price History'!$B$6:$B$72=$B16)*('Price History'!$C$6:$C$72=$C16)*('Price History'!$D$6:$D$72<=MIN(DATE(2022,12,31),'Price Analysis'!$C$4))*ROW('Price History'!$E$6:$E$72)))=0,"",INDEX('Price History'!$E$6:$E$72,SUMPRODUCT(MAX(('Price History'!$B$6:$B$72=$B16)*('Price History'!$C$6:$C$72=$C16)*('Price History'!$D$6:$D$72<=MIN(DATE(2022,12,31),'Price Analysis'!$C$4))*ROW('Price History'!$E$6:$E$72)))-5)) -> 7.99 | I16: =IF(SUMPRODUCT(MAX(('Price History'!$B$6:$B$72=$B16)*('Price History'!$C$6:$C$72=$C16)*('Price History'!$D$6:$D$72<=MIN(DATE(2023,12,31),'Price Analysis'!$C$4))*ROW('Price History'!$E$6:$E$72)))=0,"",INDEX('Price History'!$E$6:$E$72,SUMPRODUCT(MAX(('Price History'!$B$6:$B$72=$B16)*('Price History'!$C$6:$C$72=$C16)*('Price History'!$D$6:$D$72<=MIN(DATE(2023,12,31),'Price Analysis'!$C$4))*ROW('Price History'!$E$6:$E$72)))-5)) -> 7.99 | J16: =IF(SUMPRODUCT(MAX(('Price History'!$B$6:$B$72=$B16)*('Price History'!$C$6:$C$72=$C16)*('Price History'!$D$6:$D$72<=MIN(DATE(2024,12,31),'Price Analysis'!$C$4))*ROW('Price History'!$E$6:$E$72)))=0,"",INDEX('Price History'!$E$6:$E$72,SUMPRODUCT(MAX(('Price History'!$B$6:$B$72=$B16)*('Price History'!$C$6:$C$72=$C16)*('Price History'!$D$6:$D$72<=MIN(DATE(2024,12,31),'Price Analysis'!$C$4))*ROW('Price History'!$E$6:$E$72)))-5)) -> 9.99 | K16: =IF(SUMPRODUCT(MAX(('Price History'!$B$6:$B$72=$B16)*('Price History'!$C$6:$C$72=$C16)*('Price History'!$D$6:$D$72<=MIN(DATE(2025,12,31),'Price Analysis'!$C$4))*ROW('Price History'!$E$6:$E$72)))=0,"",INDEX('Price History'!$E$6:$E$72,SUMPRODUCT(MAX(('Price History'!$B$6:$B$72=$B16)*('Price History'!$C$6:$C$72=$C16)*('Price History'!$D$6:$D$72<=MIN(DATE(2025,12,31),'Price Analysis'!$C$4))*ROW('Price History'!$E$6:$E$72)))-5)) -> 11.99 | L16: =IF(SUMPRODUCT(MAX(('Price History'!$B$6:$B$72=$B16)*('Price History'!$C$6:$C$72=$C16)*('Price History'!$D$6:$D$72<=MIN(DATE(2026,12,31),'Price Analysis'!$C$4))*ROW('Price History'!$E$6:$E$72)))=0,"",INDEX('Price History'!$E$6:$E$72,SUMPRODUCT(MAX(('Price History'!$B$6:$B$72=$B16)*('Price History'!$C$6:$C$72=$C16)*('Price History'!$D$6:$D$72<=MIN(DATE(2026,12,31),'Price Analysis'!$C$4))*ROW('Price History'!$E$6:$E$72)))-5)) -> 11.99
B17: HBO Max | C17: Basic w/ ads | D17: Ad-supported | E17: =IF(SUMPRODUCT(MAX(('Price History'!$B$6:$B$72=$B17)*('Price History'!$C$6:$C$72=$C17)*('Price History'!$D$6:$D$72<=MIN(DATE(2019,12,31),'Price Analysis'!$C$4))*ROW('Price History'!$E$6:$E$72)))=0,"",INDEX('Price History'!$E$6:$E$72,SUMPRODUCT(MAX(('Price History'!$B$6:$B$72=$B17)*('Price History'!$C$6:$C$72=$C17)*('Price History'!$D$6:$D$72<=MIN(DATE(2019,12,31),'Price Analysis'!$C$4))*ROW('Price History'!$E$6:$E$72)))-5)) | F17: =IF(SUMPRODUCT(MAX(('Price History'!$B$6:$B$72=$B17)*('Price History'!$C$6:$C$72=$C17)*('Price History'!$D$6:$D$72<=MIN(DATE(2020,12,31),'Price Analysis'!$C$4))*ROW('Price History'!$E$6:$E$72)))=0,"",INDEX('Price History'!$E$6:$E$72,SUMPRODUCT(MAX(('Price History'!$B$6:$B$72=$B17)*('Price History'!$C$6:$C$72=$C17)*('Price History'!$D$6:$D$72<=MIN(DATE(2020,12,31),'Price Analysis'!$C$4))*ROW('Price History'!$E$6:$E$72)))-5)) | G17: =IF(SUMPRODUCT(MAX(('Price History'!$B$6:$B$72=$B17)*('Price History'!$C$6:$C$72=$C17)*('Price History'!$D$6:$D$72<=MIN(DATE(2021,12,31),'Price Analysis'!$C$4))*ROW('Price History'!$E$6:$E$72)))=0,"",INDEX('Price History'!$E$6:$E$72,SUMPRODUCT(MAX(('Price History'!$B$6:$B$72=$B17)*('Price History'!$C$6:$C$72=$C17)*('Price History'!$D$6:$D$72<=MIN(DATE(2021,12,31),'Price Analysis'!$C$4))*ROW('Price History'!$E$6:$E$72)))-5)) -> 9.99 | H17: =IF(SUMPRODUCT(MAX(('Price History'!$B$6:$B$72=$B17)*('Price History'!$C$6:$C$72=$C17)*('Price History'!$D$6:$D$72<=MIN(DATE(2022,12,31),'Price Analysis'!$C$4))*ROW('Price History'!$E$6:$E$72)))=0,"",INDEX('Price History'!$E$6:$E$72,SUMPRODUCT(MAX(('Price History'!$B$6:$B$72=$B17)*('Price History'!$C$6:$C$72=$C17)*('Price History'!$D$6:$D$72<=MIN(DATE(2022,12,31),'Price Analysis'!$C$4))*ROW('Price History'!$E$6:$E$72)))-5)) -> 9.99 | I17: =IF(SUMPRODUCT(MAX(('Price History'!$B$6:$B$72=$B17)*('Price History'!$C$6:$C$72=$C17)*('Price History'!$D$6:$D$72<=MIN(DATE(2023,12,31),'Price Analysis'!$C$4))*ROW('Price History'!$E$6:$E$72)))=0,"",INDEX('Price History'!$E$6:$E$72,SUMPRODUCT(MAX(('Price History'!$B$6:$B$72=$B17)*('Price History'!$C$6:$C$72=$C17)*('Price History'!$D$6:$D$72<=MIN(DATE(2023,12,31),'Price Analysis'!$C$4))*ROW('Price History'!$E$6:$E$72)))-5)) -> 9.99 | J17: =IF(SUMPRODUCT(MAX(('Price History'!$B$6:$B$72=$B17)*('Price History'!$C$6:$C$72=$C17)*('Price History'!$D$6:$D$72<=MIN(DATE(2024,12,31),'Price Analysis'!$C$4))*ROW('Price History'!$E$6:$E$72)))=0,"",INDEX('Price History'!$E$6:$E$72,SUMPRODUCT(MAX(('Price History'!$B$6:$B$72=$B17)*('Price History'!$C$6:$C$72=$C17)*('Price History'!$D$6:$D$72<=MIN(DATE(2024,12,31),'Price Analysis'!$C$4))*ROW('Price History'!$E$6:$E$72)))-5)) -> 9.99 | K17: =IF(SUMPRODUCT(MAX(('Price History'!$B$6:$B$72=$B17)*('Price History'!$C$6:$C$72=$C17)*('Price History'!$D$6:$D$72<=MIN(DATE(2025,12,31),'Price Analysis'!$C$4))*ROW('Price History'!$E$6:$E$72)))=0,"",INDEX('Price History'!$E$6:$E$72,SUMPRODUCT(MAX(('Price History'!$B$6:$B$72=$B17)*('Price History'!$C$6:$C$72=$C17)*('Price History'!$D$6:$D$72<=MIN(DATE(2025,12,31),'Price Analysis'!$C$4))*ROW('Price History'!$E$6:$E$72)))-5)) -> 10.99 | L17: =IF(SUMPRODUCT(MAX(('Price History'!$B$6:$B$72=$B17)*('Price History'!$C$6:$C$72=$C17)*('Price History'!$D$6:$D$72<=MIN(DATE(2026,12,31),'Price Analysis'!$C$4))*ROW('Price History'!$E$6:$E$72)))=0,"",INDEX('Price History'!$E$6:$E$72,SUMPRODUCT(MAX(('Price History'!$B$6:$B$72=$B17)*('Price History'!$C$6:$C$72=$C17)*('Price History'!$D$6:$D$72<=MIN(DATE(2026,12,31),'Price Analysis'!$C$4))*ROW('Price History'!$E$6:$E$72)))-5)) -> 10.99
... B19: Paramount+ | C19: Essential w/ ads | D19: Ad-supported | E19: =IF(SUMPRODUCT(MAX(('Price History'!$B$6:$B$72=$B19)*('Price History'!$C$6:$C$72=$C19)*('Price History'!$D$6:$D$72<=MIN(DATE(2019,12,31),'Price Analysis'!$C$4))*ROW('Price History'!$E$6:$E$72)))=0,"",INDEX('Price History'!$E$6:$E$72,SUMPRODUCT(MAX(('Price History'!$B$6:$B$72=$B19)*('Price History'!$C$6:$C$72=$C19)*('Price History'!$D$6:$D$72<=MIN(DATE(2019,12,31),'Price Analysis'!$C$4))*ROW('Price History'!$E$6:$E$72)))-5)) | F19: =IF(SUMPRODUCT(MAX(('Price History'!$B$6:$B$72=$B19)*('Price History'!$C$6:$C$72=$C19)*('Price History'!$D$6:$D$72<=MIN(DATE(2020,12,31),'Price Analysis'!$C$4))*ROW('Price History'!$E$6:$E$72)))=0,"",INDEX('Price History'!$E$6:$E$72,SUMPRODUCT(MAX(('Price History'!$B$6:$B$72=$B19)*('Price History'!$C$6:$C$72=$C19)*('Price History'!$D$6:$D$72<=MIN(DATE(2020,12,31),'Price Analysis'!$C$4))*ROW('Price History'!$E$6:$E$72)))-5)) | G19: =IF(SUMPRODUCT(MAX(('Price History'!$B$6:$B$72=$B19)*('Price History'!$C$6:$C$72=$C19)*('Price History'!$D$6:$D$72<=MIN(DATE(2021,12,31),'Price Analysis'!$C$4))*ROW('Price History'!$E$6:$E$72)))=0,"",INDEX('Price History'!$E$6:$E$72,SUMPRODUCT(MAX(('Price History'!$B$6:$B$72=$B19)*('Price History'!$C$6:$C$72=$C19)*('Price History'!$D$6:$D$72<=MIN(DATE(2021,12,31),'Price Analysis'!$C$4))*ROW('Price History'!$E$6:$E$72)))-5)) -> 4.99 | H19: =IF(SUMPRODUCT(MAX(('Price History'!$B$6:$B$72=$B19)*('Price History'!$C$6:$C$72=$C19)*('Price History'!$D$6:$D$72<=MIN(DATE(2022,12,31),'Price Analysis'!$C$4))*ROW('Price History'!$E$6:$E$72)))=0,"",INDEX('Price History'!$E$6:$E$72,SUMPRODUCT(MAX(('Price History'!$B$6:$B$72=$B19)*('Price History'!$C$6:$C$72=$C19)*('Price History'!$D$6:$D$72<=MIN(DATE(2022,12,31),'Price Analysis'!$C$4))*ROW('Price History'!$E$6:$E$72)))-5)) -> 4.99 | I19: =IF(SUMPRODUCT(MAX(('Price History'!$B$6:$B$72=$B19)*('Price History'!$C$6:$C$72=$C19)*('Price History'!$D$6:$D$72<=MIN(DATE(2023,12,31),'Price Analysis'!$C$4))*ROW('Price History'!$E$6:$E$72)))=0,"",INDEX('Price History'!$E$6:$E$72,SUMPRODUCT(MAX(('Price History'!$B$6:$B$72=$B19)*('Price History'!$C$6:$C$72=$C19)*('Price History'!$D$6:$D$72<=MIN(DATE(2023,12,31),'Price Analysis'!$C$4))*ROW('Price History'!$E$6:$E$72)))-5)) -> 5.99 | J19: =IF(SUMPRODUCT(MAX(('Price History'!$B$6:$B$72=$B19)*('Price History'!$C$6:$C$72=$C19)*('Price History'!$D$6:$D$72<=MIN(DATE(2024,12,31),'Price Analysis'!$C$4))*ROW('Price History'!$E$6:$E$72)))=0,"",INDEX('Price History'!$E$6:$E$72,SUMPRODUCT(MAX(('Price History'!$B$6:$B$72=$B19)*('Price History'!$C$6:$C$72=$C19)*('Price History'!$D$6:$D$72<=MIN(DATE(2024,12,31),'Price Analysis'!$C$4))*ROW('Price History'!$E$6:$E$72)))-5)) -> 7.99 | K19: =IF(SUMPRODUCT(MAX(('Price History'!$B$6:$B$72=$B19)*('Price History'!$C$6:$C$72=$C19)*('Price History'!$D$6:$D$72<=MIN(DATE(2025,12,31),'Price Analysis'!$C$4))*ROW('Price History'!$E$6:$E$72)))=0,"",INDEX('Price History'!$E$6:$E$72,SUMPRODUCT(MAX(('Price History'!$B$6:$B$72=$B19)*('Price History'!$C$6:$C$72=$C19)*('Price History'!$D$6:$D$72<=MIN(DATE(2025,12,31),'Price Analysis'!$C$4))*ROW('Price History'!$E$6:$E$72)))-5)) -> 7.99 | L19: =IF(SUMPRODUCT(MAX(('Price History'!$B$6:$B$72=$B19)*('Price History'!$C$6:$C$72=$C19)*('Price History'!$D$6:$D$72<=MIN(DATE(2026,12,31),'Price Analysis'!$C$4))*ROW('Price History'!$E$6:$E$72)))=0,"",INDEX('Price History'!$E$6:$E$72,SUMPRODUCT(MAX(('Price History'!$B$6:$B$72=$B19)*('Price History'!$C$6:$C$72=$C19)*('Price History'!$D$6:$D$72<=MIN(DATE(2026,12,31),'Price Analysis'!$C$4))*ROW('Price History'!$E$6:$E$72)))-5)) -> 8.99
B21: Ad-free rows are averaged on the Ad vs No-Ad tab; ESPN Select is classified Ad-supported and never enters an ad-free average.

Sheet Price Analysis
B2: Price Analysis — Flagship Tier Inflation
B3: Flagship means the ad-free consumer plan, except at ESPN Select, which has never offered one. Launch date and launch price are read from Price History and elapsed years are computed with YEARFRAC rather than typed. Windows differ by service, so read CAGR next to the launch date and alongside the median.
B4: As-of date | C4: 46232 | D4: Single input governing every current-price comparison and the 2026 column of the Panel.
B6: Service | C6: Flagship tier | D6: Launch date | E6: Launch $ | F6: Current $ | G6: Years | H6: Total % chg | I6: CAGR
